Workbook

Sheet computation
B1: 1 | C1: 2 | D1: 3 | E1: 5 | F1: 6 | G1: 7 | H1: 8 | I1: 9 | J1: 10 | K1: 11 | L1: 12 | M1: 13 | N1: 14 | O1: 15 | P1: 16 | Q1: 17 | R1: 18 | S1: 19 | T1: 20 | U1: 21 | V1: 22 | W1: 23 | X1: 24 | Y1: 25 | Z1: 26 | AA1: 27 | AB1: 28 | AC1: 29 | AD1: 101 | AE1: 102 | AF1: 103 | AG1: 104 | AH1: 105 | AI1: 106 | AJ1: 107 | AK1: 108 | AL1: 109 | AM1: 110 | AN1: 111 | AO1: 112 | AP1: 113 | AQ1: 114 | AR1: 115 | AS1: 116 | AT1: p138
A2: 1 | B2: =SUM(B76,B108,B141) -> 480 | C2: =SUM(C76,C108,C141) -> 27 | D2: =SUM(D76,D108,D141) -> 27 | E2: =SUM(E76,E108,E141) -> 47 | F2: =SUM(F76,F108,F141) -> 89 | G2: =SUM(G76,G108,G141) -> 91 | H2: =SUM(H76,H108,H141) -> 77 | I2: =SUM(I76,I108,I141) -> 30 | ... AC2: =SUM(AC76,AC108,AC141) -> 54 | AD2: =$AT2*AD$46 -> 62.061898 | AE2: =$AT2*AE$46 -> 44.03562 | AF2: =$AT2*AF$46 -> 44.808175 | AG2: =$AT2*AG$46 -> 26.781898 | AH2: =$AT2*AH$46 -> 36.567591 | AI2: =$AT2*AI$46 -> 67.984818 | AJ2: =$AT2*AJ$46 -> 68.757372 | AK2: =$AT2*AK$46 -> 45.065693 | ... AS2: =$AT2*AS$46 -> 75.710365 | AT2: 882
A3: 2 | B3: =SUM(B77,B109,B142) -> 12 | C3: =SUM(C77,C109,C142) -> 538 | D3: =SUM(D77,D109,D142) -> 12 | E3: =SUM(E77,E109,E142) -> 12 | F3: =SUM(F77,F109,F142) -> 12 | G3: =SUM(G77,G109,G142) -> 12 | H3: =SUM(H77,H109,H142) -> 12 | I3: =SUM(I77,I109,I142) -> 12 | ... AC3: =SUM(AC77,AC109,AC142) -> 12 | AD3: =$AT3*AD$46 -> 33.423358 | AE3: =$AT3*AE$46 -> 23.715328 | AF3: =$AT3*AF$46 -> 24.131387 | AG3: =$AT3*AG$46 -> 14.423358 | AH3: =$AT3*AH$46 -> 19.693431 | AI3: =$AT3*AI$46 -> 36.613139 | AJ3: =$AT3*AJ$46 -> 37.029197 | AK3: =$AT3*AK$46 -> 24.270073 | ... AS3: =$AT3*AS$46 -> 40.773723 | AT3: 475
A4: 3 | B4: =SUM(B78,B110,B143) -> 127 | C4: =SUM(C78,C110,C143) -> 18 | D4: =SUM(D78,D110,D143) -> 55 | E4: =SUM(E78,E110,E143) -> 33 | F4: =SUM(F78,F110,F143) -> 46 | G4: =SUM(G78,G110,G143) -> 67 | H4: =SUM(H78,H110,H143) -> 46 | I4: =SUM(I78,I110,I143) -> 20 | ... AC4: =SUM(AC78,AC110,AC143) -> 34 | AD4: =$AT4*AD$46 -> 20.757664 | AE4: =$AT4*AE$46 -> 14.728467 | AF4: =$AT4*AF$46 -> 14.986861 | AG4: =$AT4*AG$46 -> 8.9576642 | AH4: =$AT4*AH$46 -> 12.230657 | AI4: =$AT4*AI$46 -> 22.738686 | AJ4: =$AT4*AJ$46 -> 22.99708 | AK4: =$AT4*AK$46 -> 15.072993 | ... AS4: =$AT4*AS$46 -> 25.322628 | AT4: 295
A5: 5 | B5: =SUM(B79,B111,B144) -> 47 | C5: =SUM(C79,C111,C144) -> 30 | D5: =SUM(D79,D111,D144) -> 30 | E5: =SUM(E79,E111,E144) -> 44 | F5: =SUM(F79,F111,F144) -> 35 | G5: =SUM(G79,G111,G144) -> 48 | H5: =SUM(H79,H111,H144) -> 38 | I5: =SUM(I79,I111,I144) -> 34 | ... AC5: =SUM(AC79,AC111,AC144) -> 36 | AD5: =$AT5*AD$46 -> 9.64 | AE5: =$AT5*AE$46 -> 6.84 | AF5: =$AT5*AF$46 -> 6.96 | AG5: =$AT5*AG$46 -> 4.16 | AH5: =$AT5*AH$46 -> 5.68 | AI5: =$AT5*AI$46 -> 10.56 | AJ5: =$AT5*AJ$46 -> 10.68 | AK5: =$AT5*AK$46 -> 7 | ... AS5: =$AT5*AS$46 -> 11.76 | AT5: 137
A6: 6 | B6: =SUM(B80,B112,B145) -> 268 | C6: =SUM(C80,C112,C145) -> 45 | D6: =SUM(D80,D112,D145) -> 45 | E6: =SUM(E80,E112,E145) -> 66 | F6: =SUM(F80,F112,F145) -> 123 | G6: =SUM(G80,G112,G145) -> 130 | H6: =SUM(H80,H112,H145) -> 137 | I6: =SUM(I80,I112,I145) -> 48 | ... AC6: =SUM(AC80,AC112,AC145) -> 95 | AD6: =$AT6*AD$46 -> 46.651971 | AE6: =$AT6*AE$46 -> 33.101606 | AF6: =$AT6*AF$46 -> 33.682336 | AG6: =$AT6*AG$46 -> 20.131971 | AH6: =$AT6*AH$46 -> 27.487883 | AI6: =$AT6*AI$46 -> 51.104234 | AJ6: =$AT6*AJ$46 -> 51.684964 | AK6: =$AT6*AK$46 -> 33.875912 | ... AS6: =$AT6*AS$46 -> 56.911533 | AT6: 663
A7: 7 | B7: =SUM(B81,B113,B146) -> 159 | C7: =SUM(C81,C113,C146) -> 50 | D7: =SUM(D81,D113,D146) -> 50 | E7: =SUM(E81,E113,E146) -> 86 | F7: =SUM(F81,F113,F146) -> 91 | G7: =SUM(G81,G113,G146) -> 163 | H7: =SUM(H81,H113,H146) -> 110 | I7: =SUM(I81,I113,I146) -> 56 | ... AC7: =SUM(AC81,AC113,AC146) -> 91 | AD7: =$AT7*AD$46 -> 42.218978 | AE7: =$AT7*AE$46 -> 29.956204 | AF7: =$AT7*AF$46 -> 30.481752 | AG7: =$AT7*AG$46 -> 18.218978 | AH7: =$AT7*AH$46 -> 24.875912 | AI7: =$AT7*AI$46 -> 46.248175 | AJ7: =$AT7*AJ$46 -> 46.773723 | AK7: =$AT7*AK$46 -> 30.656934 | ... AS7: =$AT7*AS$46 -> 51.50365 | AT7: 600
A8: 8 | B8: =SUM(B82,B114,B147) -> 188 | C8: =SUM(C82,C114,C147) -> 36 | D8: =SUM(D82,D114,D147) -> 36 | E8: =SUM(E82,E114,E147) -> 62 | F8: =SUM(F82,F114,F147) -> 114 | G8: =SUM(G82,G114,G147) -> 143 | H8: =SUM(H82,H114,H147) -> 180 | I8: =SUM(I82,I114,I147) -> 41 | ... AC8: =SUM(AC82,AC114,AC147) -> 132 | AD8: =$AT8*AD$46 -> 48.48146 | AE8: =$AT8*AE$46 -> 34.399708 | AF8: =$AT8*AF$46 -> 35.003212 | AG8: =$AT8*AG$46 -> 20.92146 | AH8: =$AT8*AH$46 -> 28.565839 | AI8: =$AT8*AI$46 -> 53.108321 | AJ8: =$AT8*AJ$46 -> 53.711825 | AK8: =$AT8*AK$46 -> 35.20438 | ... AS8: =$AT8*AS$46 -> 59.143358 | AT8: 689
A9: 9 | B9: =SUM(B83,B115,B148) -> 28 | C9: =SUM(C83,C115,C148) -> 22 | D9: =SUM(D83,D115,D148) -> 22 | E9: =SUM(E83,E115,E148) -> 30 | F9: =SUM(F83,F115,F148) -> 24 | G9: =SUM(G83,G115,G148) -> 28 | H9: =SUM(H83,H115,H148) -> 25 | I9: =SUM(I83,I115,I148) -> 83 | ... AC9: =SUM(AC83,AC115,AC148) -> 25 | AD9: =$AT9*AD$46 -> 21.883504 | AE9: =$AT9*AE$46 -> 15.527299 | AF9: =$AT9*AF$46 -> 15.799708 | AG9: =$AT9*AG$46 -> 9.4435036 | AH9: =$AT9*AH$46 -> 12.894015 | AI9: =$AT9*AI$46 -> 23.971971 | AJ9: =$AT9*AJ$46 -> 24.24438 | AK9: =$AT9*AK$46 -> 15.890511 | ... AS9: =$AT9*AS$46 -> 26.696058 | AT9: 311
A10: 10 | B10: =SUM(B84,B116,B149) -> 82 | C10: =SUM(C84,C116,C149) -> 15 | D10: =SUM(D84,D116,D149) -> 15 | E10: =SUM(E84,E116,E149) -> 32 | F10: =SUM(F84,F116,F149) -> 48 | G10: =SUM(G84,G116,G149) -> 78 | H10: =SUM(H84,H116,H149) -> 86 | I10: =SUM(I84,I116,I149) -> 18 | ... AC10: =SUM(AC84,AC116,AC149) -> 74 | AD10: =$AT10*AD$46 -> 33.634453 | AE10: =$AT10*AE$46 -> 23.865109 | AF10: =$AT10*AF$46 -> 24.283796 | AG10: =$AT10*AG$46 -> 14.514453 | AH10: =$AT10*AH$46 -> 19.81781 | AI10: =$AT10*AI$46 -> 36.84438 | AJ10: =$AT10*AJ$46 -> 37.263066 | AK10: =$AT10*AK$46 -> 24.423358 | ... AS10: =$AT10*AS$46 -> 41.031241 | AT10: 478
A11: 11 | B11: =SUM(B85,B117,B150) -> 7 | C11: =SUM(C85,C117,C150) -> 7 | D11: =SUM(D85,D117,D150) -> 7 | E11: =SUM(E85,E117,E150) -> 7 | F11: =SUM(F85,F117,F150) -> 7 | G11: =SUM(G85,G117,G150) -> 7 | H11: =SUM(H85,H117,H150) -> 7 | I11: =SUM(I85,I117,I150) -> 7 | ... AC11: =SUM(AC85,AC117,AC150) -> 7 | AD11: =$AT11*AD$46 -> 1.5480292 | AE11: =$AT11*AE$46 -> 1.0983942 | AF11: =$AT11*AF$46 -> 1.1176642 | AG11: =$AT11*AG$46 -> 0.6680292 | AH11: =$AT11*AH$46 -> 0.91211679 | AI11: =$AT11*AI$46 -> 1.6957664 | AJ11: =$AT11*AJ$46 -> 1.7150365 | AK11: =$AT11*AK$46 -> 1.1240876 | ... AS11: =$AT11*AS$46 -> 1.8884672 | AT11: 22
A12: 12 | B12: =SUM(B86,B118,B151) -> 40 | C12: =SUM(C86,C118,C151) -> 16 | D12: =SUM(D86,D118,D151) -> 16 | E12: =SUM(E86,E118,E151) -> 25 | F12: =SUM(F86,F118,F151) -> 27 | G12: =SUM(G86,G118,G151) -> 44 | H12: =SUM(H86,H118,H151) -> 39 | I12: =SUM(I86,I118,I151) -> 18 | ... AC12: =SUM(AC86,AC118,AC151) -> 38 | AD12: =$AT12*AD$46 -> 16.817226 | AE12: =$AT12*AE$46 -> 11.932555 | AF12: =$AT12*AF$46 -> 12.141898 | AG12: =$AT12*AG$46 -> 7.2572263 | AH12: =$AT12*AH$46 -> 9.9089051 | AI12: =$AT12*AI$46 -> 18.42219 | AJ12: =$AT12*AJ$46 -> 18.631533 | AK12: =$AT12*AK$46 -> 12.211679 | ... AS12: =$AT12*AS$46 -> 20.51562 | AT12: 239
A13: 13 | B13: =SUM(B87,B119,B152) -> 33 | C13: =SUM(C87,C119,C152) -> 18 | D13: =SUM(D87,D119,D152) -> 18 | E13: =SUM(E87,E119,E152) -> 28 | F13: =SUM(F87,F119,F152) -> 25 | G13: =SUM(G87,G119,G152) -> 37 | H13: =SUM(H87,H119,H152) -> 33 | I13: =SUM(I87,I119,I152) -> 22 | ... AC13: =SUM(AC87,AC119,AC152) -> 36 | AD13: =$AT13*AD$46 -> 17.661606 | AE13: =$AT13*AE$46 -> 12.531679 | AF13: =$AT13*AF$46 -> 12.751533 | AG13: =$AT13*AG$46 -> 7.6216058 | AH13: =$AT13*AH$46 -> 10.406423 | AI13: =$AT13*AI$46 -> 19.347153 | AJ13: =$AT13*AJ$46 -> 19.567007 | AK13: =$AT13*AK$46 -> 12.824818 | ... AS13: =$AT13*AS$46 -> 21.545693 | AT13: 251
... A28: 28 | B28: =SUM(B102,B134,B167) -> 59 | C28: =SUM(C102,C134,C167) -> 31 | D28: =SUM(D102,D134,D167) -> 31 | E28: =SUM(E102,E134,E167) -> 55 | F28: =SUM(F102,F134,F167) -> 42 | G28: =SUM(G102,G134,G167) -> 69 | H28: =SUM(H102,H134,H167) -> 52 | I28: =SUM(I102,I134,I167) -> 38 | ... AC28: =SUM(AC102,AC134,AC167) -> 52 | AD28: =$AT28*AD$46 -> 27.934891 | AE28: =$AT28*AE$46 -> 19.821022 | AF28: =$AT28*AF$46 -> 20.168759 | AG28: =$AT28*AG$46 -> 12.054891 | AH28: =$AT28*AH$46 -> 16.459562 | AI28: =$AT28*AI$46 -> 30.600876 | AJ28: =$AT28*AJ$46 -> 30.948613 | AK28: =$AT28*AK$46 -> 20.284672 | ... AS28: =$AT28*AS$46 -> 34.078248 | AT28: 397
A29: 29 | B29: =SUM(B103,B135,B168) -> 72 | C29: =SUM(C103,C135,C168) -> 15 | D29: =SUM(D103,D135,D168) -> 15 | E29: =SUM(E103,E135,E168) -> 29 | F29: =SUM(F103,F135,F168) -> 44 | G29: =SUM(G103,G135,G168) -> 66 | H29: =SUM(H103,H135,H168) -> 82 | I29: =SUM(I103,I135,I168) -> 18 | ... AC29: =SUM(AC103,AC135,AC168) -> 89 | AD29: =$AT29*AD$46 -> 29.76438 | AE29: =$AT29*AE$46 -> 21.119124 | AF29: =$AT29*AF$46 -> 21.489635 | AG29: =$AT29*AG$46 -> 12.84438 | AH29: =$AT29*AH$46 -> 17.537518 | AI29: =$AT29*AI$46 -> 32.604964 | AJ29: =$AT29*AJ$46 -> 32.975474 | AK29: =$AT29*AK$46 -> 21.613139 | ... AS29: =$AT29*AS$46 -> 36.310073 | AT29: 423 | AU29: inflow | AV29: outflow | AW29: B1 | AX29: B2 | AY29: EXCHANGE | AZ29: CROSSING
A30: 101 | B30: =B$50*$AY30 -> 5.0005591 | C30: =C$50*$AY30 -> 1.0972046 | D30: =D$50*$AY30 -> 0.42653478 | E30: =E$50*$AY30 -> 0.0028061499 | F30: =F$50*$AY30 -> 0.12347059 | G30: =G$50*$AY30 -> 1.6921084 | H30: =H$50*$AY30 -> 1.0719493 | I30: =I$50*$AY30 -> 1.2852166 | ... AC30: =AC$50*$AY30 -> 0.58648532 | AD30: =AD$48*$AZ30 -> 8.5704526 | AE30: =AE$48*$AZ30 -> 6.0811095 | AF30: =AF$48*$AZ30 -> 6.1877956 | AG30: =AG$48*$AZ30 -> 3.6984526 | AH30: =AH$48*$AZ30 -> 5.0498102 | AI30: =AI$48*$AZ30 -> 9.3883796 | AJ30: =AJ$48*$AZ30 -> 9.4950657 | AK30: =AK$48*$AZ30 -> 6.2233577 | ... AS30: =AS$48*$AZ30 -> 10.455241 | AU30: 174 | AV30: 241 | AW30: 0.3 | AX30: 0.7 | AY30: =AU30*AW30 -> 52.2 | AZ30: =AU30*AX30 -> 121.8
A31: 102 | B31: =B$50*$AY31 -> 2.5194388 | C31: =C$50*$AY31 -> 0.55280615 | D31: =D$50*$AY31 -> 0.21490162 | E31: =E$50*$AY31 -> 0.0014138265 | F31: =F$50*$AY31 -> 0.062208365 | G31: =G$50*$AY31 -> 0.85253736 | H31: =H$50*$AY31 -> 0.54008171 | I31: =I$50*$AY31 -> 0.64753252 | ... AC31: =AC$50*$AY31 -> 0.29548973 | AD31: =AD$48*$AZ31 -> 16.655387 | AE31: =AE$48*$AZ31 -> 11.817723 | AF31: =AF$48*$AZ31 -> 12.025051 | AG31: =AG$48*$AZ31 -> 7.1873869 | AH31: =AH$48*$AZ31 -> 9.8135474 | AI31: =AI$48*$AZ31 -> 18.244905 | AJ31: =AJ$48*$AZ31 -> 18.452234 | AK31: =AK$48*$AZ31 -> 12.094161 | ... AS31: =AS$48*$AZ31 -> 20.31819 | AU31: 263 | AV31: 171 | AW31: 0.1 | AX31: 0.9 | AY31: =AU31*AW31 -> 26.3 | AZ31: =AU31*AX31 -> 236.7
A32: 103 | B32: =B$50*$AY32 -> 12.980378 | C32: =C$50*$AY32 -> 2.8481077 | D32: =D$50*$AY32 -> 1.1071928 | E32: =E$50*$AY32 -> 0.007284163 | F32: =F$50*$AY32 -> 0.32050317 | G32: =G$50*$AY32 -> 4.3923503 | H32: =H$50*$AY32 -> 2.7825503 | I32: =I$50*$AY32 -> 3.3361467 | ... AC32: =AC$50*$AY32 -> 1.5223901 | AD32: =AD$48*$AZ32 -> 9.5344526 | AE32: =AE$48*$AZ32 -> 6.7651095 | AF32: =AF$48*$AZ32 -> 6.8837956 | AG32: =AG$48*$AZ32 -> 4.1144526 | AH32: =AH$48*$AZ32 -> 5.6178102 | AI32: =AI$48*$AZ32 -> 10.44438 | AJ32: =AJ$48*$AZ32 -> 10.563066 | AK32: =AK$48*$AZ32 -> 6.9233577 | ... AS32: =AS$48*$AZ32 -> 11.631241 | AU32: 271 | AV32: 174 | AW32: 0.5 | AX32: 0.5 | AY32: =AU32*AW32 -> 135.5 | AZ32: =AU32*AX32 -> 135.5
A33: 104 | B33: =B$50*$AY33 -> 5.5944952 | C33: =C$50*$AY33 -> 1.2275239 | D33: =D$50*$AY33 -> 0.477196 | E33: =E$50*$AY33 -> 0.0031394474 | F33: =F$50*$AY33 -> 0.13813568 | G33: =G$50*$AY33 -> 1.8930868 | H33: =H$50*$AY33 -> 1.1992689 | I33: =I$50*$AY33 -> 1.4378669 | ... AC33: =AC$50*$AY33 -> 0.6561445 | AD33: =AD$48*$AZ33 -> 6.1639708 | AE33: =AE$48*$AZ33 -> 4.3736058 | AF33: =AF$48*$AZ33 -> 4.4503358 | AG33: =AG$48*$AZ33 -> 2.6599708 | AH33: =AH$48*$AZ33 -> 3.6318832 | AI33: =AI$48*$AZ33 -> 6.7522336 | AJ33: =AJ$48*$AZ33 -> 6.8289635 | AK33: =AK$48*$AZ33 -> 4.4759124 | ... AS33: =AS$48*$AZ33 -> 7.5195328 | AU33: 146 | AV33: 104 | AW33: 0.4 | AX33: 0.6 | AY33: =AU33*AW33 -> 58.4 | AZ33: =AU33*AX33 -> 87.6
A34: 105 | B34: =B$50*$AY34 -> 16.630212 | C34: =C$50*$AY34 -> 3.648941 | D34: =D$50*$AY34 -> 1.4185141 | E34: =E$50*$AY34 -> 0.0093323299 | F34: =F$50*$AY34 -> 0.41062251 | G34: =G$50*$AY34 -> 5.6273949 | H34: =H$50*$AY34 -> 3.56495 | I34: =I$50*$AY34 -> 4.2742071 | ... AC34: =AC$50*$AY34 -> 1.9504569 | AD34: =AD$48*$AZ34 -> 3.0538394 | AE34: =AE$48*$AZ34 -> 2.1668321 | AF34: =AF$48*$AZ34 -> 2.2048467 | AG34: =AG$48*$AZ34 -> 1.3178394 | AH34: =AH$48*$AZ34 -> 1.7993577 | AI34: =AI$48*$AZ34 -> 3.3452847 | AJ34: =AJ$48*$AZ34 -> 3.3832993 | AK34: =AK$48*$AZ34 -> 2.2175182 | ... AS34: =AS$48*$AZ34 -> 3.7254307 | AU34: 217 | AV34: 142 | AW34: 0.8 | AX34: 0.2 | AY34: =AU34*AW34 -> 173.6 | AZ34: =AU34*AX34 -> 43.4
A35: 106 | B35: =B$50*$AY35 -> 13.69885 | C35: =C$50*$AY35 -> 3.0057521 | D35: =D$50*$AY35 -> 1.1684765 | E35: =E$50*$AY35 -> 0.0076873454 | F35: =F$50*$AY35 -> 0.3382432 | G35: =G$50*$AY35 -> 4.6354693 | H35: =H$50*$AY35 -> 2.936566 | I35: =I$50*$AY35 -> 3.5208042 | ... AC35: =AC$50*$AY35 -> 1.6066552 | AD35: =AD$48*$AZ35 -> 8.2327007 | AE35: =AE$48*$AZ35 -> 5.8414599 | AF35: =AF$48*$AZ35 -> 5.9439416 | AG35: =AG$48*$AZ35 -> 3.5527007 | AH35: =AH$48*$AZ35 -> 4.8508029 | AI35: =AI$48*$AZ35 -> 9.0183942 | AJ35: =AJ$48*$AZ35 -> 9.1208759 | AK35: =AK$48*$AZ35 -> 5.9781022 | ... AS35: =AS$48*$AZ35 -> 10.043212 | AU35: 260 | AV35: 264 | AW35: 0.55 | AX35: 0.45 | AY35: =AU35*AW35 -> 143 | AZ35: =AU35*AX35 -> 117
A36: 107 | B36: =B$50*$AY36 -> 5.101145 | C36: =C$50*$AY36 -> 1.1192748 | D36: =D$50*$AY36 -> 0.4351145 | E36: =E$50*$AY36 -> 0.0028625954 | F36: =F$50*$AY36 -> 0.1259542 | G36: =G$50*$AY36 -> 1.726145 | H36: =H$50*$AY36 -> 1.0935115 | I36: =I$50*$AY36 -> 1.3110687 | ... AC36: =AC$50*$AY36 -> 0.59828244 | AD36: =AD$48*$AZ36 -> 11.240803 | AE36: =AE$48*$AZ36 -> 7.9758394 | AF36: =AF$48*$AZ36 -> 8.1157664 | AG36: =AG$48*$AZ36 -> 4.8508029 | AH36: =AH$48*$AZ36 -> 6.6232117 | AI36: =AI$48*$AZ36 -> 12.313577 | AJ36: =AJ$48*$AZ36 -> 12.453504 | AK36: =AK$48*$AZ36 -> 8.1624088 | ... AS36: =AS$48*$AZ36 -> 13.712847 | AU36: 213 | AV36: 267 | AW36: 0.25 | AX36: 0.75 | AY36: =AU36*AW36 -> 53.25 | AZ36: =AU36*AX36 -> 159.75
A37: 108 | B37: =B$50*$AY37 -> 16.084174 | C37: =C$50*$AY37 -> 3.5291313 | D37: =D$50*$AY37 -> 1.3719385 | E37: =E$50*$AY37 -> 0.0090259112 | F37: =F$50*$AY37 -> 0.39714009 | G37: =G$50*$AY37 -> 5.4426244 | H37: =H$50*$AY37 -> 3.4478981 | I37: =I$50*$AY37 -> 4.1338673 | ... AC37: =AC$50*$AY37 -> 1.8864154 | AD37: =AD$48*$AZ37 -> 4.3696642 | AE37: =AE$48*$AZ37 -> 3.1004672 | AF37: =AF$48*$AZ37 -> 3.1548613 | AG37: =AG$48*$AZ37 -> 1.8856642 | AH37: =AH$48*$AZ37 -> 2.5746569 | AI37: =AI$48*$AZ37 -> 4.7866861 | AJ37: =AJ$48*$AZ37 -> 4.8410803 | AK37: =AK$48*$AZ37 -> 3.1729927 | ... AS37: =AS$48*$AZ37 -> 5.3306277 | AU37: 230 | AV37: 175 | AW37: 0.73 | AX37: 0.27 | AY37: =AU37*AW37 -> 167.9 | AZ37: =AU37*AX37 -> 62.1
A38: 109 | B38: =B$50*$AY38 -> 15.404021 | C38: =C$50*$AY38 -> 3.3798946 | D38: =D$50*$AY38 -> 1.3139232 | E38: =E$50*$AY38 -> 0.0086442318 | F38: =F$50*$AY38 -> 0.3803462 | G38: =G$50*$AY38 -> 5.2124718 | H38: =H$50*$AY38 -> 3.3020965 | I38: =I$50*$AY38 -> 3.9590582 | ... AC38: =AC$50*$AY38 -> 1.8066444 | AD38: =AD$48*$AZ38 -> 7.5431241 | AE38: =AE$48*$AZ38 -> 5.3521752 | AF38: =AF$48*$AZ38 -> 5.446073 | AG38: =AG$48*$AZ38 -> 3.2551241 | AH38: =AH$48*$AZ38 -> 4.4444964 | AI38: =AI$48*$AZ38 -> 8.2630073 | AJ38: =AJ$48*$AZ38 -> 8.3569051 | AK38: =AK$48*$AZ38 -> 5.4773723 | ... AS38: =AS$48*$AZ38 -> 9.2019854 | AU38: 268 | AV38: 242 | AW38: 0.6 | AX38: 0.4 | AY38: =AU38*AW38 -> 160.8 | AZ38: =AU38*AX38 -> 107.2
A39: 110 | B39: =B$50*$AY39 -> 11.380583 | C39: =C$50*$AY39 -> 2.4970863 | D39: =D$50*$AY39 -> 0.97073433 | E39: =E$50*$AY39 -> 0.0063864101 | F39: =F$50*$AY39 -> 0.28100204 | G39: =G$50*$AY39 -> 3.8510053 | H39: =H$50*$AY39 -> 2.4396086 | I39: =I$50*$AY39 -> 2.9249758 | ... AC39: =AC$50*$AY39 -> 1.3347597 | AD39: =AD$48*$AZ39 -> 0.92881752 | AE39: =AE$48*$AZ39 -> 0.6590365 | AF39: =AF$48*$AZ39 -> 0.67059854 | AG39: =AG$48*$AZ39 -> 0.40081752 | AH39: =AH$48*$AZ39 -> 0.54727007 | AI39: =AI$48*$AZ39 -> 1.0174599 | AJ39: =AJ$48*$AZ39 -> 1.0290219 | AK39: =AK$48*$AZ39 -> 0.67445255 | ... AS39: =AS$48*$AZ39 -> 1.1330803 | AU39: 132 | AV39: 161 | AW39: 0.9 | AX39: 0.1 | AY39: =AU39*AW39 -> 118.8 | AZ39: =AU39*AX39 -> 13.2
A40: 111 | B40: =B$50*$AY40 -> 2.8738845 | C40: =C$50*$AY40 -> 0.63057736 | D40: =D$50*$AY40 -> 0.24513493 | E40: =E$50*$AY40 -> 0.0016127298 | F40: =F$50*$AY40 -> 0.070960112 | G40: =G$50*$AY40 -> 0.97247608 | H40: =H$50*$AY40 -> 0.61606279 | I40: =I$50*$AY40 -> 0.73863025 | ... AC40: =AC$50*$AY40 -> 0.33706053 | AD40: =AD$48*$AZ40 -> 8.4437956 | AE40: =AE$48*$AZ40 -> 5.9912409 | AF40: =AF$48*$AZ40 -> 6.0963504 | AG40: =AG$48*$AZ40 -> 3.6437956 | AH40: =AH$48*$AZ40 -> 4.9751825 | AI40: =AI$48*$AZ40 -> 9.249635 | AJ40: =AJ$48*$AZ40 -> 9.3547445 | AK40: =AK$48*$AZ40 -> 6.1313869 | ... AS40: =AS$48*$AZ40 -> 10.30073 | AU40: 150 | AV40: 286 | AW40: 0.2 | AX40: 0.8 | AY40: =AU40*AW40 -> 30 | AZ40: =AU40*AX40 -> 120
A41: 112 | B41: =B$50*$AY41 -> 19.705268 | C41: =C$50*$AY41 -> 4.3236587 | D41: =D$50*$AY41 -> 1.6808085 | E41: =E$50*$AY41 -> 0.011057951 | F41: =F$50*$AY41 -> 0.48654983 | G41: =G$50*$AY41 -> 6.6679443 | H41: =H$50*$AY41 -> 4.2241372 | I41: =I$50*$AY41 -> 5.0645414 | ... AC41: =AC$50*$AY41 -> 2.3111117 | AD41: =AD$48*$AZ41 -> 2.5542482 | AE41: =AE$48*$AZ41 -> 1.8123504 | AF41: =AF$48*$AZ41 -> 1.844146 | AG41: =AG$48*$AZ41 -> 1.1022482 | AH41: =AH$48*$AZ41 -> 1.5049927 | AI41: =AI$48*$AZ41 -> 2.7980146 | AJ41: =AJ$48*$AZ41 -> 2.8298102 | AK41: =AK$48*$AZ41 -> 1.8547445 | ... AS41: =AS$48*$AZ41 -> 3.1159708 | AU41: 242 | AV41: 272 | AW41: 0.85 | AX41: 0.15 | AY41: =AU41*AW41 -> 205.7 | AZ41: =AU41*AX41 -> 36.3
... A45: 116 | B45: =B$50*$AY45 -> 4.9813998 | C45: =C$50*$AY45 -> 1.0930008 | D45: =D$50*$AY45 -> 0.42490055 | E45: =E$50*$AY45 -> 0.0027953983 | F45: =F$50*$AY45 -> 0.12299753 | G45: =G$50*$AY45 -> 1.6856252 | H45: =H$50*$AY45 -> 1.0678422 | I45: =I$50*$AY45 -> 1.2802924 | ... AC45: =AC$50*$AY45 -> 0.58423825 | AD45: =AD$48*$AZ45 -> 14.635912 | AE45: =AE$48*$AZ45 -> 10.384818 | AF45: =AF$48*$AZ45 -> 10.567007 | AG45: =AG$48*$AZ45 -> 6.3159124 | AH45: =AH$48*$AZ45 -> 8.6236496 | AI45: =AI$48*$AZ45 -> 16.032701 | AJ45: =AJ$48*$AZ45 -> 16.214891 | AK45: =AK$48*$AZ45 -> 10.627737 | ... AS45: =AS$48*$AZ45 -> 17.854599 | AU45: 260 | AV45: 294 | AW45: 0.2 | AX45: 0.8 | AY45: =AU45*AW45 -> 52 | AZ45: =AU45*AX45 -> 208
AD46: =AD47/$AT$47 -> 0.070364964 | AE46: =AE47/$AT$47 -> 0.049927007 | AF46: =AF47/$AT$47 -> 0.05080292 | AG46: =AG47/$AT$47 -> 0.030364964 | AH46: =AH47/$AT$47 -> 0.041459854 | AI46: =AI47/$AT$47 -> 0.077080292 | AJ46: =AJ47/$AT$47 -> 0.077956204 | AK46: =AK47/$AT$47 -> 0.051094891 | ... AS46: =AS47/$AT$47 -> 0.085839416
AC47: outflow | AD47: 241 | AE47: 171 | AF47: 174 | AG47: 104 | AH47: 142 | AI47: 264 | AJ47: 267 | AK47: 175 | AL47: 242 | AM47: 161 | AN47: 286 | AO47: 272 | AP47: 222 | AQ47: 149 | AR47: 261 | AS47: 294 | AT47: =SUM(AD47:AS47) -> 3425
AD48: 0.070364964 | AE48: 0.049927007 | AF48: 0.05080292 | AG48: 0.030364964 | AH48: 0.041459854 | AI48: 0.077080292 | AJ48: 0.077956204 | AK48: 0.051094891 | AL48: 0.070656934 | AM48: 0.047007299 | AN48: 0.08350365 | AO48: 0.079416058 | AP48: 0.064817518 | AQ48: 0.04350365 | AR48: 0.07620438 | AS48: 0.085839416
B50: =B51/$B$52 -> 0.095796151 | C50: =C51/$B$52 -> 0.021019245 | D50: =D51/$B$52 -> 0.0081711644 | E50: =E51/$B$52 -> 5.375766e-05 | F50: =F51/$B$52 -> 0.0023653371 | G50: =G51/$B$52 -> 0.032415869 | H50: =H51/$B$52 -> 0.020535426 | I50: =I51/$B$52 -> 0.024621008 | ... AC50: =AC51/$B$52 -> 0.011235351
A51: totalworker | B51: 1782 | C51: 391 | D51: 152 | E51: 1 | F51: 44 | G51: 603 | H51: 382 | I51: 458 | J51: 139 | K51: 667 | L51: 57 | M51: 361 | N51: 2344 | O51: 588 | P51: 1753 | Q51: 130 | R51: 6 | S51: 1093 | T51: 2242 | U51: 788 | V51: 849 | W51: 270 | X51: 810 | Y51: 87 | Z51: 1082 | AA51: 116 | AB51: 1198 | AC51: 209
A52: sum | B52: =SUM(B51:AC51) -> 18602
L74: leisure
B75: 1 | C75: 2 | D75: 3 | E75: 5 | F75: 6 | G75: 7 | H75: 8 | I75: 9 | J75: 10 | K75: 11 | L75: 12 | M75: 13 | N75: 14 | O75: 15 | P75: 16 | Q75: 17 | R75: 18 | S75: 19 | T75: 20 | U75: 21 | V75: 22 | W75: 23 | X75: 24 | Y75: 25 | Z75: 26 | AA75: 27 | AB75: 28 | AC75: 29
A76: 1 | B76: 27 | C76: 27 | D76: 27 | E76: 27 | F76: 27 | G76: 27 | H76: 27 | I76: 27 | J76: 27 | K76: 27 | L76: 27 | M76: 27 | N76: 27 | O76: 27 | P76: 27 | Q76: 27 | R76: 27 | S76: 27 | T76: 27 | U76: 27 | V76: 27 | W76: 27 | X76: 27 | Y76: 27 | Z76: 27 | AA76: 27 | AB76: 27 | AC76: 27
A77: 2 | B77: 0 | C77: 0 | D77: 0 | E77: 0 | F77: 0 | G77: 0 | H77: 0 | I77: 0 | J77: 0 | K77: 0 | L77: 0 | M77: 0 | N77: 0 | O77: 0 | P77: 0 | Q77: 0 | R77: 0 | S77: 0 | T77: 0 | U77: 0 | V77: 0 | W77: 0 | X77: 0 | Y77: 0 | Z77: 0 | AA77: 0 | AB77: 0 | AC77: 0
A78: 3 | B78: 12 | C78: 12 | D78: 12 | E78: 12 | F78: 12 | G78: 12 | H78: 12 | I78: 12 | J78: 12 | K78: 12 | L78: 12 | M78: 12 | N78: 12 | O78: 12 | P78: 12 | Q78: 12 | R78: 12 | S78: 12 | T78: 12 | U78: 12 | V78: 12 | W78: 12 | X78: 12 | Y78: 12 | Z78: 12 | AA78: 12 | AB78: 12 | AC78: 12
A79: 5 | B79: 6 | C79: 6 | D79: 6 | E79: 6 | F79: 6 | G79: 6 | H79: 6 | I79: 6 | J79: 6 | K79: 6 | L79: 6 | M79: 6 | N79: 6 | O79: 6 | P79: 6 | Q79: 6 | R79: 6 | S79: 6 | T79: 6 | U79: 6 | V79: 6 | W79: 6 | X79: 6 | Y79: 6 | Z79: 6 | AA79: 6 | AB79: 6 | AC79: 6
...

Sheet 25%
B1: 1 | C1: 2 | D1: 3 | E1: 5 | F1: 6 | G1: 7 | H1: 8 | I1: 10 | J1: 11 | K1: 12 | L1: 13 | M1: 14 | N1: 15 | O1: 16 | P1: 17 | Q1: 18 | R1: 19 | S1: 20 | T1: 21 | U1: 22 | V1: 23 | W1: 24 | X1: 25 | Y1: 26 | Z1: 27 | AA1: 28 | AB1: 29
A2: 1 | B2: =computation!B2*0.25 -> 120 | C2: =computation!C2*0.25 -> 6.75 | D2: =computation!D2*0.25 -> 6.75 | E2: =computation!E2*0.25 -> 11.75 | F2: =computation!F2*0.25 -> 22.25 | G2: =computation!G2*0.25 -> 22.75 | H2: =computation!H2*0.25 -> 19.25 | I2: =computation!J2*0.25 -> 6.75 | J2: =computation!K2*0.25 -> 6.75 | K2: =computation!L2*0.25 -> 13 | L2: =computation!M2*0.25 -> 10.5 | M2: =computation!N2*0.25 -> 30 | N2: =computation!O2*0.25 -> 9.75 | O2: =computation!P2*0.25 -> 7 | P2: =computation!Q2*0.25 -> 8 | ... AB2: =computation!AC2*0.25 -> 13.5
A3: 2 | B3: =computation!B3*0.25 -> 3 | C3: =computation!C3*0.25 -> 134.5 | D3: =computation!D3*0.25 -> 3 | E3: =computation!E3*0.25 -> 3 | F3: =computation!F3*0.25 -> 3 | G3: =computation!G3*0.25 -> 3 | H3: =computation!H3*0.25 -> 3 | I3: =computation!J3*0.25 -> 3 | J3: =computation!K3*0.25 -> 3 | K3: =computation!L3*0.25 -> 3 | L3: =computation!M3*0.25 -> 3 | M3: =computation!N3*0.25 -> 3 | N3: =computation!O3*0.25 -> 3 | O3: =computation!P3*0.25 -> 3 | P3: =computation!Q3*0.25 -> 3 | ... AB3: =computation!AC3*0.25 -> 3
A4: 3 | B4: =computation!B4*0.25 -> 31.75 | C4: =computation!C4*0.25 -> 4.5 | D4: =computation!D4*0.25 -> 13.75 | E4: =computation!E4*0.25 -> 8.25 | F4: =computation!F4*0.25 -> 11.5 | G4: =computation!G4*0.25 -> 16.75 | H4: =computation!H4*0.25 -> 11.5 | I4: =computation!J4*0.25 -> 4.5 | J4: =computation!K4*0.25 -> 4.5 | K4: =computation!L4*0.25 -> 9 | L4: =computation!M4*0.25 -> 7.25 | M4: =computation!N4*0.25 -> 22.75 | N4: =computation!O4*0.25 -> 6.75 | O4: =computation!P4*0.25 -> 4.75 | P4: =computation!Q4*0.25 -> 5.5 | ... AB4: =computation!AC4*0.25 -> 8.5
A5: 5 | B5: =computation!B5*0.25 -> 11.75 | C5: =computation!C5*0.25 -> 7.5 | D5: =computation!D5*0.25 -> 7.5 | E5: =computation!E5*0.25 -> 11 | F5: =computation!F5*0.25 -> 8.75 | G5: =computation!G5*0.25 -> 12 | H5: =computation!H5*0.25 -> 9.5 | I5: =computation!J5*0.25 -> 7.5 | J5: =computation!K5*0.25 -> 7.5 | K5: =computation!L5*0.25 -> 9.5 | L5: =computation!M5*0.25 -> 9.75 | M5: =computation!N5*0.25 -> 29.25 | N5: =computation!O5*0.25 -> 11 | O5: =computation!P5*0.25 -> 7.75 | P5: =computation!Q5*0.25 -> 9 | ... AB5: =computation!AC5*0.25 -> 9
A6: 6 | B6: =computation!B6*0.25 -> 67 | C6: =computation!C6*0.25 -> 11.25 | D6: =computation!D6*0.25 -> 11.25 | E6: =computation!E6*0.25 -> 16.5 | F6: =computation!F6*0.25 -> 30.75 | G6: =computation!G6*0.25 -> 32.5 | H6: =computation!H6*0.25 -> 34.25 | I6: =computation!J6*0.25 -> 11.25 | J6: =computation!K6*0.25 -> 11.25 | K6: =computation!L6*0.25 -> 21.75 | L6: =computation!M6*0.25 -> 17.5 | M6: =computation!N6*0.25 -> 44 | N6: =computation!O6*0.25 -> 14 | O6: =computation!P6*0.25 -> 11.75 | P6: =computation!Q6*0.25 -> 12.75 | ... AB6: =computation!AC6*0.25 -> 23.75
A7: 7 | B7: =computation!B7*0.25 -> 39.75 | C7: =computation!C7*0.25 -> 12.5 | D7: =computation!D7*0.25 -> 12.5 | E7: =computation!E7*0.25 -> 21.5 | F7: =computation!F7*0.25 -> 22.75 | G7: =computation!G7*0.25 -> 40.75 | H7: =computation!H7*0.25 -> 27.5 | I7: =computation!J7*0.25 -> 12.5 | J7: =computation!K7*0.25 -> 12.5 | K7: =computation!L7*0.25 -> 25.25 | L7: =computation!M7*0.25 -> 20.75 | M7: =computation!N7*0.25 -> 66.5 | N7: =computation!O7*0.25 -> 17.25 | O7: =computation!P7*0.25 -> 13.25 | P7: =computation!Q7*0.25 -> 15.25 | ... AB7: =computation!AC7*0.25 -> 22.75
A8: 8 | B8: =computation!B8*0.25 -> 47 | C8: =computation!C8*0.25 -> 9 | D8: =computation!D8*0.25 -> 9 | E8: =computation!E8*0.25 -> 15.5 | F8: =computation!F8*0.25 -> 28.5 | G8: =computation!G8*0.25 -> 35.75 | H8: =computation!H8*0.25 -> 45 | I8: =computation!J8*0.25 -> 9 | J8: =computation!K8*0.25 -> 9 | K8: =computation!L8*0.25 -> 27.5 | L8: =computation!M8*0.25 -> 20.25 | M8: =computation!N8*0.25 -> 61.75 | N8: =computation!O8*0.25 -> 12.5 | O8: =computation!P8*0.25 -> 9.75 | P8: =computation!Q8*0.25 -> 11.5 | ... AB8: =computation!AC8*0.25 -> 33
A9: 9 | B9: =computation!B9*0.25 -> 7 | C9: =computation!C9*0.25 -> 5.5 | D9: =computation!D9*0.25 -> 5.5 | E9: =computation!E9*0.25 -> 7.5 | F9: =computation!F9*0.25 -> 6 | G9: =computation!G9*0.25 -> 7 | H9: =computation!H9*0.25 -> 6.25 | I9: =computation!J9*0.25 -> 5.5 | J9: =computation!K9*0.25 -> 5.5 | K9: =computation!L9*0.25 -> 6.5 | L9: =computation!M9*0.25 -> 7.25 | M9: =computation!N9*0.25 -> 24 | N9: =computation!O9*0.25 -> 14.5 | O9: =computation!P9*0.25 -> 8.25 | P9: =computation!Q9*0.25 -> 11.5 | ... AB9: =computation!AC9*0.25 -> 6.25
A10: 10 | B10: =computation!B10*0.25 -> 20.5 | C10: =computation!C10*0.25 -> 3.75 | D10: =computation!D10*0.25 -> 3.75 | E10: =computation!E10*0.25 -> 8 | F10: =computation!F10*0.25 -> 12 | G10: =computation!G10*0.25 -> 19.5 | H10: =computation!H10*0.25 -> 21.5 | I10: =computation!J10*0.25 -> 19.75 | J10: =computation!K10*0.25 -> 3.75 | K10: =computation!L10*0.25 -> 17 | L10: =computation!M10*0.25 -> 11.75 | M10: =computation!N10*0.25 -> 41 | N10: =computation!O10*0.25 -> 6 | O10: =computation!P10*0.25 -> 4.25 | P10: =computation!Q10*0.25 -> 5.5 | ... AB10: =computation!AC10*0.25 -> 18.5
A11: 11 | B11: =computation!B11*0.25 -> 1.75 | C11: =computation!C11*0.25 -> 1.75 | D11: =computation!D11*0.25 -> 1.75 | E11: =computation!E11*0.25 -> 1.75 | F11: =computation!F11*0.25 -> 1.75 | G11: =computation!G11*0.25 -> 1.75 | H11: =computation!H11*0.25 -> 1.75 | I11: =computation!J11*0.25 -> 1.75 | J11: =computation!K11*0.25 -> 12.75 | K11: =computation!L11*0.25 -> 1.75 | L11: =computation!M11*0.25 -> 1.75 | M11: =computation!N11*0.25 -> 1.75 | N11: =computation!O11*0.25 -> 1.75 | O11: =computation!P11*0.25 -> 1.75 | P11: =computation!Q11*0.25 -> 1.75 | ... AB11: =computation!AC11*0.25 -> 1.75
A12: 12 | B12: =computation!B12*0.25 -> 10 | C12: =computation!C12*0.25 -> 4 | D12: =computation!D12*0.25 -> 4 | E12: =computation!E12*0.25 -> 6.25 | F12: =computation!F12*0.25 -> 6.75 | G12: =computation!G12*0.25 -> 11 | H12: =computation!H12*0.25 -> 9.75 | I12: =computation!J12*0.25 -> 4 | J12: =computation!K12*0.25 -> 4 | K12: =computation!L12*0.25 -> 10.5 | L12: =computation!M12*0.25 -> 8.5 | M12: =computation!N12*0.25 -> 25.5 | N12: =computation!O12*0.25 -> 5.25 | O12: =computation!P12*0.25 -> 4.25 | P12: =computation!Q12*0.25 -> 5 | ... AB12: =computation!AC12*0.25 -> 9.5
A13: 13 | B13: =computation!B13*0.25 -> 8.25 | C13: =computation!C13*0.25 -> 4.5 | D13: =computation!D13*0.25 -> 4.5 | E13: =computation!E13*0.25 -> 7 | F13: =computation!F13*0.25 -> 6.25 | G13: =computation!G13*0.25 -> 9.25 | H13: =computation!H13*0.25 -> 8.25 | I13: =computation!J13*0.25 -> 4.5 | J13: =computation!K13*0.25 -> 4.5 | K13: =computation!L13*0.25 -> 9.25 | L13: =computation!M13*0.25 -> 14 | M13: =computation!N13*0.25 -> 46.25 | N13: =computation!O13*0.25 -> 6.25 | O13: =computation!P13*0.25 -> 5.5 | P13: =computation!Q13*0.25 -> 7 | ... AB13: =computation!AC13*0.25 -> 9
... A29: 29 | B29: =computation!B29*0.25 -> 18 | C29: =computation!C29*0.25 -> 3.75 | D29: =computation!D29*0.25 -> 3.75 | E29: =computation!E29*0.25 -> 7.25 | F29: =computation!F29*0.25 -> 11 | G29: =computation!G29*0.25 -> 16.5 | H29: =computation!H29*0.25 -> 20.5 | I29: =computation!J29*0.25 -> 3.75 | J29: =computation!K29*0.25 -> 3.75 | K29: =computation!L29*0.25 -> 16.25 | L29: =computation!M29*0.25 -> 13.25 | M29: =computation!N29*0.25 -> 41.25 | N29: =computation!O29*0.25 -> 5.75 | O29: =computation!P29*0.25 -> 4.5 | P29: =computation!Q29*0.25 -> 5.5 | ... AB29: =computation!AC29*0.25 -> 22.25
S33: round
F35: 1 | G35: 2 | H35: 3 | I35: 5 | J35: 6 | K35: 7 | L35: 8 | M35: 9 | N35: 10 | O35: 11 | P35: 12 | Q35: 13 | R35: 14 | S35: 15 | T35: 16 | U35: 17 | V35: 18 | W35: 19 | X35: 20 | Y35: 21 | Z35: 22 | AA35: 23 | AB35: 24 | AC35: 25 | AD35: 26 | AE35: 27 | AF35: 28 | AG35: 29 | AH35: 101 | AI35: 102 | AJ35: 103 | AK35: 104 | AL35: 105 | AM35: 106 | AN35: 107 | AO35: 108 | AP35: 109 | AQ35: 110 | AR35: 111 | AS35: 112 | AT35: 113 | AU35: 114 | AV35: 115 | AW35: 116
E36: 1 | F36: =ROUND(B2,0) -> 120 | G36: =ROUND(C2,0) -> 7 | H36: =ROUND(D2,0) -> 7 | I36: =ROUND(E2,0) -> 12 | J36: =ROUND(F2,0) -> 22 | K36: =ROUND(G2,0) -> 23 | L36: =ROUND(H2,0) -> 19 | M36: =ROUND(I2,0) -> 7 | ... AF36: =ROUND(AB2,0) -> 14 | AG36: =ROUND(AB2,0) -> 14 | AH36: =ROUND(computation!AD2,0) -> 62 | AI36: =ROUND(computation!AE2,0) -> 44 | AJ36: =ROUND(computation!AF2,0) -> 45 | AK36: =ROUND(computation!AG2,0) -> 27 | AL36: =ROUND(computation!AH2,0) -> 37 | AM36: =ROUND(computation!AI2,0) -> 68 | AN36: =ROUND(computation!AJ2,0) -> 69 | AO36: =ROUND(computation!AK2,0) -> 45 | ... AW36: =ROUND(computation!AS2,0) -> 76
E37: 2 | F37: =ROUND(B3,0) -> 3 | G37: =ROUND(C3,0) -> 135 | H37: =ROUND(D3,0) -> 3 | I37: =ROUND(E3,0) -> 3 | J37: =ROUND(F3,0) -> 3 | K37: =ROUND(G3,0) -> 3 | L37: =ROUND(H3,0) -> 3 | M37: =ROUND(I3,0) -> 3 | ... AF37: =ROUND(AB3,0) -> 3 | AG37: =ROUND(AB3,0) -> 3 | AH37: =ROUND(computation!AD3,0) -> 33 | AI37: =ROUND(computation!AE3,0) -> 24 | AJ37: =ROUND(computation!AF3,0) -> 24 | AK37: =ROUND(computation!AG3,0) -> 14 | AL37: =ROUND(computation!AH3,0) -> 20 | AM37: =ROUND(computation!AI3,0) -> 37 | AN37: =ROUND(computation!AJ3,0) -> 37 | AO37: =ROUND(computation!AK3,0) -> 24 | ... AW37: =ROUND(computation!AS3,0) -> 41
E38: 3 | F38: =ROUND(B4,0) -> 32 | G38: =ROUND(C4,0) -> 5 | H38: =ROUND(D4,0) -> 14 | I38: =ROUND(E4,0) -> 8 | J38: =ROUND(F4,0) -> 12 | K38: =ROUND(G4,0) -> 17 | L38: =ROUND(H4,0) -> 12 | M38: =ROUND(I4,0) -> 5 | ... AF38: =ROUND(AB4,0) -> 9 | AG38: =ROUND(AB4,0) -> 9 | AH38: =ROUND(computation!AD4,0) -> 21 | AI38: =ROUND(computation!AE4,0) -> 15 | AJ38: =ROUND(computation!AF4,0) -> 15 | AK38: =ROUND(computation!AG4,0) -> 9 | AL38: =ROUND(computation!AH4,0) -> 12 | AM38: =ROUND(computation!AI4,0) -> 23 | AN38: =ROUND(computation!AJ4,0) -> 23 | AO38: =ROUND(computation!AK4,0) -> 15 | ... AW38: =ROUND(computation!AS4,0) -> 25
E39: 5 | F39: =ROUND(B5,0) -> 12 | G39: =ROUND(C5,0) -> 8 | H39: =ROUND(D5,0) -> 8 | I39: =ROUND(E5,0) -> 11 | J39: =ROUND(F5,0) -> 9 | K39: =ROUND(G5,0) -> 12 | L39: =ROUND(H5,0) -> 10 | M39: =ROUND(I5,0) -> 8 | ... AF39: =ROUND(AB5,0) -> 9 | AG39: =ROUND(AB5,0) -> 9 | AH39: =ROUND(computation!AD5,0) -> 10 | AI39: =ROUND(computation!AE5,0) -> 7 | AJ39: =ROUND(computation!AF5,0) -> 7 | AK39: =ROUND(computation!AG5,0) -> 4 | AL39: =ROUND(computation!AH5,0) -> 6 | AM39: =ROUND(computation!AI5,0) -> 11 | AN39: =ROUND(computation!AJ5,0) -> 11 | AO39: =ROUND(computation!AK5,0) -> 7 | ... AW39: =ROUND(computation!AS5,0) -> 12
E40: 6 | F40: =ROUND(B6,0) -> 67 | G40: =ROUND(C6,0) -> 11 | H40: =ROUND(D6,0) -> 11 | I40: =ROUND(E6,0) -> 17 | J40: =ROUND(F6,0) -> 31 | K40: =ROUND(G6,0) -> 33 | L40: =ROUND(H6,0) -> 34 | M40: =ROUND(I6,0) -> 11 | ... AF40: =ROUND(AB6,0) -> 24 | AG40: =ROUND(AB6,0) -> 24 | AH40: =ROUND(computation!AD6,0) -> 47 | AI40: =ROUND(computation!AE6,0) -> 33 | AJ40: =ROUND(computation!AF6,0) -> 34 | AK40: =ROUND(computation!AG6,0) -> 20 | AL40: =ROUND(computation!AH6,0) -> 27 | AM40: =ROUND(computation!AI6,0) -> 51 | AN40: =ROUND(computation!AJ6,0) -> 52 | AO40: =ROUND(computation!AK6,0) -> 34 | ... AW40: =ROUND(computation!AS6,0) -> 57
E41: 7 | F41: =ROUND(B7,0) -> 40 | G41: =ROUND(C7,0) -> 13 | H41: =ROUND(D7,0) -> 13 | I41: =ROUND(E7,0) -> 22 | J41: =ROUND(F7,0) -> 23 | K41: =ROUND(G7,0) -> 41 | L41: =ROUND(H7,0) -> 28 | M41: =ROUND(I7,0) -> 13 | ... AF41: =ROUND(AB7,0) -> 23 | AG41: =ROUND(AB7,0) -> 23 | AH41: =ROUND(computation!AD7,0) -> 42 | AI41: =ROUND(computation!AE7,0) -> 30 | AJ41: =ROUND(computation!AF7,0) -> 30 | AK41: =ROUND(computation!AG7,0) -> 18 | AL41: =ROUND(computation!AH7,0) -> 25 | AM41: =ROUND(computation!AI7,0) -> 46 | AN41: =ROUND(computation!AJ7,0) -> 47 | AO41: =ROUND(computation!AK7,0) -> 31 | ... AW41: =ROUND(computation!AS7,0) -> 52
E42: 8 | F42: =ROUND(B8,0) -> 47 | G42: =ROUND(C8,0) -> 9 | H42: =ROUND(D8,0) -> 9 | I42: =ROUND(E8,0) -> 16 | J42: =ROUND(F8,0) -> 29 | K42: =ROUND(G8,0) -> 36 | L42: =ROUND(H8,0) -> 45 | M42: =ROUND(I8,0) -> 9 | ... AF42: =ROUND(AB8,0) -> 33 | AG42: =ROUND(AB8,0) -> 33 | AH42: =ROUND(computation!AD8,0) -> 48 | AI42: =ROUND(computation!AE8,0) -> 34 | AJ42: =ROUND(computation!AF8,0) -> 35 | AK42: =ROUND(computation!AG8,0) -> 21 | AL42: =ROUND(computation!AH8,0) -> 29 | AM42: =ROUND(computation!AI8,0) -> 53 | AN42: =ROUND(computation!AJ8,0) -> 54 | AO42: =ROUND(computation!AK8,0) -> 35 | ... AW42: =ROUND(computation!AS8,0) -> 59
E43: 9 | F43: =ROUND(B9,0) -> 7 | G43: =ROUND(C9,0) -> 6 | H43: =ROUND(D9,0) -> 6 | I43: =ROUND(E9,0) -> 8 | J43: =ROUND(F9,0) -> 6 | K43: =ROUND(G9,0) -> 7 | L43: =ROUND(H9,0) -> 6 | M43: =ROUND(I9,0) -> 6 | ... AF43: =ROUND(AB9,0) -> 6 | AG43: =ROUND(AB9,0) -> 6 | AH43: =ROUND(computation!AD9,0) -> 22 | AI43: =ROUND(computation!AE9,0) -> 16 | AJ43: =ROUND(computation!AF9,0) -> 16 | AK43: =ROUND(computation!AG9,0) -> 9 | AL43: =ROUND(computation!AH9,0) -> 13 | AM43: =ROUND(computation!AI9,0) -> 24 | AN43: =ROUND(computation!AJ9,0) -> 24 | AO43: =ROUND(computation!AK9,0) -> 16 | ... AW43: =ROUND(computation!AS9,0) -> 27
E44: 10 | F44: =ROUND(B10,0) -> 21 | G44: =ROUND(C10,0) -> 4 | H44: =ROUND(D10,0) -> 4 | I44: =ROUND(E10,0) -> 8 | J44: =ROUND(F10,0) -> 12 | K44: =ROUND(G10,0) -> 20 | L44: =ROUND(H10,0) -> 22 | M44: =ROUND(I10,0) -> 20 | ... AF44: =ROUND(AB10,0) -> 19 | AG44: =ROUND(AB10,0) -> 19 | AH44: =ROUND(computation!AD10,0) -> 34 | AI44: =ROUND(computation!AE10,0) -> 24 | AJ44: =ROUND(computation!AF10,0) -> 24 | AK44: =ROUND(computation!AG10,0) -> 15 | AL44: =ROUND(computation!AH10,0) -> 20 | AM44: =ROUND(computation!AI10,0) -> 37 | AN44: =ROUND(computation!AJ10,0) -> 37 | AO44: =ROUND(computation!AK10,0) -> 24 | ... AW44: =ROUND(computation!AS10,0) -> 41
E45: 11 | F45: =ROUND(B11,0) -> 2 | G45: =ROUND(C11,0) -> 2 | H45: =ROUND(D11,0) -> 2 | I45: =ROUND(E11,0) -> 2 | J45: =ROUND(F11,0) -> 2 | K45: =ROUND(G11,0) -> 2 | L45: =ROUND(H11,0) -> 2 | M45: =ROUND(I11,0) -> 2 | ... AF45: =ROUND(AB11,0) -> 2 | AG45: =ROUND(AB11,0) -> 2 | AH45: =ROUND(computation!AD11,0) -> 2 | AI45: =ROUND(computation!AE11,0) -> 1 | AJ45: =ROUND(computation!AF11,0) -> 1 | AK45: =ROUND(computation!AG11,0) -> 1 | AL45: =ROUND(computation!AH11,0) -> 1 | AM45: =ROUND(computation!AI11,0) -> 2 | AN45: =ROUND(computation!AJ11,0) -> 2 | AO45: =ROUND(computation!AK11,0) -> 1 | ... AW45: =ROUND(computation!AS11,0) -> 2
E46: 12 | F46: =ROUND(B12,0) -> 10 | G46: =ROUND(C12,0) -> 4 | H46: =ROUND(D12,0) -> 4 | I46: =ROUND(E12,0) -> 6 | J46: =ROUND(F12,0) -> 7 | K46: =ROUND(G12,0) -> 11 | L46: =ROUND(H12,0) -> 10 | M46: =ROUND(I12,0) -> 4 | ... AF46: =ROUND(AB12,0) -> 10 | AG46: =ROUND(AB12,0) -> 10 | AH46: =ROUND(computation!AD12,0) -> 17 | AI46: =ROUND(computation!AE12,0) -> 12 | AJ46: =ROUND(computation!AF12,0) -> 12 | AK46: =ROUND(computation!AG12,0) -> 7 | AL46: =ROUND(computation!AH12,0) -> 10 | AM46: =ROUND(computation!AI12,0) -> 18 | AN46: =ROUND(computation!AJ12,0) -> 19 | AO46: =ROUND(computation!AK12,0) -> 12 | ... AW46: =ROUND(computation!AS12,0) -> 21
E47: 13 | F47: =ROUND(B13,0) -> 8 | G47: =ROUND(C13,0) -> 5 | H47: =ROUND(D13,0) -> 5 | I47: =ROUND(E13,0) -> 7 | J47: =ROUND(F13,0) -> 6 | K47: =ROUND(G13,0) -> 9 | L47: =ROUND(H13,0) -> 8 | M47: =ROUND(I13,0) -> 5 | ... AF47: =ROUND(AB13,0) -> 9 | AG47: =ROUND(AB13,0) -> 9 | AH47: =ROUND(computation!AD13,0) -> 18 | AI47: =ROUND(computation!AE13,0) -> 13 | AJ47: =ROUND(computation!AF13,0) -> 13 | AK47: =ROUND(computation!AG13,0) -> 8 | AL47: =ROUND(computation!AH13,0) -> 10 | AM47: =ROUND(computation!AI13,0) -> 19 | AN47: =ROUND(computation!AJ13,0) -> 20 | AO47: =ROUND(computation!AK13,0) -> 13 | ... AW47: =ROUND(computation!AS13,0) -> 22
... E63: 29 | F63: =ROUND(B29,0) -> 18 | G63: =ROUND(C29,0) -> 4 | H63: =ROUND(D29,0) -> 4 | I63: =ROUND(E29,0) -> 7 | J63: =ROUND(F29,0) -> 11 | K63: =ROUND(G29,0) -> 17 | L63: =ROUND(H29,0) -> 21 | M63: =ROUND(I29,0) -> 4 | ... AF63: =ROUND(AB29,0) -> 22 | AG63: =ROUND(AB29,0) -> 22 | AH63: =ROUND(computation!AD29,0) -> 30 | AI63: =ROUND(computation!AE29,0) -> 21 | AJ63: =ROUND(computation!AF29,0) -> 21 | AK63: =ROUND(computation!AG29,0) -> 13 | AL63: =ROUND(computation!AH29,0) -> 18 | AM63: =ROUND(computation!AI29,0) -> 33 | AN63: =ROUND(computation!AJ29,0) -> 33 | AO63: =ROUND(computation!AK29,0) -> 22 | ... AW63: =ROUND(computation!AS29,0) -> 36
E64: 101 | F64: =ROUND(computation!B30,0) -> 5 | G64: =ROUND(computation!C30,0) -> 1 | H64: =ROUND(computation!D30,0) -> 0 | I64: =ROUND(computation!E30,0) -> 0 | J64: =ROUND(computation!F30,0) -> 0 | K64: =ROUND(computation!G30,0) -> 2 | L64: =ROUND(computation!H30,0) -> 1 | M64: =ROUND(computation!I30,0) -> 1 | ... AW64: =ROUND(computation!AS30,0) -> 10
E65: 102 | F65: =ROUND(computation!B31,0) -> 3 | G65: =ROUND(computation!C31,0) -> 1 | H65: =ROUND(computation!D31,0) -> 0 | I65: =ROUND(computation!E31,0) -> 0 | J65: =ROUND(computation!F31,0) -> 0 | K65: =ROUND(computation!G31,0) -> 1 | L65: =ROUND(computation!H31,0) -> 1 | M65: =ROUND(computation!I31,0) -> 1 | ... AW65: =ROUND(computation!AS31,0) -> 20
E66: 103 | F66: =ROUND(computation!B32,0) -> 13 | G66: =ROUND(computation!C32,0) -> 3 | H66: =ROUND(computation!D32,0) -> 1 | I66: =ROUND(computation!E32,0) -> 0 | J66: =ROUND(computation!F32,0) -> 0 | K66: =ROUND(computation!G32,0) -> 4 | L66: =ROUND(computation!H32,0) -> 3 | M66: =ROUND(computation!I32,0) -> 3 | ... AW66: =ROUND(computation!AS32,0) -> 12
E67: 104 | F67: =ROUND(computation!B33,0) -> 6 | G67: =ROUND(computation!C33,0) -> 1 | H67: =ROUND(computation!D33,0) -> 0 | I67: =ROUND(computation!E33,0) -> 0 | J67: =ROUND(computation!F33,0) -> 0 | K67: =ROUND(computation!G33,0) -> 2 | L67: =ROUND(computation!H33,0) -> 1 | M67: =ROUND(computation!I33,0) -> 1 | ... AW67: =ROUND(computation!AS33,0) -> 8
E68: 105 | F68: =ROUND(computation!B34,0) -> 17 | G68: =ROUND(computation!C34,0) -> 4 | H68: =ROUND(computation!D34,0) -> 1 | I68: =ROUND(computation!E34,0) -> 0 | J68: =ROUND(computation!F34,0) -> 0 | K68: =ROUND(computation!G34,0) -> 6 | L68: =ROUND(computation!H34,0) -> 4 | M68: =ROUND(computation!I34,0) -> 4 | ... AW68: =ROUND(computation!AS34,0) -> 4
E69: 106 | F69: =ROUND(computation!B35,0) -> 14 | G69: =ROUND(computation!C35,0) -> 3 | H69: =ROUND(computation!D35,0) -> 1 | I69: =ROUND(computation!E35,0) -> 0 | J69: =ROUND(computation!F35,0) -> 0 | K69: =ROUND(computation!G35,0) -> 5 | L69: =ROUND(computation!H35,0) -> 3 | M69: =ROUND(computation!I35,0) -> 4 | ... AW69: =ROUND(computation!AS35,0) -> 10
E70: 107 | F70: =ROUND(computation!B36,0) -> 5 | G70: =ROUND(computation!C36,0) -> 1 | H70: =ROUND(computation!D36,0) -> 0 | I70: =ROUND(computation!E36,0) -> 0 | J70: =ROUND(computation!F36,0) -> 0 | K70: =ROUND(computation!G36,0) -> 2 | L70: =ROUND(computation!H36,0) -> 1 | M70: =ROUND(computation!I36,0) -> 1 | ... AW70: =ROUND(computation!AS36,0) -> 14
E71: 108 | F71: =ROUND(computation!B37,0) -> 16 | G71: =ROUND(computation!C37,0) -> 4 | H71: =ROUND(computation!D37,0) -> 1 | I71: =ROUND(computation!E37,0) -> 0 | J71: =ROUND(computation!F37,0) -> 0 | K71: =ROUND(computation!G37,0) -> 5 | L71: =ROUND(computation!H37,0) -> 3 | M71: =ROUND(computation!I37,0) -> 4 | ... AW71: =ROUND(computation!AS37,0) -> 5
E72: 109 | F72: =ROUND(computation!B38,0) -> 15 | G72: =ROUND(computation!C38,0) -> 3 | H72: =ROUND(computation!D38,0) -> 1 | I72: =ROUND(computation!E38,0) -> 0 | J72: =ROUND(computation!F38,0) -> 0 | K72: =ROUND(computation!G38,0) -> 5 | L72: =ROUND(computation!H38,0) -> 3 | M72: =ROUND(computation!I38,0) -> 4 | ... AW72: =ROUND(computation!AS38,0) -> 9
E73: 110 | F73: =ROUND(computation!B39,0) -> 11 | G73: =ROUND(computation!C39,0) -> 2 | H73: =ROUND(computation!D39,0) -> 1 | I73: =ROUND(computation!E39,0) -> 0 | J73: =ROUND(computation!F39,0) -> 0 | K73: =ROUND(computation!G39,0) -> 4 | L73: =ROUND(computation!H39,0) -> 2 | M73: =ROUND(computation!I39,0) -> 3 | ... AW73: =ROUND(computation!AS39,0) -> 1
E74: 111 | F74: =ROUND(computation!B40,0) -> 3 | G74: =ROUND(computation!C40,0) -> 1 | H74: =ROUND(computation!D40,0) -> 0 | I74: =ROUND(computation!E40,0) -> 0 | J74: =ROUND(computation!F40,0) -> 0 | K74: =ROUND(computation!G40,0) -> 1 | L74: =ROUND(computation!H40,0) -> 1 | M74: =ROUND(computation!I40,0) -> 1 | ... AW74: =ROUND(computation!AS40,0) -> 10
...

Sheet random
A1: externalzone | B1: inflow | C1: outflow
A2: 101 | B2: 174 | C2: 241
A3: 102 | B3: 263 | C3: 171
A4: 103 | B4: 271 | C4: 174
A5: 104 | B5: 146 | C5: 104
A6: 105 | B6: 217 | C6: 142
A7: 106 | B7: 260 | C7: 264
A8: 107 | B8: 213 | C8: 267
A9: 108 | B9: 230 | C9: 175
A10: 109 | B10: 268 | C10: 242
A11: 110 | B11: 132 | C11: 161
A12: 111 | B12: 150 | C12: 286
A13: 112 | B13: 242 | C13: 272
... A17: 116 | B17: 260 | C17: 294
