Workbook

Sheet data
A1: idzoning | B1: p61 employees | C1: p131 students | D1: pf1 family
A2: 1 | B2: 953 | C2: 229 | D2: 1094
A3: 2 | B3: 558 | C3: 149 | D3: 633
A4: 3 | B4: 478 | C4: 144 | D4: 592
A5: 5 | B5: 0 | C5: 0 | D5: 0
A6: 6 | B6: 268 | C6: 71 | D6: 318
A7: 7 | B7: 921 | C7: 233 | D7: 1108
A8: 8 | B8: 947 | C8: 269 | D8: 1067
A9: 9 | B9: 1193 | C9: 299 | D9: 1488
A10: 10 | B10: 468 | C10: 114 | D10: 500
A11: 11 | B11: 787 | C11: 186 | D11: 882
A12: 12 | B12: 47 | C12: 12 | D12: 61
A13: 13 | B13: 341 | C13: 100 | D13: 386
... A45: 0 | B45: 0 | C45: 0 | D45: 0

Sheet dsitancematrix
B1: 1 | C1: 2 | D1: 3 | E1: 5 | F1: 6 | G1: 7 | H1: 8 | I1: 9 | J1: 10 | K1: 11 | L1: 12 | M1: 13 | N1: 14 | O1: 15 | P1: 16 | Q1: 17 | R1: 18 | S1: 19 | T1: 20 | U1: 21 | V1: 22 | W1: 23 | X1: 24 | Y1: 25 | Z1: 26 | AA1: 27 | AB1: 28 | AC1: 29 | AD1: 101 | AE1: 102 | AF1: 103 | AG1: 104 | AH1: 105 | AI1: 106 | AJ1: 107 | AK1: 108 | AL1: 109 | AM1: 110 | AN1: 111 | AO1: 112 | AP1: 113 | AQ1: 114 | AR1: 115
A2: 1 | B2: 0.68181955 | C2: 1.284534 | D2: 1.192822 | E2: 2.86295 | F2: 1.27848 | G2: 1.966059 | H2: 2.016857 | I2: 6.037658 | J2: 2.304832 | K2: 2.588122 | L2: 2.588945 | M2: 3.732644 | N2: 3.669351 | O2: 4.289047 | P2: 9.207378 | Q2: 5.012865 | R2: 4.858912 | S2: 5.345885 | T2: 6.695306 | U2: 7.363369 | V2: 9.366328 | W2: 8.135048 | X2: 6.118518 | Y2: 5.674337 | Z2: 6.61103 | AA2: 7.650443 | AB2: 3.185189 | AC2: 2.668138 | AD2: 10.802906 | AE2: 6.659687 | AF2: 7.336507 | AG2: 6.360181 | AH2: 7.55162 | AI2: 8.299856 | AJ2: 9.628539 | AK2: 8.150397 | AL2: 7.86928 | AM2: 6.657017 | AN2: 6.282654 | AO2: 4.430696 | AP2: 0.755505 | AQ2: 1.097192 | AR2: 1.219731 | AS2: 2.091159
A3: 2 | B3: 1.284534 | C3: 0.52285065 | D3: 0.782342 | E3: 1.78496 | F3: 1.642389 | G3: 1.430796 | H3: 2.113246 | I3: 4.832659 | J3: 2.182867 | K3: 1.968643 | L3: 2.267015 | M3: 3.231137 | N3: 2.85932 | O3: 3.038381 | P3: 8.427841 | Q3: 4.022587 | R3: 4.218967 | S3: 4.859198 | T3: 5.696777 | U3: 6.578801 | V3: 8.444111 | W3: 7.15381 | X3: 5.729511 | Y3: 4.928213 | Z3: 6.04059 | AA3: 6.518905 | AB3: 2.460191 | AC3: 2.64731 | AD3: 9.801818 | AE3: 6.369103 | AF3: 6.893177 | AG3: 6.086192 | AH3: 6.941477 | AI3: 7.714135 | AJ3: 8.598343 | AK3: 6.973114 | AL3: 6.67606 | AM3: 5.406179 | AN3: 5.010943 | AO3: 3.156372 | AP3: 1.829099 | AQ3: 2.30603 | AR3: 1.58082 | AS3: 1.705355
A4: 3 | B4: 1.192822 | C4: 0.782342 | D4: 0.64758372 | E4: 1.710536 | F4: 0.911674 | G4: 0.818482 | H4: 1.332103 | I4: 4.921398 | J4: 1.433054 | K4: 1.436406 | L4: 1.583223 | M4: 2.653597 | N4: 2.486271 | O4: 3.253456 | P4: 8.048577 | Q4: 3.820956 | R4: 3.732354 | S4: 4.290349 | T4: 5.502802 | U4: 6.200056 | V4: 8.178156 | W4: 6.942302 | X4: 5.119791 | Y4: 4.516805 | Z4: 5.52268 | AA4: 6.482144 | AB4: 2.014924 | AC4: 1.887514 | AD4: 9.610084 | AE4: 5.722149 | AF4: 6.313279 | AG4: 5.431706 | AH4: 6.449403 | AI4: 7.210189 | AJ4: 8.436768 | AK4: 7.004267 | AL4: 6.735146 | AM4: 5.596108 | AN4: 5.275444 | AO4: 3.644563 | AP4: 1.925547 | AQ4: 2.285091 | AR4: 2.032725 | AS4: 2.42808
A5: 5 | B5: 2.86295 | C5: 1.78496 | D5: 1.710536 | E5: 0.83095856 | F5: 2.364418 | G5: 1.260966 | H5: 2.232347 | I5: 3.21577 | J5: 1.968463 | K5: 1.102562 | L5: 1.705133 | M5: 2.024143 | N5: 1.27398 | O5: 1.663624 | P5: 6.702036 | Q5: 2.239988 | R5: 2.699365 | S5: 3.470033 | T5: 3.911817 | U5: 4.863872 | V5: 6.665207 | W5: 5.368951 | X5: 4.400756 | Y5: 3.270001 | Z5: 4.506579 | AA5: 4.787915 | AB5: 1.113273 | AC5: 2.344775 | AD5: 8.017915 | AE5: 5.122256 | AF5: 5.459268 | AG5: 4.87291 | AH5: 5.349436 | AI5: 6.129299 | AJ5: 6.818116 | AK5: 5.295209 | AL5: 5.024614 | AM5: 3.925964 | AN5: 3.664738 | AO5: 2.475217 | AP5: 3.540206 | AQ5: 3.95825 | AR5: 3.360904 | AS5: 3.228292
A6: 6 | B6: 1.27848 | C6: 1.642389 | D6: 0.911674 | E6: 2.364418 | F6: 0.54115811 | G6: 1.134496 | H6: 0.745563 | I6: 5.546209 | J6: 1.082328 | K6: 1.649081 | L6: 1.436246 | M6: 2.59349 | N6: 2.759565 | O6: 4.004565 | P6: 8.129365 | Q6: 4.208612 | R6: 3.757006 | S6: 4.153375 | T6: 5.849243 | U6: 6.30768 | V6: 8.401923 | W6: 7.244566 | X6: 4.882348 | Y6: 4.621184 | Z6: 5.438512 | AA6: 6.972552 | AB6: 2.247205 | AC6: 1.3975 | AD6: 9.907828 | AE6: 5.397471 | AF6: 6.108357 | AG6: 5.096271 | AH6: 6.388663 | AI6: 7.119678 | AJ6: 8.777705 | AK6: 7.55116 | AL6: 7.309592 | AM6: 6.288022 | AN6: 6.022315 | AO6: 4.520573 | AP6: 1.988568 | AQ6: 2.148818 | AR6: 2.452091 | AS6: 3.120863
A7: 7 | B7: 1.966059 | C7: 1.430796 | D7: 0.818482 | E7: 1.260966 | F7: 1.134496 | G7: 0.40319152 | H7: 1.011339 | I7: 4.41292 | J7: 0.86612 | K7: 0.62354 | L7: 0.843324 | M7: 1.840484 | N7: 1.713728 | O7: 2.923 | P7: 7.244206 | Q7: 3.116813 | R7: 2.915117 | S7: 3.478316 | T7: 4.782451 | U7: 5.398419 | V7: 7.411004 | W7: 6.204125 | X7: 4.321997 | Y7: 3.710875 | Z7: 4.704665 | AA7: 5.853554 | AB7: 1.220269 | AC7: 1.327655 | AD7: 8.873441 | AE7: 4.944987 | AF7: 5.50589 | AG7: 4.659596 | AH7: 5.630941 | AI7: 6.391868 | AJ7: 7.719018 | AK7: 6.421262 | AL7: 6.176424 | AM7: 5.166047 | AN7: 4.924274 | AO7: 3.598071 | AP7: 2.716313 | AQ7: 3.030204 | AR7: 2.845224 | AS7: 3.136147
A8: 8 | B8: 2.016857 | C8: 2.113246 | D8: 1.332103 | E8: 2.232347 | F8: 0.745563 | G8: 1.011339 | H8: 0.29758741 | I8: 5.254316 | J8: 0.411066 | K8: 1.254436 | L8: 0.823868 | M8: 1.928108 | N8: 2.275295 | O8: 3.891076 | P8: 7.459444 | Q8: 3.74534 | R8: 3.097954 | S8: 3.435072 | T8: 5.329186 | U8: 5.656666 | V8: 7.79345 | W8: 6.684886 | X8: 4.142567 | Y8: 3.984001 | Z8: 4.726435 | AA8: 6.543487 | AB8: 1.775706 | AC8: 0.652304 | AD8: 9.332756 | AE8: 4.651911 | AF8: 5.370459 | AG8: 4.350723 | AH8: 5.679068 | AI8: 6.400601 | AJ8: 8.232398 | AK8: 7.163736 | AL8: 6.948601 | AM8: 6.057372 | AN8: 5.86258 | AO8: 4.60939 | AP8: 2.734087 | AQ8: 2.87963 | AR8: 3.160245 | AS8: 3.732045
A9: 9 | B9: 6.037658 | C9: 4.832659 | D9: 4.921398 | E9: 3.21577 | F9: 5.546209 | G9: 4.41292 | H9: 5.254316 | I9: 0.96263855 | J9: 4.893069 | K9: 4.000116 | L9: 4.50766 | M9: 3.952552 | N9: 3.10158 | O9: 1.85508 | P9: 5.126288 | Q9: 1.88906 | R9: 3.486655 | S9: 4.235979 | T9: 2.026888 | U9: 3.722821 | V9: 4.503375 | W9: 3.13508 | X9: 4.993001 | Y9: 3.147184 | Z9: 4.409811 | AA9: 1.861494 | AB9: 3.528169 | AC9: 5.105011 | AD9: 5.431627 | AE9: 5.73571 | AF9: 5.462783 | AG9: 5.628239 | AH9: 4.778525 | AI9: 5.430094 | AJ9: 4.190833 | AK9: 2.159824 | AL9: 1.845716 | AM9: 0.924768 | AN9: 1.185671 | AO9: 2.694225 | AP9: 6.65983 | AQ9: 7.117705 | AR9: 6.28898 | AS9: 5.768598
A10: 10 | B10: 2.304832 | C10: 2.182867 | D10: 1.433054 | E10: 1.968463 | F10: 1.082328 | G10: 0.86612 | H10: 0.411066 | I10: 4.893069 | J10: 0.25755239 | K10: 0.913918 | L10: 0.415192 | M10: 1.52801 | N10: 1.877181 | O10: 3.60353 | P10: 7.065145 | Q10: 3.345541 | R10: 2.697721 | S10: 3.071261 | T10: 4.920057 | U10: 5.255719 | V10: 7.385068 | W10: 6.273822 | X10: 3.815278 | Y10: 3.578915 | Z10: 4.356371 | AA10: 6.145925 | AB10: 1.386082 | AC10: 0.470155 | AD10: 8.922027 | AE10: 4.360548 | AF10: 5.03689 | AG10: 4.063052 | AH10: 5.306932 | AI10: 6.037414 | AJ10: 7.821481 | AK10: 6.773922 | AL10: 6.565055 | AM10: 5.713211 | AN10: 5.544128 | AO10: 4.406893 | AP10: 3.044265 | AQ10: 3.230776 | AR10: 3.389113 | AS10: 3.860631
A11: 11 | B11: 2.588122 | C11: 1.968643 | D11: 1.436406 | E11: 1.102562 | F11: 1.649081 | G11: 0.62354 | H11: 1.254436 | I11: 4.000116 | J11: 0.913918 | K11: 0.44499861 | L11: 0.603419 | M11: 1.262756 | N11: 1.115707 | O11: 2.699183 | P11: 6.620775 | Q11: 2.560208 | R11: 2.296884 | S11: 2.892568 | T11: 4.203556 | U11: 4.775437 | V11: 6.800566 | W11: 5.610682 | X11: 3.762366 | Y11: 3.087424 | Z11: 4.097613 | AA11: 5.335735 | AB11: 0.608056 | AC11: 1.24694 | AD11: 8.278334 | AE11: 4.415566 | AF11: 4.925959 | AG11: 4.138843 | AH11: 5.017596 | AI11: 5.781993 | AJ11: 7.136038 | AK11: 5.934267 | AL11: 5.708736 | AM11: 4.806213 | AN11: 4.630216 | AO11: 3.576385 | AP11: 3.339437 | AQ11: 3.644566 | AR11: 3.448733 | AS11: 3.65722
A12: 12 | B12: 2.588945 | C12: 2.267015 | D12: 1.583223 | E12: 1.705133 | F12: 1.436246 | G12: 0.843324 | H12: 0.823868 | I12: 4.50766 | J12: 0.415192 | K12: 0.603419 | L12: 0.2239854 | M12: 1.159711 | N12: 1.466176 | O12: 3.292178 | P12: 6.693131 | Q12: 2.932549 | R12: 2.320759 | S12: 2.756946 | T12: 4.505456 | U12: 4.873074 | V12: 6.985752 | W12: 5.863532 | X12: 3.549616 | Y12: 3.189335 | Z12: 4.026405 | AA12: 5.733584 | AB12: 0.984643 | AC12: 0.645705 | AD12: 8.514966 | AE12: 4.139269 | AF12: 4.756879 | AG12: 3.848484 | AH12: 4.971569 | AI12: 5.713838 | AJ12: 7.409682 | AK12: 6.365895 | AL12: 6.161216 | AM12: 5.341599 | AN12: 5.195983 | AO12: 4.176807 | AP12: 3.340657 | AQ12: 3.566744 | AR12: 3.603049 | AS12: 3.970778
A13: 13 | B13: 3.732644 | C13: 3.231137 | D13: 2.653597 | E13: 2.024143 | F13: 2.59349 | G13: 1.840484 | H13: 1.928108 | I13: 3.952552 | J13: 1.52801 | K13: 1.262756 | L13: 1.159711 | M13: 0.53023737 | N13: 0.965973 | O13: 3.20818 | P13: 5.53827 | Q13: 2.144836 | R13: 1.170044 | S13: 1.637838 | T13: 3.532528 | U13: 3.728665 | V13: 5.87673 | W13: 4.815343 | X13: 2.500071 | Y13: 2.059485 | Z13: 2.879584 | AA13: 4.885098 | AB13: 0.912008 | AC13: 1.435192 | AD13: 7.437993 | AE13: 3.166118 | AF13: 3.667496 | AG13: 2.897133 | AH13: 3.819085 | AI13: 4.568903 | AJ13: 6.371345 | AK13: 5.572672 | AL13: 5.416527 | AM13: 4.854416 | AN13: 4.844616 | AO13: 4.346369 | AP13: 4.487296 | AQ13: 4.725885 | AR13: 4.685002 | AS13: 4.918124
... A44: 115 | B44: 1.219731 | C44: 1.58082 | D44: 2.032725 | E44: 3.360904 | F44: 2.452091 | G44: 2.845224 | H44: 3.160245 | I44: 6.28898 | J44: 3.389113 | K44: 3.448733 | L44: 3.603049 | M44: 4.685002 | N44: 4.42053 | O44: 4.444712 | P44: 9.998808 | Q44: 5.600668 | R44: 5.740852 | S44: 6.322445 | T44: 7.270415 | U44: 8.148406 | V44: 10.024131 | W44: 8.728333 | X44: 7.149587 | Y44: 6.485769 | Z44: 7.546078 | AA44: 8.035522 | AB44: 3.99255 | AC44: 3.797924 | AD44: 11.369506 | AE44: 7.737424 | AF44: 8.345918 | AG44: 7.443322 | AH44: 8.464824 | AI44: 9.230626 | AJ44: 10.15928 | AK44: 8.446829 | AL44: 8.132712 | AM44: 6.769241 | AN44: 6.304644 | AO44: 4.21952 | AP44: 0.897654 | AQ44: 1.376857 | AR44: 0 | AS44: 1.090244
B45: 2.091159 | C45: 1.705355 | D45: 2.42808 | E45: 3.228292 | F45: 3.120863 | G45: 3.136147 | H45: 3.732045 | I45: 5.768598 | J45: 3.860631 | K45: 3.65722 | L45: 3.970778 | M45: 4.918124 | N45: 4.444402 | O45: 3.919923 | P45: 9.921417 | Q45: 5.404171 | R45: 5.849582 | S45: 6.532203 | T45: 7.012445 | U45: 8.089483 | V45: 9.803569 | W45: 8.460893 | X45: 7.418043 | Y45: 6.491826 | Z45: 7.676185 | AA45: 7.588929 | AB45: 4.102432 | AC45: 4.314751 | AD45: 11.045582 | AE45: 8.06918 | AF45: 8.564347 | AG45: 7.788238 | AH45: 8.552252 | AI45: 9.330349 | AJ45: 9.813543 | AK45: 7.918975 | AL45: 7.582956 | AM45: 6.12699 | AN45: 5.60591 | AO45: 3.423156 | AP45: 1.976668 | AQ45: 2.467038 | AR45: 1.090244 | AS45: 0

Sheet generation
A1: idzoning | B1: p131 students | C1: generation
A2: 1 | B2: 229 | C2: =$I$3*B2 -> 192.36 | G2: co-efficient | H2: home-work | I2: home-cshool | J2: home-leisure
A3: 2 | B3: 149 | C3: =$I$3*B3 -> 125.16 | G3: beta1 | H3: 1.024 | I3: 0.84 | J3: 0.47
A4: 3 | B4: 144 | C4: =$I$3*B4 -> 120.96 | G4: beta2 | H4: 0.92 | I4: 0 | J4: 0.58
A5: 5 | B5: 71 | C5: =$I$3*B5 -> 59.64
A6: 6 | B6: 233 | C6: =$I$3*B6 -> 195.72
A7: 7 | B7: 269 | C7: =$I$3*B7 -> 225.96
A8: 8 | B8: 299 | C8: =$I$3*B8 -> 251.16
A9: 9 | B9: 114 | C9: =$I$3*B9 -> 95.76
A10: 10 | B10: 186 | C10: =$I$3*B10 -> 156.24
A11: 11 | B11: 12 | C11: =$I$3*B11 -> 10.08
A12: 12 | B12: 100 | C12: =$I$3*B12 -> 84
A13: 13 | B13: 105 | C13: =$I$3*B13 -> 88.2
A14: 14 | B14: 122 | C14: =$I$3*B14 -> 102.48
A15: 15 | B15: 160 | C15: =$I$3*B15 -> 134.4
A16: 16 | B16: 91 | C16: =$I$3*B16 -> 76.44
... A29: 29 | B29: 136 | C29: =$I$3*B29 -> 114.24

Sheet distribution
A1: idzoning | B1: schoolworker | F1: co-efficient | G1: home-work | H1: home-school | I1: home-leisure
A2: 1 | B2: 0 | F2: beta1 | G2: 0.0009 | H2: 0.001 | I2: 0.0026395
A3: 2 | B3: 5 | F3: beta2 | G3: -0.7 | H3: 0 | I3: -0.1
A4: 3 | B4: 13
A5: 5 | B5: 0
A6: 6 | B6: 135 | F6: 0 | G6: 5 | H6: 13 | I6: 0 | J6: 135 | K6: 135 | L6: 39 | M6: 0 | N6: 0 | O6: 0 | P6: 0 | Q6: 219 | R6: 14 | S6: 36 | T6: 0 | U6: 0 | V6: 193 | W6: 85 | X6: 180 | Y6: 177 | Z6: 66 | AA6: 21 | AB6: 0 | AC6: 90 | AD6: 0 | AE6: 407 | AF6: 31 | AG6: 113
A7: 7 | B7: 135 | F7: 1 | G7: 2 | H7: 3 | I7: 5 | J7: 6 | K7: 7 | L7: 8 | M7: 9 | N7: 10 | O7: 11 | P7: 12 | Q7: 13 | R7: 14 | S7: 15 | T7: 16 | U7: 17 | V7: 18 | W7: 19 | X7: 20 | Y7: 21 | Z7: 22 | AA7: 23 | AB7: 24 | AC7: 25 | AD7: 26 | AE7: 27 | AF7: 28 | AG7: 29
A8: 8 | B8: 39 | E8: 1 | F8: =$H$2*F$6 -> 0 | G8: =$H$2*$G$6 -> 0.005 | H8: =$H$2*$H$6 -> 0.013 | I8: =$H$2*$I$6 -> 0 | J8: =$H$2*J$6 -> 0.135 | K8: =$H$2*K$6 -> 0.135 | L8: =$H$2*L$6 -> 0.039 | M8: =$H$2*M$6 -> 0 | N8: =$H$2*N$6 -> 0 | O8: =$H$2*O$6 -> 0 | P8: =$H$2*P$6 -> 0 | Q8: =$H$2*Q$6 -> 0.219 | ... AH8: =$H$2*AH$6 -> 0
A9: 9 | B9: 0 | E9: 2 | F9: =$H$2*F$6 -> 0 | G9: =$H$2*$G$6 -> 0.005 | H9: =$H$2*$H$6 -> 0.013 | I9: =$H$2*$I$6 -> 0 | J9: =$H$2*J$6 -> 0.135 | K9: =$H$2*K$6 -> 0.135 | L9: =$H$2*L$6 -> 0.039 | M9: =$H$2*M$6 -> 0 | N9: =$H$2*N$6 -> 0 | O9: =$H$2*O$6 -> 0 | P9: =$H$2*P$6 -> 0 | Q9: =$H$2*Q$6 -> 0.219 | ... AG9: =$H$2*AG$6 -> 0.113
A10: 10 | B10: 0 | E10: 3 | F10: =$H$2*F$6 -> 0 | G10: =$H$2*$G$6 -> 0.005 | H10: =$H$2*$H$6 -> 0.013 | I10: =$H$2*$I$6 -> 0 | J10: =$H$2*J$6 -> 0.135 | K10: =$H$2*K$6 -> 0.135 | L10: =$H$2*L$6 -> 0.039 | M10: =$H$2*M$6 -> 0 | N10: =$H$2*N$6 -> 0 | O10: =$H$2*O$6 -> 0 | P10: =$H$2*P$6 -> 0 | Q10: =$H$2*Q$6 -> 0.219 | ... AG10: =$H$2*AG$6 -> 0.113
A11: 11 | B11: 0 | E11: 5 | F11: =$H$2*F$6 -> 0 | G11: =$H$2*$G$6 -> 0.005 | H11: =$H$2*$H$6 -> 0.013 | I11: =$H$2*$I$6 -> 0 | J11: =$H$2*J$6 -> 0.135 | K11: =$H$2*K$6 -> 0.135 | L11: =$H$2*L$6 -> 0.039 | M11: =$H$2*M$6 -> 0 | N11: =$H$2*N$6 -> 0 | O11: =$H$2*O$6 -> 0 | P11: =$H$2*P$6 -> 0 | Q11: =$H$2*Q$6 -> 0.219 | ... AG11: =$H$2*AG$6 -> 0.113
A12: 12 | B12: 0 | E12: 6 | F12: =$H$2*F$6 -> 0 | G12: =$H$2*$G$6 -> 0.005 | H12: =$H$2*$H$6 -> 0.013 | I12: =$H$2*$I$6 -> 0 | J12: =$H$2*J$6 -> 0.135 | K12: =$H$2*K$6 -> 0.135 | L12: =$H$2*L$6 -> 0.039 | M12: =$H$2*M$6 -> 0 | N12: =$H$2*N$6 -> 0 | O12: =$H$2*O$6 -> 0 | P12: =$H$2*P$6 -> 0 | Q12: =$H$2*Q$6 -> 0.219 | ... AG12: =$H$2*AG$6 -> 0.113
A13: 13 | B13: 219 | E13: 7 | F13: =$H$2*F$6 -> 0 | G13: =$H$2*$G$6 -> 0.005 | H13: =$H$2*$H$6 -> 0.013 | I13: =$H$2*$I$6 -> 0 | J13: =$H$2*J$6 -> 0.135 | K13: =$H$2*K$6 -> 0.135 | L13: =$H$2*L$6 -> 0.039 | M13: =$H$2*M$6 -> 0 | N13: =$H$2*N$6 -> 0 | O13: =$H$2*O$6 -> 0 | P13: =$H$2*P$6 -> 0 | Q13: =$H$2*Q$6 -> 0.219 | ... AG13: =$H$2*AG$6 -> 0.113
A14: 14 | B14: 14 | E14: 8 | F14: =$H$2*F$6 -> 0 | G14: =$H$2*$G$6 -> 0.005 | H14: =$H$2*$H$6 -> 0.013 | I14: =$H$2*$I$6 -> 0 | J14: =$H$2*J$6 -> 0.135 | K14: =$H$2*K$6 -> 0.135 | L14: =$H$2*L$6 -> 0.039 | M14: =$H$2*M$6 -> 0 | N14: =$H$2*N$6 -> 0 | O14: =$H$2*O$6 -> 0 | P14: =$H$2*P$6 -> 0 | Q14: =$H$2*Q$6 -> 0.219 | ... AG14: =$H$2*AG$6 -> 0.113
A15: 15 | B15: 36 | E15: 9 | F15: =$H$2*F$6 -> 0 | G15: =$H$2*$G$6 -> 0.005 | H15: =$H$2*$H$6 -> 0.013 | I15: =$H$2*$I$6 -> 0 | J15: =$H$2*J$6 -> 0.135 | K15: =$H$2*K$6 -> 0.135 | L15: =$H$2*L$6 -> 0.039 | M15: =$H$2*M$6 -> 0 | N15: =$H$2*N$6 -> 0 | O15: =$H$2*O$6 -> 0 | P15: =$H$2*P$6 -> 0 | Q15: =$H$2*Q$6 -> 0.219 | ... AG15: =$H$2*AG$6 -> 0.113
A16: 16 | B16: 0 | E16: 10 | F16: =$H$2*F$6 -> 0 | G16: =$H$2*$G$6 -> 0.005 | H16: =$H$2*$H$6 -> 0.013 | I16: =$H$2*$I$6 -> 0 | J16: =$H$2*J$6 -> 0.135 | K16: =$H$2*K$6 -> 0.135 | L16: =$H$2*L$6 -> 0.039 | M16: =$H$2*M$6 -> 0 | N16: =$H$2*N$6 -> 0 | O16: =$H$2*O$6 -> 0 | P16: =$H$2*P$6 -> 0 | Q16: =$H$2*Q$6 -> 0.219 | ... AG16: =$H$2*AG$6 -> 0.113
A17: 17 | B17: 0 | E17: 11 | F17: =$H$2*F$6 -> 0 | G17: =$H$2*$G$6 -> 0.005 | H17: =$H$2*$H$6 -> 0.013 | I17: =$H$2*$I$6 -> 0 | J17: =$H$2*J$6 -> 0.135 | K17: =$H$2*K$6 -> 0.135 | L17: =$H$2*L$6 -> 0.039 | M17: =$H$2*M$6 -> 0 | N17: =$H$2*N$6 -> 0 | O17: =$H$2*O$6 -> 0 | P17: =$H$2*P$6 -> 0 | Q17: =$H$2*Q$6 -> 0.219 | ... AG17: =$H$2*AG$6 -> 0.113
A18: 18 | B18: 193 | E18: 12 | F18: =$H$2*F$6 -> 0 | G18: =$H$2*$G$6 -> 0.005 | H18: =$H$2*$H$6 -> 0.013 | I18: =$H$2*$I$6 -> 0 | J18: =$H$2*J$6 -> 0.135 | K18: =$H$2*K$6 -> 0.135 | L18: =$H$2*L$6 -> 0.039 | M18: =$H$2*M$6 -> 0 | N18: =$H$2*N$6 -> 0 | O18: =$H$2*O$6 -> 0 | P18: =$H$2*P$6 -> 0 | Q18: =$H$2*Q$6 -> 0.219 | ... AG18: =$H$2*AG$6 -> 0.113
A19: 19 | B19: 85 | E19: 13 | F19: =$H$2*F$6 -> 0 | G19: =$H$2*$G$6 -> 0.005 | H19: =$H$2*$H$6 -> 0.013 | I19: =$H$2*$I$6 -> 0 | J19: =$H$2*J$6 -> 0.135 | K19: =$H$2*K$6 -> 0.135 | L19: =$H$2*L$6 -> 0.039 | M19: =$H$2*M$6 -> 0 | N19: =$H$2*N$6 -> 0 | O19: =$H$2*O$6 -> 0 | P19: =$H$2*P$6 -> 0 | Q19: =$H$2*Q$6 -> 0.219 | ... AG19: =$H$2*AG$6 -> 0.113
A20: 20 | B20: 180 | E20: 14 | F20: =$H$2*F$6 -> 0 | G20: =$H$2*$G$6 -> 0.005 | H20: =$H$2*$H$6 -> 0.013 | I20: =$H$2*$I$6 -> 0 | J20: =$H$2*J$6 -> 0.135 | K20: =$H$2*K$6 -> 0.135 | L20: =$H$2*L$6 -> 0.039 | M20: =$H$2*M$6 -> 0 | N20: =$H$2*N$6 -> 0 | O20: =$H$2*O$6 -> 0 | P20: =$H$2*P$6 -> 0 | Q20: =$H$2*Q$6 -> 0.219 | ... AG20: =$H$2*AG$6 -> 0.113
... A29: 29 | B29: 113 | E29: 23 | F29: =$H$2*F$6 -> 0 | G29: =$H$2*$G$6 -> 0.005 | H29: =$H$2*$H$6 -> 0.013 | I29: =$H$2*$I$6 -> 0 | J29: =$H$2*J$6 -> 0.135 | K29: =$H$2*K$6 -> 0.135 | L29: =$H$2*L$6 -> 0.039 | M29: =$H$2*M$6 -> 0 | N29: =$H$2*N$6 -> 0 | O29: =$H$2*O$6 -> 0 | P29: =$H$2*P$6 -> 0 | Q29: =$H$2*Q$6 -> 0.219 | ... AG29: =$H$2*AG$6 -> 0.113
E30: 24 | F30: =$H$2*F$6 -> 0 | G30: =$H$2*$G$6 -> 0.005 | H30: =$H$2*$H$6 -> 0.013 | I30: =$H$2*$I$6 -> 0 | J30: =$H$2*J$6 -> 0.135 | K30: =$H$2*K$6 -> 0.135 | L30: =$H$2*L$6 -> 0.039 | M30: =$H$2*M$6 -> 0 | N30: =$H$2*N$6 -> 0 | O30: =$H$2*O$6 -> 0 | P30: =$H$2*P$6 -> 0 | Q30: =$H$2*Q$6 -> 0.219 | ... AG30: =$H$2*AG$6 -> 0.113
E31: 25 | F31: =$H$2*F$6 -> 0 | G31: =$H$2*$G$6 -> 0.005 | H31: =$H$2*$H$6 -> 0.013 | I31: =$H$2*$I$6 -> 0 | J31: =$H$2*J$6 -> 0.135 | K31: =$H$2*K$6 -> 0.135 | L31: =$H$2*L$6 -> 0.039 | M31: =$H$2*M$6 -> 0 | N31: =$H$2*N$6 -> 0 | O31: =$H$2*O$6 -> 0 | P31: =$H$2*P$6 -> 0 | Q31: =$H$2*Q$6 -> 0.219 | ... AG31: =$H$2*AG$6 -> 0.113
E32: 26 | F32: =$H$2*F$6 -> 0 | G32: =$H$2*$G$6 -> 0.005 | H32: =$H$2*$H$6 -> 0.013 | I32: =$H$2*$I$6 -> 0 | J32: =$H$2*J$6 -> 0.135 | K32: =$H$2*K$6 -> 0.135 | L32: =$H$2*L$6 -> 0.039 | M32: =$H$2*M$6 -> 0 | N32: =$H$2*N$6 -> 0 | O32: =$H$2*O$6 -> 0 | P32: =$H$2*P$6 -> 0 | Q32: =$H$2*Q$6 -> 0.219 | ... AG32: =$H$2*AG$6 -> 0.113
E33: 27 | F33: =$H$2*F$6 -> 0 | G33: =$H$2*$G$6 -> 0.005 | H33: =$H$2*$H$6 -> 0.013 | I33: =$H$2*$I$6 -> 0 | J33: =$H$2*J$6 -> 0.135 | K33: =$H$2*K$6 -> 0.135 | L33: =$H$2*L$6 -> 0.039 | M33: =$H$2*M$6 -> 0 | N33: =$H$2*N$6 -> 0 | O33: =$H$2*O$6 -> 0 | P33: =$H$2*P$6 -> 0 | Q33: =$H$2*Q$6 -> 0.219 | ... AG33: =$H$2*AG$6 -> 0.113
E34: 28 | F34: =$H$2*F$6 -> 0 | G34: =$H$2*$G$6 -> 0.005 | H34: =$H$2*$H$6 -> 0.013 | I34: =$H$2*$I$6 -> 0 | J34: =$H$2*J$6 -> 0.135 | K34: =$H$2*K$6 -> 0.135 | L34: =$H$2*L$6 -> 0.039 | M34: =$H$2*M$6 -> 0 | N34: =$H$2*N$6 -> 0 | O34: =$H$2*O$6 -> 0 | P34: =$H$2*P$6 -> 0 | Q34: =$H$2*Q$6 -> 0.219 | ... AG34: =$H$2*AG$6 -> 0.113
E35: 29 | F35: =$H$2*F$6 -> 0 | G35: =$H$2*$G$6 -> 0.005 | H35: =$H$2*$H$6 -> 0.013 | I35: =$H$2*$I$6 -> 0 | J35: =$H$2*J$6 -> 0.135 | K35: =$H$2*K$6 -> 0.135 | L35: =$H$2*L$6 -> 0.039 | M35: =$H$2*M$6 -> 0 | N35: =$H$2*N$6 -> 0 | O35: =$H$2*O$6 -> 0 | P35: =$H$2*P$6 -> 0 | Q35: =$H$2*Q$6 -> 0.219 | ... AG35: =$H$2*AG$6 -> 0.113
N39: exp
F40: 1 | G40: 2 | H40: 3 | I40: 5 | J40: 6 | K40: 7 | L40: 8 | M40: 9 | N40: 10 | O40: 11 | P40: 12 | Q40: 13 | R40: 14 | S40: 15 | T40: 16 | U40: 17 | V40: 18 | W40: 19 | X40: 20 | Y40: 21 | Z40: 22 | AA40: 23 | AB40: 24 | AC40: 25 | AD40: 26 | AE40: 27 | AF40: 28 | AG40: 29
E41: 1 | F41: =EXP(F8) -> 1 | G41: =EXP(G8) -> 1.0050125 | H41: =EXP(H8) -> 1.0130849 | I41: =EXP(I8) -> 1 | J41: =EXP(J8) -> 1.1445368 | K41: =EXP(K8) -> 1.1445368 | L41: =EXP(L8) -> 1.0397705 | M41: =EXP(M8) -> 1 | ... AG41: =EXP(AG8) -> 1.1196319 | AH41: =SUM(F41:AG41) -> 30.17202
E42: 2 | F42: =EXP(F9) -> 1 | G42: =EXP(G9) -> 1.0050125 | H42: =EXP(H9) -> 1.0130849 | I42: =EXP(I9) -> 1 | J42: =EXP(J9) -> 1.1445368 | K42: =EXP(K9) -> 1.1445368 | L42: =EXP(L9) -> 1.0397705 | M42: =EXP(M9) -> 1 | ... AG42: =EXP(AG9) -> 1.1196319 | AH42: =SUM(F42:AG42) -> 30.17202
E43: 3 | F43: =EXP(F10) -> 1 | G43: =EXP(G10) -> 1.0050125 | H43: =EXP(H10) -> 1.0130849 | I43: =EXP(I10) -> 1 | J43: =EXP(J10) -> 1.1445368 | K43: =EXP(K10) -> 1.1445368 | L43: =EXP(L10) -> 1.0397705 | M43: =EXP(M10) -> 1 | ... AG43: =EXP(AG10) -> 1.1196319 | AH43: =SUM(F43:AG43) -> 30.17202
E44: 5 | F44: =EXP(F11) -> 1 | G44: =EXP(G11) -> 1.0050125 | H44: =EXP(H11) -> 1.0130849 | I44: =EXP(I11) -> 1 | J44: =EXP(J11) -> 1.1445368 | K44: =EXP(K11) -> 1.1445368 | L44: =EXP(L11) -> 1.0397705 | M44: =EXP(M11) -> 1 | ... AG44: =EXP(AG11) -> 1.1196319 | AH44: =SUM(F44:AG44) -> 30.17202
E45: 6 | F45: =EXP(F12) -> 1 | G45: =EXP(G12) -> 1.0050125 | H45: =EXP(H12) -> 1.0130849 | I45: =EXP(I12) -> 1 | J45: =EXP(J12) -> 1.1445368 | K45: =EXP(K12) -> 1.1445368 | L45: =EXP(L12) -> 1.0397705 | M45: =EXP(M12) -> 1 | ... AG45: =EXP(AG12) -> 1.1196319 | AH45: =SUM(F45:AG45) -> 30.17202
E46: 7 | F46: =EXP(F13) -> 1 | G46: =EXP(G13) -> 1.0050125 | H46: =EXP(H13) -> 1.0130849 | I46: =EXP(I13) -> 1 | J46: =EXP(J13) -> 1.1445368 | K46: =EXP(K13) -> 1.1445368 | L46: =EXP(L13) -> 1.0397705 | M46: =EXP(M13) -> 1 | ... AG46: =EXP(AG13) -> 1.1196319 | AH46: =SUM(F46:AG46) -> 30.17202
E47: 8 | F47: =EXP(F14) -> 1 | G47: =EXP(G14) -> 1.0050125 | H47: =EXP(H14) -> 1.0130849 | I47: =EXP(I14) -> 1 | J47: =EXP(J14) -> 1.1445368 | K47: =EXP(K14) -> 1.1445368 | L47: =EXP(L14) -> 1.0397705 | M47: =EXP(M14) -> 1 | ... AG47: =EXP(AG14) -> 1.1196319 | AH47: =SUM(F47:AG47) -> 30.17202
E48: 9 | F48: =EXP(F15) -> 1 | G48: =EXP(G15) -> 1.0050125 | H48: =EXP(H15) -> 1.0130849 | I48: =EXP(I15) -> 1 | J48: =EXP(J15) -> 1.1445368 | K48: =EXP(K15) -> 1.1445368 | L48: =EXP(L15) -> 1.0397705 | M48: =EXP(M15) -> 1 | ... AG48: =EXP(AG15) -> 1.1196319 | AH48: =SUM(F48:AG48) -> 30.17202
E49: 10 | F49: =EXP(F16) -> 1 | G49: =EXP(G16) -> 1.0050125 | H49: =EXP(H16) -> 1.0130849 | I49: =EXP(I16) -> 1 | J49: =EXP(J16) -> 1.1445368 | K49: =EXP(K16) -> 1.1445368 | L49: =EXP(L16) -> 1.0397705 | M49: =EXP(M16) -> 1 | ... AG49: =EXP(AG16) -> 1.1196319 | AH49: =SUM(F49:AG49) -> 30.17202
E50: 11 | F50: =EXP(F17) -> 1 | G50: =EXP(G17) -> 1.0050125 | H50: =EXP(H17) -> 1.0130849 | I50: =EXP(I17) -> 1 | J50: =EXP(J17) -> 1.1445368 | K50: =EXP(K17) -> 1.1445368 | L50: =EXP(L17) -> 1.0397705 | M50: =EXP(M17) -> 1 | ... AG50: =EXP(AG17) -> 1.1196319 | AH50: =SUM(F50:AG50) -> 30.17202
E51: 12 | F51: =EXP(F18) -> 1 | G51: =EXP(G18) -> 1.0050125 | H51: =EXP(H18) -> 1.0130849 | I51: =EXP(I18) -> 1 | J51: =EXP(J18) -> 1.1445368 | K51: =EXP(K18) -> 1.1445368 | L51: =EXP(L18) -> 1.0397705 | M51: =EXP(M18) -> 1 | ... AG51: =EXP(AG18) -> 1.1196319 | AH51: =SUM(F51:AG51) -> 30.17202
...

Sheet ODmatrix
A1: idzoning | B1: schoolworker
A2: 1 | B2: 229
A3: 2 | B3: 149 | C3: generation | E3: generation | F3: 192.36 | G3: 125.16 | H3: 120.96 | I3: 59.64 | J3: 195.72 | K3: 225.96 | L3: 251.16 | M3: 95.76 | N3: 156.24 | O3: 10.08 | P3: 84 | Q3: 88.2 | R3: 102.48 | S3: 134.4 | T3: 76.44 | U3: 4.2 | V3: 284.76 | W3: 219.24 | X3: 498.12 | Y3: 145.32 | Z3: 126 | AA3: 365.4 | AB3: 41.16 | AC3: 320.04 | AD3: 31.92 | AE3: 610.68 | AF3: 194.88 | AG3: 114.24
A4: 3 | B4: 144 | C4: 192.36
A5: 5 | B5: 71 | C5: 125.16
A6: 6 | B6: 233 | C6: 120.96
A7: 7 | B7: 269 | C7: 59.64
A8: 8 | B8: 299 | C8: 195.72 | F8: 1 | G8: 2 | H8: 3 | I8: 5 | J8: 6 | K8: 7 | L8: 8 | M8: 9 | N8: 10 | O8: 11 | P8: 12 | Q8: 13 | R8: 14 | S8: 15 | T8: 16 | U8: 17 | V8: 18 | W8: 19 | X8: 20 | Y8: 21 | Z8: 22 | AA8: 23 | AB8: 24 | AC8: 25 | AD8: 26 | AE8: 27 | AF8: 28 | AG8: 29
A9: 9 | B9: 114 | C9: 225.96 | E9: 1 | F9: =$C4*distribution!F$73 -> 6.3754432 | G9: =$C4*distribution!G$73 -> 6.4074003 | H9: =$C4*distribution!H$73 -> 6.4588651 | I9: =$C4*distribution!I$73 -> 6.3754432 | J9: =$C4*distribution!J$73 -> 7.2969293 | K9: =$C4*distribution!K$73 -> 7.2969293 | L9: =$C4*distribution!L$73 -> 6.6289977 | M9: =$C4*distribution!M$73 -> 6.3754432 | ... AG9: =$C4*distribution!AG$73 -> 7.1381498 | AH9: =SUM(F9:AG9) -> 192.36
A10: 10 | B10: 186 | C10: 251.16 | E10: 2 | F10: =$C5*distribution!F$73 -> 4.1482141 | G10: =$C5*distribution!G$73 -> 4.1690072 | H10: =$C5*distribution!H$73 -> 4.202493 | I10: =$C5*distribution!I$73 -> 4.1482141 | J10: =$C5*distribution!J$73 -> 4.7477837 | K10: =$C5*distribution!K$73 -> 4.7477837 | L10: =$C5*distribution!L$73 -> 4.3131906 | M10: =$C5*distribution!M$73 -> 4.1482141 | ... AG10: =$C5*distribution!AG$73 -> 4.644473 | AH10: =SUM(F10:AG10) -> 125.16
A11: 11 | B11: 12 | C11: 95.76 | E11: 3 | F11: =$C6*distribution!F$73 -> 4.0090123 | G11: =$C6*distribution!G$73 -> 4.0291076 | H11: =$C6*distribution!H$73 -> 4.0614697 | I11: =$C6*distribution!I$73 -> 4.0090123 | J11: =$C6*distribution!J$73 -> 4.5884621 | K11: =$C6*distribution!K$73 -> 4.5884621 | L11: =$C6*distribution!L$73 -> 4.1684527 | M11: =$C6*distribution!M$73 -> 4.0090123 | ... AG11: =$C6*distribution!AG$73 -> 4.4886182 | AH11: =SUM(F11:AG11) -> 120.96
A12: 12 | B12: 100 | C12: 156.24 | E12: 4 | F12: =$C7*distribution!F$73 -> 1.9766658 | G12: =$C7*distribution!G$73 -> 1.9865739 | H12: =$C7*distribution!H$73 -> 2.0025302 | I12: =$C7*distribution!I$73 -> 1.9766658 | J12: =$C7*distribution!J$73 -> 2.2623667 | K12: =$C7*distribution!K$73 -> 2.2623667 | L12: =$C7*distribution!L$73 -> 2.0552788 | M12: =$C7*distribution!M$73 -> 1.9766658 | ... AG12: =$C7*distribution!AG$73 -> 2.2131382 | AH12: =SUM(F12:AG12) -> 59.64
A13: 13 | B13: 105 | C13: 10.08 | E13: 5 | F13: =$C8*distribution!F$73 -> 6.4868047 | G13: =$C8*distribution!G$73 -> 6.5193199 | H13: =$C8*distribution!H$73 -> 6.5716837 | I13: =$C8*distribution!I$73 -> 6.4868047 | J13: =$C8*distribution!J$73 -> 7.4243866 | K13: =$C8*distribution!K$73 -> 7.4243866 | L13: =$C8*distribution!L$73 -> 6.744788 | M13: =$C8*distribution!M$73 -> 6.4868047 | ... AG13: =$C8*distribution!AG$73 -> 7.2628337 | AH13: =SUM(F13:AG13) -> 195.72
A14: 14 | B14: 122 | C14: 84 | E14: 6 | F14: =$C9*distribution!F$73 -> 7.4890578 | G14: =$C9*distribution!G$73 -> 7.5265968 | H14: =$C9*distribution!H$73 -> 7.5870511 | I14: =$C9*distribution!I$73 -> 7.4890578 | J14: =$C9*distribution!J$73 -> 8.5715021 | K14: =$C9*distribution!K$73 -> 8.5715021 | L14: =$C9*distribution!L$73 -> 7.7869012 | M14: =$C9*distribution!M$73 -> 7.4890578 | ... AG14: =$C9*distribution!AG$73 -> 8.3849882 | AH14: =SUM(F14:AG14) -> 225.96
A15: 15 | B15: 160 | C15: 88.2 | E15: 7 | F15: =$C10*distribution!F$73 -> 8.3242687 | G15: =$C10*distribution!G$73 -> 8.3659942 | H15: =$C10*distribution!H$73 -> 8.4331906 | I15: =$C10*distribution!I$73 -> 8.3242687 | J15: =$C10*distribution!J$73 -> 9.5274317 | K15: =$C10*distribution!K$73 -> 9.5274317 | L15: =$C10*distribution!L$73 -> 8.6553289 | M15: =$C10*distribution!M$73 -> 8.3242687 | ... AG15: =$C10*distribution!AG$73 -> 9.320117 | AH15: =SUM(F15:AG15) -> 251.16
A16: 16 | B16: 91 | C16: 102.48 | E16: 8 | F16: =$C11*distribution!F$73 -> 3.1738014 | G16: =$C11*distribution!G$73 -> 3.1897102 | H16: =$C11*distribution!H$73 -> 3.2153302 | I16: =$C11*distribution!I$73 -> 3.1738014 | J16: =$C11*distribution!J$73 -> 3.6325325 | K16: =$C11*distribution!K$73 -> 3.6325325 | L16: =$C11*distribution!L$73 -> 3.300025 | M16: =$C11*distribution!M$73 -> 3.1738014 | ... AG16: =$C11*distribution!AG$73 -> 3.5534894 | AH16: =SUM(F16:AG16) -> 95.76
A17: 17 | B17: 5 | C17: 134.4 | E17: 9 | F17: =$C12*distribution!F$73 -> 5.1783076 | G17: =$C12*distribution!G$73 -> 5.204264 | H17: =$C12*distribution!H$73 -> 5.2460651 | I17: =$C12*distribution!I$73 -> 5.1783076 | J17: =$C12*distribution!J$73 -> 5.9267635 | K17: =$C12*distribution!K$73 -> 5.9267635 | L17: =$C12*distribution!L$73 -> 5.3842514 | M17: =$C12*distribution!M$73 -> 5.1783076 | ... AG17: =$C12*distribution!AG$73 -> 5.7977985 | AH17: =SUM(F17:AG17) -> 156.24
A18: 18 | B18: 339 | C18: 76.44 | E18: 10 | F18: =$C13*distribution!F$73 -> 0.33408436 | G18: =$C13*distribution!G$73 -> 0.33575897 | H18: =$C13*distribution!H$73 -> 0.33845581 | I18: =$C13*distribution!I$73 -> 0.33408436 | J18: =$C13*distribution!J$73 -> 0.38237184 | K18: =$C13*distribution!K$73 -> 0.38237184 | L18: =$C13*distribution!L$73 -> 0.34737106 | M18: =$C13*distribution!M$73 -> 0.33408436 | ... AG18: =$C13*distribution!AG$73 -> 0.37405152 | AH18: =SUM(F18:AG18) -> 10.08
A19: 19 | B19: 261 | C19: 4.2 | E19: 11 | F19: =$C14*distribution!F$73 -> 2.7840363 | G19: =$C14*distribution!G$73 -> 2.7979914 | H19: =$C14*distribution!H$73 -> 2.8204651 | I19: =$C14*distribution!I$73 -> 2.7840363 | J19: =$C14*distribution!J$73 -> 3.186432 | K19: =$C14*distribution!K$73 -> 3.186432 | L19: =$C14*distribution!L$73 -> 2.8947588 | M19: =$C14*distribution!M$73 -> 2.7840363 | ... AG19: =$C14*distribution!AG$73 -> 3.117096 | AH19: =SUM(F19:AG19) -> 84
A20: 20 | B20: 593 | C20: 284.76 | E20: 12 | F20: =$C15*distribution!F$73 -> 2.9232382 | G20: =$C15*distribution!G$73 -> 2.937891 | H20: =$C15*distribution!H$73 -> 2.9614883 | I20: =$C15*distribution!I$73 -> 2.9232382 | J20: =$C15*distribution!J$73 -> 3.3457536 | K20: =$C15*distribution!K$73 -> 3.3457536 | L20: =$C15*distribution!L$73 -> 3.0394968 | M20: =$C15*distribution!M$73 -> 2.9232382 | ... AG20: =$C15*distribution!AG$73 -> 3.2729508 | AH20: =SUM(F20:AG20) -> 88.2
... A29: 29 | B29: 136 | C29: 610.68 | E29: 21 | F29: =$C24*distribution!F$73 -> 4.1760545 | G29: =$C24*distribution!G$73 -> 4.1969871 | H29: =$C24*distribution!H$73 -> 4.2306976 | I29: =$C24*distribution!I$73 -> 4.1760545 | J29: =$C24*distribution!J$73 -> 4.779648 | K29: =$C24*distribution!K$73 -> 4.779648 | L29: =$C24*distribution!L$73 -> 4.3421382 | M29: =$C24*distribution!M$73 -> 4.1760545 | ... AG29: =$C24*distribution!AG$73 -> 4.675644 | AH29: =SUM(F29:AG29) -> 126
C30: 194.88 | E30: 22 | F30: =$C25*distribution!F$73 -> 12.110558 | G30: =$C25*distribution!G$73 -> 12.171263 | H30: =$C25*distribution!H$73 -> 12.269023 | I30: =$C25*distribution!I$73 -> 12.110558 | J30: =$C25*distribution!J$73 -> 13.860979 | K30: =$C25*distribution!K$73 -> 13.860979 | L30: =$C25*distribution!L$73 -> 12.592201 | M30: =$C25*distribution!M$73 -> 12.110558 | ... AG30: =$C25*distribution!AG$73 -> 13.559368 | AH30: =SUM(F30:AG30) -> 365.4
C31: 114.24 | E31: 23 | F31: =$C26*distribution!F$73 -> 1.3641778 | G31: =$C26*distribution!G$73 -> 1.3710158 | H31: =$C26*distribution!H$73 -> 1.3820279 | I31: =$C26*distribution!I$73 -> 1.3641778 | J31: =$C26*distribution!J$73 -> 1.5613517 | K31: =$C26*distribution!K$73 -> 1.5613517 | L31: =$C26*distribution!L$73 -> 1.4184318 | M31: =$C26*distribution!M$73 -> 1.3641778 | ... AG31: =$C26*distribution!AG$73 -> 1.527377 | AH31: =SUM(F31:AG31) -> 41.16
E32: 24 | F32: =$C27*distribution!F$73 -> 10.607178 | G32: =$C27*distribution!G$73 -> 10.660347 | H32: =$C27*distribution!H$73 -> 10.745972 | I32: =$C27*distribution!I$73 -> 10.607178 | J32: =$C27*distribution!J$73 -> 12.140306 | K32: =$C27*distribution!K$73 -> 12.140306 | L32: =$C27*distribution!L$73 -> 11.029031 | M32: =$C27*distribution!M$73 -> 10.607178 | ... AG32: =$C27*distribution!AG$73 -> 11.876136 | AH32: =SUM(F32:AG32) -> 320.04
E33: 25 | F33: =$C28*distribution!F$73 -> 1.0579338 | G33: =$C28*distribution!G$73 -> 1.0632367 | H33: =$C28*distribution!H$73 -> 1.0717767 | I33: =$C28*distribution!I$73 -> 1.0579338 | J33: =$C28*distribution!J$73 -> 1.2108442 | K33: =$C28*distribution!K$73 -> 1.2108442 | L33: =$C28*distribution!L$73 -> 1.1000083 | M33: =$C28*distribution!M$73 -> 1.0579338 | ... AG33: =$C28*distribution!AG$73 -> 1.1844965 | AH33: =SUM(F33:AG33) -> 31.92
E34: 27 | F34: =$C29*distribution!F$73 -> 20.239944 | G34: =$C29*distribution!G$73 -> 20.341397 | H34: =$C29*distribution!H$73 -> 20.504781 | I34: =$C29*distribution!I$73 -> 20.239944 | J34: =$C29*distribution!J$73 -> 23.165361 | K34: =$C29*distribution!K$73 -> 23.165361 | L34: =$C29*distribution!L$73 -> 21.044897 | M34: =$C29*distribution!M$73 -> 20.239944 | ... AG34: =$C29*distribution!AG$73 -> 22.661288 | AH34: =SUM(F34:AG34) -> 610.68
E35: 28 | F35: =$C30*distribution!F$73 -> 6.4589643 | G35: =$C30*distribution!G$73 -> 6.49134 | H35: =$C30*distribution!H$73 -> 6.543479 | I35: =$C30*distribution!I$73 -> 6.4589643 | J35: =$C30*distribution!J$73 -> 7.3925222 | K35: =$C30*distribution!K$73 -> 7.3925222 | L35: =$C30*distribution!L$73 -> 6.7158404 | M35: =$C30*distribution!M$73 -> 6.4589643 | ... AG35: =$C30*distribution!AG$73 -> 7.2316627 | AH35: =SUM(F35:AG35) -> 194.88
E36: 29 | F36: =$C31*distribution!F$73 -> 3.7862894 | G36: =$C31*distribution!G$73 -> 3.8052683 | H36: =$C31*distribution!H$73 -> 3.8358325 | I36: =$C31*distribution!I$73 -> 3.7862894 | J36: =$C31*distribution!J$73 -> 4.3335475 | K36: =$C31*distribution!K$73 -> 4.3335475 | L36: =$C31*distribution!L$73 -> 3.936872 | M36: =$C31*distribution!M$73 -> 3.7862894 | ... AG36: =$C31*distribution!AG$73 -> 4.2392505 | AH36: =SUM(F36:AG36) -> 114.24
F39: 1 | G39: 2 | H39: 3 | I39: 5 | J39: 6 | K39: 7 | L39: 8 | M39: 9 | N39: 10 | O39: 11 | P39: 12 | Q39: 13 | R39: 14 | S39: 15 | T39: 16 | U39: 17 | V39: 18 | W39: 19 | X39: 20 | Y39: 21 | Z39: 22 | AA39: 23 | AB39: 24 | AC39: 25 | AD39: 26 | AE39: 27 | AF39: 28 | AG39: 29
E40: 1 | F40: =ROUND(F9,0) -> 6 | G40: =ROUND(G9,0) -> 6 | H40: =ROUND(H9,0) -> 6 | I40: =ROUND(I9,0) -> 6 | J40: =ROUND(J9,0) -> 7 | K40: =ROUND(K9,0) -> 7 | L40: =ROUND(L9,0) -> 7 | M40: =ROUND(M9,0) -> 6 | ... AG40: =ROUND(AG9,0) -> 7
E41: 2 | F41: =ROUND(F10,0) -> 4 | G41: =ROUND(G10,0) -> 4 | H41: =ROUND(H10,0) -> 4 | I41: =ROUND(I10,0) -> 4 | J41: =ROUND(J10,0) -> 5 | K41: =ROUND(K10,0) -> 5 | L41: =ROUND(L10,0) -> 4 | M41: =ROUND(M10,0) -> 4 | ... AG41: =ROUND(AG10,0) -> 5
E42: 3 | F42: =ROUND(F11,0) -> 4 | G42: =ROUND(G11,0) -> 4 | H42: =ROUND(H11,0) -> 4 | I42: =ROUND(I11,0) -> 4 | J42: =ROUND(J11,0) -> 5 | K42: =ROUND(K11,0) -> 5 | L42: =ROUND(L11,0) -> 4 | M42: =ROUND(M11,0) -> 4 | ... AG42: =ROUND(AG11,0) -> 4
E43: 5 | F43: =ROUND(F12,0) -> 2 | G43: =ROUND(G12,0) -> 2 | H43: =ROUND(H12,0) -> 2 | I43: =ROUND(I12,0) -> 2 | J43: =ROUND(J12,0) -> 2 | K43: =ROUND(K12,0) -> 2 | L43: =ROUND(L12,0) -> 2 | M43: =ROUND(M12,0) -> 2 | ... AG43: =ROUND(AG12,0) -> 2
E44: 6 | F44: =ROUND(F13,0) -> 6 | G44: =ROUND(G13,0) -> 7 | H44: =ROUND(H13,0) -> 7 | I44: =ROUND(I13,0) -> 6 | J44: =ROUND(J13,0) -> 7 | K44: =ROUND(K13,0) -> 7 | L44: =ROUND(L13,0) -> 7 | M44: =ROUND(M13,0) -> 6 | ... AG44: =ROUND(AG13,0) -> 7
E45: 7 | F45: =ROUND(F14,0) -> 7 | G45: =ROUND(G14,0) -> 8 | H45: =ROUND(H14,0) -> 8 | I45: =ROUND(I14,0) -> 7 | J45: =ROUND(J14,0) -> 9 | K45: =ROUND(K14,0) -> 9 | L45: =ROUND(L14,0) -> 8 | M45: =ROUND(M14,0) -> 7 | ... AG45: =ROUND(AG14,0) -> 8
E46: 8 | F46: =ROUND(F15,0) -> 8 | G46: =ROUND(G15,0) -> 8 | H46: =ROUND(H15,0) -> 8 | I46: =ROUND(I15,0) -> 8 | J46: =ROUND(J15,0) -> 10 | K46: =ROUND(K15,0) -> 10 | L46: =ROUND(L15,0) -> 9 | M46: =ROUND(M15,0) -> 8 | ... AG46: =ROUND(AG15,0) -> 9
E47: 9 | F47: =ROUND(F16,0) -> 3 | G47: =ROUND(G16,0) -> 3 | H47: =ROUND(H16,0) -> 3 | I47: =ROUND(I16,0) -> 3 | J47: =ROUND(J16,0) -> 4 | K47: =ROUND(K16,0) -> 4 | L47: =ROUND(L16,0) -> 3 | M47: =ROUND(M16,0) -> 3 | ... AG47: =ROUND(AG16,0) -> 4
E48: 10 | F48: =ROUND(F17,0) -> 5 | G48: =ROUND(G17,0) -> 5 | H48: =ROUND(H17,0) -> 5 | I48: =ROUND(I17,0) -> 5 | J48: =ROUND(J17,0) -> 6 | K48: =ROUND(K17,0) -> 6 | L48: =ROUND(L17,0) -> 5 | M48: =ROUND(M17,0) -> 5 | ... AG48: =ROUND(AG17,0) -> 6
E49: 11 | F49: =ROUND(F18,0) -> 0 | G49: =ROUND(G18,0) -> 0 | H49: =ROUND(H18,0) -> 0 | I49: =ROUND(I18,0) -> 0 | J49: =ROUND(J18,0) -> 0 | K49: =ROUND(K18,0) -> 0 | L49: =ROUND(L18,0) -> 0 | M49: =ROUND(M18,0) -> 0 | ... AG49: =ROUND(AG18,0) -> 0
E50: 12 | F50: =ROUND(F19,0) -> 3 | G50: =ROUND(G19,0) -> 3 | H50: =ROUND(H19,0) -> 3 | I50: =ROUND(I19,0) -> 3 | J50: =ROUND(J19,0) -> 3 | K50: =ROUND(K19,0) -> 3 | L50: =ROUND(L19,0) -> 3 | M50: =ROUND(M19,0) -> 3 | ... AG50: =ROUND(AG19,0) -> 3
...
