Workbook

Sheet data
A1: idzoning | B1: p61 employees | C1: p131 students | D1: pf1 family
A2: 1 | B2: 953 | C2: 229 | D2: 1094
A3: 2 | B3: 558 | C3: 149 | D3: 633
A4: 3 | B4: 478 | C4: 144 | D4: 592
A5: 5 | B5: 268 | C5: 71 | D5: 318
A6: 6 | B6: 921 | C6: 233 | D6: 1108
A7: 7 | B7: 947 | C7: 269 | D7: 1067
A8: 8 | B8: 1193 | C8: 299 | D8: 1488
A9: 9 | B9: 468 | C9: 114 | D9: 500
A10: 10 | B10: 787 | C10: 186 | D10: 882
A11: 11 | B11: 47 | C11: 12 | D11: 61
A12: 12 | B12: 341 | C12: 100 | D12: 386
A13: 13 | B13: 480 | C13: 105 | D13: 535
... A29: 29 | B29: 708 | C29: 136 | D29: 833
A30: 0
A31: 0 | B31: 0 | C31: 0 | D31: 0
A32: 0 | B32: 0 | C32: 0 | D32: 0
A33: 0 | B33: 0 | C33: 0 | D33: 0
A34: 0 | B34: 0 | C34: 0 | D34: 0
A35: 0 | B35: 0 | C35: 0 | D35: 0
A36: 0 | B36: 0 | C36: 0 | D36: 0
A37: 0 | B37: 0 | C37: 0 | D37: 0
A38: 0 | B38: 0 | C38: 0 | D38: 0
A39: 0 | B39: 0 | C39: 0 | D39: 0
A40: 0 | B40: 0 | C40: 0 | D40: 0
A41: 0 | B41: 0 | C41: 0 | D41: 0
A42: 0 | B42: 0 | C42: 0 | D42: 0
... A45: 0 | B45: 0 | C45: 0 | D45: 0

Sheet distancematrix
B1: 1 | C1: 2 | D1: 3 | E1: 5 | F1: 6 | G1: 7 | H1: 8 | I1: 9 | J1: 10 | K1: 11 | L1: 12 | M1: 13 | N1: 14 | O1: 15 | P1: 16 | Q1: 17 | R1: 18 | S1: 19 | T1: 20 | U1: 21 | V1: 22 | W1: 23 | X1: 24 | Y1: 25 | Z1: 26 | AA1: 27 | AB1: 28 | AC1: 29 | AD1: 101 | AE1: 102 | AF1: 103 | AG1: 104 | AH1: 105 | AI1: 106 | AJ1: 107 | AK1: 108 | AL1: 109 | AM1: 110 | AN1: 111 | AO1: 112 | AP1: 113 | AQ1: 114 | AR1: 115
A2: 1 | B2: 0.68181955 | C2: 1.284534 | D2: 1.192822 | E2: 2.86295 | F2: 1.27848 | G2: 1.966059 | H2: 2.016857 | I2: 6.037658 | J2: 2.304832 | K2: 2.588122 | L2: 2.588945 | M2: 3.732644 | N2: 3.669351 | O2: 4.289047 | P2: 9.207378 | Q2: 5.012865 | R2: 4.858912 | S2: 5.345885 | T2: 6.695306 | U2: 7.363369 | V2: 9.366328 | W2: 8.135048 | X2: 6.118518 | Y2: 5.674337 | Z2: 6.61103 | AA2: 7.650443 | AB2: 3.185189 | AC2: 2.668138 | AD2: 10.802906 | AE2: 6.659687 | AF2: 7.336507 | AG2: 6.360181 | AH2: 7.55162 | AI2: 8.299856 | AJ2: 9.628539 | AK2: 8.150397 | AL2: 7.86928 | AM2: 6.657017 | AN2: 6.282654 | AO2: 4.430696 | AP2: 0.755505 | AQ2: 1.097192 | AR2: 1.219731 | AS2: 2.091159
A3: 2 | B3: 1.284534 | C3: 0.52285065 | D3: 0.782342 | E3: 1.78496 | F3: 1.642389 | G3: 1.430796 | H3: 2.113246 | I3: 4.832659 | J3: 2.182867 | K3: 1.968643 | L3: 2.267015 | M3: 3.231137 | N3: 2.85932 | O3: 3.038381 | P3: 8.427841 | Q3: 4.022587 | R3: 4.218967 | S3: 4.859198 | T3: 5.696777 | U3: 6.578801 | V3: 8.444111 | W3: 7.15381 | X3: 5.729511 | Y3: 4.928213 | Z3: 6.04059 | AA3: 6.518905 | AB3: 2.460191 | AC3: 2.64731 | AD3: 9.801818 | AE3: 6.369103 | AF3: 6.893177 | AG3: 6.086192 | AH3: 6.941477 | AI3: 7.714135 | AJ3: 8.598343 | AK3: 6.973114 | AL3: 6.67606 | AM3: 5.406179 | AN3: 5.010943 | AO3: 3.156372 | AP3: 1.829099 | AQ3: 2.30603 | AR3: 1.58082 | AS3: 1.705355
A4: 3 | B4: 1.192822 | C4: 0.782342 | D4: 0.64758372 | E4: 1.710536 | F4: 0.911674 | G4: 0.818482 | H4: 1.332103 | I4: 4.921398 | J4: 1.433054 | K4: 1.436406 | L4: 1.583223 | M4: 2.653597 | N4: 2.486271 | O4: 3.253456 | P4: 8.048577 | Q4: 3.820956 | R4: 3.732354 | S4: 4.290349 | T4: 5.502802 | U4: 6.200056 | V4: 8.178156 | W4: 6.942302 | X4: 5.119791 | Y4: 4.516805 | Z4: 5.52268 | AA4: 6.482144 | AB4: 2.014924 | AC4: 1.887514 | AD4: 9.610084 | AE4: 5.722149 | AF4: 6.313279 | AG4: 5.431706 | AH4: 6.449403 | AI4: 7.210189 | AJ4: 8.436768 | AK4: 7.004267 | AL4: 6.735146 | AM4: 5.596108 | AN4: 5.275444 | AO4: 3.644563 | AP4: 1.925547 | AQ4: 2.285091 | AR4: 2.032725 | AS4: 2.42808
A5: 5 | B5: 2.86295 | C5: 1.78496 | D5: 1.710536 | E5: 0.83095856 | F5: 2.364418 | G5: 1.260966 | H5: 2.232347 | I5: 3.21577 | J5: 1.968463 | K5: 1.102562 | L5: 1.705133 | M5: 2.024143 | N5: 1.27398 | O5: 1.663624 | P5: 6.702036 | Q5: 2.239988 | R5: 2.699365 | S5: 3.470033 | T5: 3.911817 | U5: 4.863872 | V5: 6.665207 | W5: 5.368951 | X5: 4.400756 | Y5: 3.270001 | Z5: 4.506579 | AA5: 4.787915 | AB5: 1.113273 | AC5: 2.344775 | AD5: 8.017915 | AE5: 5.122256 | AF5: 5.459268 | AG5: 4.87291 | AH5: 5.349436 | AI5: 6.129299 | AJ5: 6.818116 | AK5: 5.295209 | AL5: 5.024614 | AM5: 3.925964 | AN5: 3.664738 | AO5: 2.475217 | AP5: 3.540206 | AQ5: 3.95825 | AR5: 3.360904 | AS5: 3.228292
A6: 6 | B6: 1.27848 | C6: 1.642389 | D6: 0.911674 | E6: 2.364418 | F6: 0.54115811 | G6: 1.134496 | H6: 0.745563 | I6: 5.546209 | J6: 1.082328 | K6: 1.649081 | L6: 1.436246 | M6: 2.59349 | N6: 2.759565 | O6: 4.004565 | P6: 8.129365 | Q6: 4.208612 | R6: 3.757006 | S6: 4.153375 | T6: 5.849243 | U6: 6.30768 | V6: 8.401923 | W6: 7.244566 | X6: 4.882348 | Y6: 4.621184 | Z6: 5.438512 | AA6: 6.972552 | AB6: 2.247205 | AC6: 1.3975 | AD6: 9.907828 | AE6: 5.397471 | AF6: 6.108357 | AG6: 5.096271 | AH6: 6.388663 | AI6: 7.119678 | AJ6: 8.777705 | AK6: 7.55116 | AL6: 7.309592 | AM6: 6.288022 | AN6: 6.022315 | AO6: 4.520573 | AP6: 1.988568 | AQ6: 2.148818 | AR6: 2.452091 | AS6: 3.120863
A7: 7 | B7: 1.966059 | C7: 1.430796 | D7: 0.818482 | E7: 1.260966 | F7: 1.134496 | G7: 0.40319152 | H7: 1.011339 | I7: 4.41292 | J7: 0.86612 | K7: 0.62354 | L7: 0.843324 | M7: 1.840484 | N7: 1.713728 | O7: 2.923 | P7: 7.244206 | Q7: 3.116813 | R7: 2.915117 | S7: 3.478316 | T7: 4.782451 | U7: 5.398419 | V7: 7.411004 | W7: 6.204125 | X7: 4.321997 | Y7: 3.710875 | Z7: 4.704665 | AA7: 5.853554 | AB7: 1.220269 | AC7: 1.327655 | AD7: 8.873441 | AE7: 4.944987 | AF7: 5.50589 | AG7: 4.659596 | AH7: 5.630941 | AI7: 6.391868 | AJ7: 7.719018 | AK7: 6.421262 | AL7: 6.176424 | AM7: 5.166047 | AN7: 4.924274 | AO7: 3.598071 | AP7: 2.716313 | AQ7: 3.030204 | AR7: 2.845224 | AS7: 3.136147
A8: 8 | B8: 2.016857 | C8: 2.113246 | D8: 1.332103 | E8: 2.232347 | F8: 0.745563 | G8: 1.011339 | H8: 0.29758741 | I8: 5.254316 | J8: 0.411066 | K8: 1.254436 | L8: 0.823868 | M8: 1.928108 | N8: 2.275295 | O8: 3.891076 | P8: 7.459444 | Q8: 3.74534 | R8: 3.097954 | S8: 3.435072 | T8: 5.329186 | U8: 5.656666 | V8: 7.79345 | W8: 6.684886 | X8: 4.142567 | Y8: 3.984001 | Z8: 4.726435 | AA8: 6.543487 | AB8: 1.775706 | AC8: 0.652304 | AD8: 9.332756 | AE8: 4.651911 | AF8: 5.370459 | AG8: 4.350723 | AH8: 5.679068 | AI8: 6.400601 | AJ8: 8.232398 | AK8: 7.163736 | AL8: 6.948601 | AM8: 6.057372 | AN8: 5.86258 | AO8: 4.60939 | AP8: 2.734087 | AQ8: 2.87963 | AR8: 3.160245 | AS8: 3.732045
A9: 9 | B9: 6.037658 | C9: 4.832659 | D9: 4.921398 | E9: 3.21577 | F9: 5.546209 | G9: 4.41292 | H9: 5.254316 | I9: 0.96263855 | J9: 4.893069 | K9: 4.000116 | L9: 4.50766 | M9: 3.952552 | N9: 3.10158 | O9: 1.85508 | P9: 5.126288 | Q9: 1.88906 | R9: 3.486655 | S9: 4.235979 | T9: 2.026888 | U9: 3.722821 | V9: 4.503375 | W9: 3.13508 | X9: 4.993001 | Y9: 3.147184 | Z9: 4.409811 | AA9: 1.861494 | AB9: 3.528169 | AC9: 5.105011 | AD9: 5.431627 | AE9: 5.73571 | AF9: 5.462783 | AG9: 5.628239 | AH9: 4.778525 | AI9: 5.430094 | AJ9: 4.190833 | AK9: 2.159824 | AL9: 1.845716 | AM9: 0.924768 | AN9: 1.185671 | AO9: 2.694225 | AP9: 6.65983 | AQ9: 7.117705 | AR9: 6.28898 | AS9: 5.768598
A10: 10 | B10: 2.304832 | C10: 2.182867 | D10: 1.433054 | E10: 1.968463 | F10: 1.082328 | G10: 0.86612 | H10: 0.411066 | I10: 4.893069 | J10: 0.25755239 | K10: 0.913918 | L10: 0.415192 | M10: 1.52801 | N10: 1.877181 | O10: 3.60353 | P10: 7.065145 | Q10: 3.345541 | R10: 2.697721 | S10: 3.071261 | T10: 4.920057 | U10: 5.255719 | V10: 7.385068 | W10: 6.273822 | X10: 3.815278 | Y10: 3.578915 | Z10: 4.356371 | AA10: 6.145925 | AB10: 1.386082 | AC10: 0.470155 | AD10: 8.922027 | AE10: 4.360548 | AF10: 5.03689 | AG10: 4.063052 | AH10: 5.306932 | AI10: 6.037414 | AJ10: 7.821481 | AK10: 6.773922 | AL10: 6.565055 | AM10: 5.713211 | AN10: 5.544128 | AO10: 4.406893 | AP10: 3.044265 | AQ10: 3.230776 | AR10: 3.389113 | AS10: 3.860631
A11: 11 | B11: 2.588122 | C11: 1.968643 | D11: 1.436406 | E11: 1.102562 | F11: 1.649081 | G11: 0.62354 | H11: 1.254436 | I11: 4.000116 | J11: 0.913918 | K11: 0.44499861 | L11: 0.603419 | M11: 1.262756 | N11: 1.115707 | O11: 2.699183 | P11: 6.620775 | Q11: 2.560208 | R11: 2.296884 | S11: 2.892568 | T11: 4.203556 | U11: 4.775437 | V11: 6.800566 | W11: 5.610682 | X11: 3.762366 | Y11: 3.087424 | Z11: 4.097613 | AA11: 5.335735 | AB11: 0.608056 | AC11: 1.24694 | AD11: 8.278334 | AE11: 4.415566 | AF11: 4.925959 | AG11: 4.138843 | AH11: 5.017596 | AI11: 5.781993 | AJ11: 7.136038 | AK11: 5.934267 | AL11: 5.708736 | AM11: 4.806213 | AN11: 4.630216 | AO11: 3.576385 | AP11: 3.339437 | AQ11: 3.644566 | AR11: 3.448733 | AS11: 3.65722
A12: 12 | B12: 2.588945 | C12: 2.267015 | D12: 1.583223 | E12: 1.705133 | F12: 1.436246 | G12: 0.843324 | H12: 0.823868 | I12: 4.50766 | J12: 0.415192 | K12: 0.603419 | L12: 0.2239854 | M12: 1.159711 | N12: 1.466176 | O12: 3.292178 | P12: 6.693131 | Q12: 2.932549 | R12: 2.320759 | S12: 2.756946 | T12: 4.505456 | U12: 4.873074 | V12: 6.985752 | W12: 5.863532 | X12: 3.549616 | Y12: 3.189335 | Z12: 4.026405 | AA12: 5.733584 | AB12: 0.984643 | AC12: 0.645705 | AD12: 8.514966 | AE12: 4.139269 | AF12: 4.756879 | AG12: 3.848484 | AH12: 4.971569 | AI12: 5.713838 | AJ12: 7.409682 | AK12: 6.365895 | AL12: 6.161216 | AM12: 5.341599 | AN12: 5.195983 | AO12: 4.176807 | AP12: 3.340657 | AQ12: 3.566744 | AR12: 3.603049 | AS12: 3.970778
A13: 13 | B13: 3.732644 | C13: 3.231137 | D13: 2.653597 | E13: 2.024143 | F13: 2.59349 | G13: 1.840484 | H13: 1.928108 | I13: 3.952552 | J13: 1.52801 | K13: 1.262756 | L13: 1.159711 | M13: 0.53023737 | N13: 0.965973 | O13: 3.20818 | P13: 5.53827 | Q13: 2.144836 | R13: 1.170044 | S13: 1.637838 | T13: 3.532528 | U13: 3.728665 | V13: 5.87673 | W13: 4.815343 | X13: 2.500071 | Y13: 2.059485 | Z13: 2.879584 | AA13: 4.885098 | AB13: 0.912008 | AC13: 1.435192 | AD13: 7.437993 | AE13: 3.166118 | AF13: 3.667496 | AG13: 2.897133 | AH13: 3.819085 | AI13: 4.568903 | AJ13: 6.371345 | AK13: 5.572672 | AL13: 5.416527 | AM13: 4.854416 | AN13: 4.844616 | AO13: 4.346369 | AP13: 4.487296 | AQ13: 4.725885 | AR13: 4.685002 | AS13: 4.918124
... A44: 115 | B44: 1.219731 | C44: 1.58082 | D44: 2.032725 | E44: 3.360904 | F44: 2.452091 | G44: 2.845224 | H44: 3.160245 | I44: 6.28898 | J44: 3.389113 | K44: 3.448733 | L44: 3.603049 | M44: 4.685002 | N44: 4.42053 | O44: 4.444712 | P44: 9.998808 | Q44: 5.600668 | R44: 5.740852 | S44: 6.322445 | T44: 7.270415 | U44: 8.148406 | V44: 10.024131 | W44: 8.728333 | X44: 7.149587 | Y44: 6.485769 | Z44: 7.546078 | AA44: 8.035522 | AB44: 3.99255 | AC44: 3.797924 | AD44: 11.369506 | AE44: 7.737424 | AF44: 8.345918 | AG44: 7.443322 | AH44: 8.464824 | AI44: 9.230626 | AJ44: 10.15928 | AK44: 8.446829 | AL44: 8.132712 | AM44: 6.769241 | AN44: 6.304644 | AO44: 4.21952 | AP44: 0.897654 | AQ44: 1.376857 | AR44: 0 | AS44: 1.090244
B45: 2.091159 | C45: 1.705355 | D45: 2.42808 | E45: 3.228292 | F45: 3.120863 | G45: 3.136147 | H45: 3.732045 | I45: 5.768598 | J45: 3.860631 | K45: 3.65722 | L45: 3.970778 | M45: 4.918124 | N45: 4.444402 | O45: 3.919923 | P45: 9.921417 | Q45: 5.404171 | R45: 5.849582 | S45: 6.532203 | T45: 7.012445 | U45: 8.089483 | V45: 9.803569 | W45: 8.460893 | X45: 7.418043 | Y45: 6.491826 | Z45: 7.676185 | AA45: 7.588929 | AB45: 4.102432 | AC45: 4.314751 | AD45: 11.045582 | AE45: 8.06918 | AF45: 8.564347 | AG45: 7.788238 | AH45: 8.552252 | AI45: 9.330349 | AJ45: 9.813543 | AK45: 7.918975 | AL45: 7.582956 | AM45: 6.12699 | AN45: 5.60591 | AO45: 3.423156 | AP45: 1.976668 | AQ45: 2.467038 | AR45: 1.090244 | AS45: 0

Sheet generation
A1: idzoning | B1: pf1 family | C1: generation | F1: co-efficient | G1: home-work | H1: home-cshool | I1: home-leisure
A2: 1 | B2: 1094 | C2: =$I$2*$I$3*B2 -> 298.2244 | F2: beta1 | G2: 1.024 | H2: 0.84 | I2: 0.47
A3: 2 | B3: 633 | C3: =$I$2*$I$3*B3 -> 172.5558 | F3: beta2 | G3: 0.92 | H3: 0 | I3: 0.58
A4: 3 | B4: 592 | C4: =$I$2*$I$3*B4 -> 161.3792
A5: 5 | B5: 318 | C5: =$I$2*$I$3*B5 -> 86.6868
A6: 6 | B6: 1108 | C6: =$I$2*$I$3*B6 -> 302.0408
A7: 7 | B7: 1067 | C7: =$I$2*$I$3*B7 -> 290.8642
A8: 8 | B8: 1488 | C8: =$I$2*$I$3*B8 -> 405.6288
A9: 9 | B9: 500 | C9: =$I$2*$I$3*B9 -> 136.3
A10: 10 | B10: 882 | C10: =$I$2*$I$3*B10 -> 240.4332
A11: 11 | B11: 61 | C11: =$I$2*$I$3*B11 -> 16.6286
A12: 12 | B12: 386 | C12: =$I$2*$I$3*B12 -> 105.2236
A13: 13 | B13: 535 | C13: =$I$2*$I$3*B13 -> 145.841
A14: 14 | B14: 539 | C14: =$I$2*$I$3*B14 -> 146.9314
A15: 15 | B15: 612 | C15: =$I$2*$I$3*B15 -> 166.8312
... A29: 29 | B29: 833 | C29: =$I$2*$I$3*B29 -> 227.0758

Sheet distribution
A1: zoning | B1: leisureworker | D1: co-efficient | E1: home-work | F1: home-school | G1: home-leisure
A2: 1 | B2: 152 | D2: beta1 | E2: 0.0009 | F2: 0.01 | G2: 0.0026395
A3: 2 | B3: 22 | D3: beta2 | E3: -0.7 | F3: 0 | G3: -0.1
A4: 3 | B4: 42
A5: 5 | B5: 9
A6: 6 | B6: 83 | E6: 152 | F6: 22 | G6: 42 | H6: 9 | I6: 83 | J6: 19 | K6: 92 | L6: 17 | M6: 129 | N6: 18 | O6: 30 | P6: 85 | Q6: 47 | R6: 82 | S6: 22 | T6: 2 | U6: 34 | V6: 162 | W6: 54 | X6: 29 | Y6: 30 | Z6: 108 | AA6: 55 | AB6: 14 | AC6: 38 | AD6: 51 | AE6: 43 | AF6: 238
A7: 7 | B7: 19 | E7: 1 | F7: 2 | G7: 3 | H7: 5 | I7: 6 | J7: 7 | K7: 8 | L7: 9 | M7: 10 | N7: 11 | O7: 12 | P7: 13 | Q7: 14 | R7: 15 | S7: 16 | T7: 17 | U7: 18 | V7: 19 | W7: 20 | X7: 21 | Y7: 22 | Z7: 23 | AA7: 24 | AB7: 25 | AC7: 26 | AD7: 27 | AE7: 28 | AF7: 29
A8: 8 | B8: 92 | D8: 1 | E8: =($G$2*E$6)+($G$3*distancematrix!B2) -> 0.33302204 | F8: =($G$2*F$6)+($G$3*distancematrix!C2) -> -0.0703844 | G8: =($G$2*G$6)+($G$3*distancematrix!D2) -> -0.0084232 | H8: =($G$2*H$6)+($G$3*distancematrix!E2) -> -0.2625395 | I8: =($G$2*I$6)+($G$3*distancematrix!F2) -> 0.0912305 | J8: =($G$2*J$6)+($G$3*distancematrix!G2) -> -0.1464554 | K8: =($G$2*K$6)+($G$3*distancematrix!H2) -> 0.0411483 | L8: =($G$2*L$6)+($G$3*distancematrix!I2) -> -0.5588943 | ... AF8: =($G$2*AF$6)+($G$3*distancematrix!AC2) -> 0.3613872
A9: 9 | B9: 17 | D9: 2 | E9: =($G$2*E$6)+($G$3*distancematrix!B3) -> 0.2727506 | F9: =($G$2*F$6)+($G$3*distancematrix!C3) -> 0.0057839346 | G9: =($G$2*G$6)+($G$3*distancematrix!D3) -> 0.0326248 | H9: =($G$2*H$6)+($G$3*distancematrix!E3) -> -0.1547405 | I9: =($G$2*I$6)+($G$3*distancematrix!F3) -> 0.0548396 | J9: =($G$2*J$6)+($G$3*distancematrix!G3) -> -0.0929291 | K9: =($G$2*K$6)+($G$3*distancematrix!H3) -> 0.0315094 | L9: =($G$2*L$6)+($G$3*distancematrix!I3) -> -0.4383944 | ... AF9: =($G$2*AF$6)+($G$3*distancematrix!AC3) -> 0.36347
A10: 10 | B10: 129 | D10: 3 | E10: =($G$2*E$6)+($G$3*distancematrix!B4) -> 0.2819218 | F10: =($G$2*F$6)+($G$3*distancematrix!C4) -> -0.0201652 | G10: =($G$2*G$6)+($G$3*distancematrix!D4) -> 0.046100628 | H10: =($G$2*H$6)+($G$3*distancematrix!E4) -> -0.1472981 | I10: =($G$2*I$6)+($G$3*distancematrix!F4) -> 0.1279111 | J10: =($G$2*J$6)+($G$3*distancematrix!G4) -> -0.0316977 | K10: =($G$2*K$6)+($G$3*distancematrix!H4) -> 0.1096237 | L10: =($G$2*L$6)+($G$3*distancematrix!I4) -> -0.4472683 | ... AF10: =($G$2*AF$6)+($G$3*distancematrix!AC4) -> 0.4394496
A11: 11 | B11: 18 | D11: 5 | E11: =($G$2*E$6)+($G$3*distancematrix!B5) -> 0.114909 | F11: =($G$2*F$6)+($G$3*distancematrix!C5) -> -0.120427 | G11: =($G$2*G$6)+($G$3*distancematrix!D5) -> -0.0601946 | H11: =($G$2*H$6)+($G$3*distancematrix!E5) -> -0.059340356 | I11: =($G$2*I$6)+($G$3*distancematrix!F5) -> -0.0173633 | J11: =($G$2*J$6)+($G$3*distancematrix!G5) -> -0.0759461 | K11: =($G$2*K$6)+($G$3*distancematrix!H5) -> 0.0195993 | L11: =($G$2*L$6)+($G$3*distancematrix!I5) -> -0.2767055 | ... AF11: =($G$2*AF$6)+($G$3*distancematrix!AC5) -> 0.3937235
A12: 12 | B12: 30 | D12: 6 | E12: =($G$2*E$6)+($G$3*distancematrix!B6) -> 0.273356 | F12: =($G$2*F$6)+($G$3*distancematrix!C6) -> -0.1061699 | G12: =($G$2*G$6)+($G$3*distancematrix!D6) -> 0.0196916 | H12: =($G$2*H$6)+($G$3*distancematrix!E6) -> -0.2126863 | I12: =($G$2*I$6)+($G$3*distancematrix!F6) -> 0.16496269 | J12: =($G$2*J$6)+($G$3*distancematrix!G6) -> -0.0632991 | K12: =($G$2*K$6)+($G$3*distancematrix!H6) -> 0.1682777 | L12: =($G$2*L$6)+($G$3*distancematrix!I6) -> -0.5097494 | ... AF12: =($G$2*AF$6)+($G$3*distancematrix!AC6) -> 0.488451
A13: 13 | B13: 85 | D13: 7 | E13: =($G$2*E$6)+($G$3*distancematrix!B7) -> 0.2045981 | F13: =($G$2*F$6)+($G$3*distancematrix!C7) -> -0.0850106 | G13: =($G$2*G$6)+($G$3*distancematrix!D7) -> 0.0290108 | H13: =($G$2*H$6)+($G$3*distancematrix!E7) -> -0.1023411 | I13: =($G$2*I$6)+($G$3*distancematrix!F7) -> 0.1056289 | J13: =($G$2*J$6)+($G$3*distancematrix!G7) -> 0.0098313476 | K13: =($G$2*K$6)+($G$3*distancematrix!H7) -> 0.1417001 | L13: =($G$2*L$6)+($G$3*distancematrix!I7) -> -0.3964205 | ... AF13: =($G$2*AF$6)+($G$3*distancematrix!AC7) -> 0.4954355
A14: 14 | B14: 47 | D14: 8 | E14: =($G$2*E$6)+($G$3*distancematrix!B8) -> 0.1995183 | F14: =($G$2*F$6)+($G$3*distancematrix!C8) -> -0.1532556 | G14: =($G$2*G$6)+($G$3*distancematrix!D8) -> -0.0223513 | H14: =($G$2*H$6)+($G$3*distancematrix!E8) -> -0.1994792 | I14: =($G$2*I$6)+($G$3*distancematrix!F8) -> 0.1445222 | J14: =($G$2*J$6)+($G$3*distancematrix!G8) -> -0.0509834 | K14: =($G$2*K$6)+($G$3*distancematrix!H8) -> 0.21307526 | L14: =($G$2*L$6)+($G$3*distancematrix!I8) -> -0.4805601 | ... AF14: =($G$2*AF$6)+($G$3*distancematrix!AC8) -> 0.5629706
A15: 15 | B15: 82 | D15: 9 | E15: =($G$2*E$6)+($G$3*distancematrix!B9) -> -0.2025618 | F15: =($G$2*F$6)+($G$3*distancematrix!C9) -> -0.4251969 | G15: =($G$2*G$6)+($G$3*distancematrix!D9) -> -0.3812808 | H15: =($G$2*H$6)+($G$3*distancematrix!E9) -> -0.2978215 | I15: =($G$2*I$6)+($G$3*distancematrix!F9) -> -0.3355424 | J15: =($G$2*J$6)+($G$3*distancematrix!G9) -> -0.3911415 | K15: =($G$2*K$6)+($G$3*distancematrix!H9) -> -0.2825976 | L15: =($G$2*L$6)+($G$3*distancematrix!I9) -> -0.051392355 | ... AF15: =($G$2*AF$6)+($G$3*distancematrix!AC9) -> 0.1176999
A16: 16 | B16: 22 | D16: 10 | E16: =($G$2*E$6)+($G$3*distancematrix!B10) -> 0.1707208 | F16: =($G$2*F$6)+($G$3*distancematrix!C10) -> -0.1602177 | G16: =($G$2*G$6)+($G$3*distancematrix!D10) -> -0.0324464 | H16: =($G$2*H$6)+($G$3*distancematrix!E10) -> -0.1730908 | I16: =($G$2*I$6)+($G$3*distancematrix!F10) -> 0.1108457 | J16: =($G$2*J$6)+($G$3*distancematrix!G10) -> -0.0364615 | K16: =($G$2*K$6)+($G$3*distancematrix!H10) -> 0.2017274 | L16: =($G$2*L$6)+($G$3*distancematrix!I10) -> -0.4444354 | ... AF16: =($G$2*AF$6)+($G$3*distancematrix!AC10) -> 0.5811855
A17: 17 | B17: 2 | D17: 11 | E17: =($G$2*E$6)+($G$3*distancematrix!B11) -> 0.1423918 | F17: =($G$2*F$6)+($G$3*distancematrix!C11) -> -0.1387953 | G17: =($G$2*G$6)+($G$3*distancematrix!D11) -> -0.0327816 | H17: =($G$2*H$6)+($G$3*distancematrix!E11) -> -0.0865007 | I17: =($G$2*I$6)+($G$3*distancematrix!F11) -> 0.0541704 | J17: =($G$2*J$6)+($G$3*distancematrix!G11) -> -0.0122035 | K17: =($G$2*K$6)+($G$3*distancematrix!H11) -> 0.1173904 | L17: =($G$2*L$6)+($G$3*distancematrix!I11) -> -0.3551401 | ... AF17: =($G$2*AF$6)+($G$3*distancematrix!AC11) -> 0.503507
A18: 18 | B18: 34 | D18: 12 | E18: =($G$2*E$6)+($G$3*distancematrix!B12) -> 0.1423095 | F18: =($G$2*F$6)+($G$3*distancematrix!C12) -> -0.1686325 | G18: =($G$2*G$6)+($G$3*distancematrix!D12) -> -0.0474633 | H18: =($G$2*H$6)+($G$3*distancematrix!E12) -> -0.1467578 | I18: =($G$2*I$6)+($G$3*distancematrix!F12) -> 0.0754539 | J18: =($G$2*J$6)+($G$3*distancematrix!G12) -> -0.0341819 | K18: =($G$2*K$6)+($G$3*distancematrix!H12) -> 0.1604472 | L18: =($G$2*L$6)+($G$3*distancematrix!I12) -> -0.4058945 | ... AF18: =($G$2*AF$6)+($G$3*distancematrix!AC12) -> 0.5636305
A19: 19 | B19: 162 | D19: 13 | E19: =($G$2*E$6)+($G$3*distancematrix!B13) -> 0.0279396 | F19: =($G$2*F$6)+($G$3*distancematrix!C13) -> -0.2650447 | G19: =($G$2*G$6)+($G$3*distancematrix!D13) -> -0.1545007 | H19: =($G$2*H$6)+($G$3*distancematrix!E13) -> -0.1786588 | I19: =($G$2*I$6)+($G$3*distancematrix!F13) -> -0.0402705 | J19: =($G$2*J$6)+($G$3*distancematrix!G13) -> -0.1338979 | K19: =($G$2*K$6)+($G$3*distancematrix!H13) -> 0.0500232 | L19: =($G$2*L$6)+($G$3*distancematrix!I13) -> -0.3503837 | ... AF19: =($G$2*AF$6)+($G$3*distancematrix!AC13) -> 0.4846818
... A29: 29 | B29: 238 | D29: 23 | E29: =($G$2*E$6)+($G$3*distancematrix!B23) -> -0.4123008 | F29: =($G$2*F$6)+($G$3*distancematrix!C23) -> -0.657312 | G29: =($G$2*G$6)+($G$3*distancematrix!D23) -> -0.5833712 | H29: =($G$2*H$6)+($G$3*distancematrix!E23) -> -0.5131396 | I29: =($G$2*I$6)+($G$3*distancematrix!F23) -> -0.5053781 | J29: =($G$2*J$6)+($G$3*distancematrix!G23) -> -0.570262 | K29: =($G$2*K$6)+($G$3*distancematrix!H23) -> -0.4256546 | L29: =($G$2*L$6)+($G$3*distancematrix!I23) -> -0.2686365 | ... AF29: =($G$2*AF$6)+($G$3*distancematrix!AC23) -> 0.0032134
D30: 24 | E30: =($G$2*E$6)+($G$3*distancematrix!B24) -> -0.2106478 | F30: =($G$2*F$6)+($G$3*distancematrix!C24) -> -0.5148821 | G30: =($G$2*G$6)+($G$3*distancematrix!D24) -> -0.4011201 | H30: =($G$2*H$6)+($G$3*distancematrix!E24) -> -0.4163201 | I30: =($G$2*I$6)+($G$3*distancematrix!F24) -> -0.2691563 | J30: =($G$2*J$6)+($G$3*distancematrix!G24) -> -0.3820492 | K30: =($G$2*K$6)+($G$3*distancematrix!H24) -> -0.1714227 | L30: =($G$2*L$6)+($G$3*distancematrix!I24) -> -0.4544286 | ... AF30: =($G$2*AF$6)+($G$3*distancematrix!AC24) -> 0.2779074
D31: 25 | E31: =($G$2*E$6)+($G$3*distancematrix!B25) -> -0.1662297 | F31: =($G$2*F$6)+($G$3*distancematrix!C25) -> -0.4347523 | G31: =($G$2*G$6)+($G$3*distancematrix!D25) -> -0.3408215 | H31: =($G$2*H$6)+($G$3*distancematrix!E25) -> -0.3032446 | I31: =($G$2*I$6)+($G$3*distancematrix!F25) -> -0.2430399 | J31: =($G$2*J$6)+($G$3*distancematrix!G25) -> -0.320937 | K31: =($G$2*K$6)+($G$3*distancematrix!H25) -> -0.1555661 | L31: =($G$2*L$6)+($G$3*distancematrix!I25) -> -0.2698469 | ... AF31: =($G$2*AF$6)+($G$3*distancematrix!AC25) -> 0.2799924
D32: 26 | E32: =($G$2*E$6)+($G$3*distancematrix!B26) -> -0.259899 | F32: =($G$2*F$6)+($G$3*distancematrix!C26) -> -0.54599 | G32: =($G$2*G$6)+($G$3*distancematrix!D26) -> -0.441409 | H32: =($G$2*H$6)+($G$3*distancematrix!E26) -> -0.4269024 | I32: =($G$2*I$6)+($G$3*distancematrix!F26) -> -0.3247727 | J32: =($G$2*J$6)+($G$3*distancematrix!G26) -> -0.420316 | K32: =($G$2*K$6)+($G$3*distancematrix!H26) -> -0.2298095 | L32: =($G$2*L$6)+($G$3*distancematrix!I26) -> -0.3961096 | ... AF32: =($G$2*AF$6)+($G$3*distancematrix!AC26) -> 0.215715
D33: 27 | E33: =($G$2*E$6)+($G$3*distancematrix!B27) -> -0.3638403 | F33: =($G$2*F$6)+($G$3*distancematrix!C27) -> -0.5938215 | G33: =($G$2*G$6)+($G$3*distancematrix!D27) -> -0.5373554 | H33: =($G$2*H$6)+($G$3*distancematrix!E27) -> -0.455036 | I33: =($G$2*I$6)+($G$3*distancematrix!F27) -> -0.4781767 | J33: =($G$2*J$6)+($G$3*distancematrix!G27) -> -0.5352049 | K33: =($G$2*K$6)+($G$3*distancematrix!H27) -> -0.4115147 | L33: =($G$2*L$6)+($G$3*distancematrix!I27) -> -0.1412779 | ... AF33: =($G$2*AF$6)+($G$3*distancematrix!AC27) -> 0.0037732
D34: 28 | E34: =($G$2*E$6)+($G$3*distancematrix!B28) -> 0.0826851 | F34: =($G$2*F$6)+($G$3*distancematrix!C28) -> -0.1879501 | G34: =($G$2*G$6)+($G$3*distancematrix!D28) -> -0.0906334 | H34: =($G$2*H$6)+($G$3*distancematrix!E28) -> -0.0875718 | I34: =($G$2*I$6)+($G$3*distancematrix!F28) -> -0.005642 | J34: =($G$2*J$6)+($G$3*distancematrix!G28) -> -0.0718764 | K34: =($G$2*K$6)+($G$3*distancematrix!H28) -> 0.0652634 | L34: =($G$2*L$6)+($G$3*distancematrix!I28) -> -0.3079454 | ... AF34: =($G$2*AF$6)+($G$3*distancematrix!AC28) -> 0.4701344
D35: 29 | E35: =($G$2*E$6)+($G$3*distancematrix!B29) -> 0.1343902 | F35: =($G$2*F$6)+($G$3*distancematrix!C29) -> -0.206662 | G35: =($G$2*G$6)+($G$3*distancematrix!D29) -> -0.0778924 | H35: =($G$2*H$6)+($G$3*distancematrix!E29) -> -0.210722 | I35: =($G$2*I$6)+($G$3*distancematrix!F29) -> 0.0793285 | J35: =($G$2*J$6)+($G$3*distancematrix!G29) -> -0.082615 | K35: =($G$2*K$6)+($G$3*distancematrix!H29) -> 0.1776036 | L35: =($G$2*L$6)+($G$3*distancematrix!I29) -> -0.4656296 | ... AF35: =($G$2*AF$6)+($G$3*distancematrix!AC29) -> 0.59710791
P40: EXP
E41: 1 | F41: 2 | G41: 3 | H41: 5 | I41: 6 | J41: 7 | K41: 8 | L41: 9 | M41: 10 | N41: 11 | O41: 12 | P41: 13 | Q41: 14 | R41: 15 | S41: 16 | T41: 17 | U41: 18 | V41: 19 | W41: 20 | X41: 21 | Y41: 22 | Z41: 23 | AA41: 24 | AB41: 25 | AC41: 26 | AD41: 27 | AE41: 28 | AF41: 29
D42: 1 | E42: =EXP(E8) -> 1.3951781 | F42: =EXP(F8) -> 0.93203548 | G42: =EXP(G8) -> 0.99161218 | H42: =EXP(H8) -> 0.76909598 | I42: =EXP(I8) -> 1.0955215 | J42: =EXP(J8) -> 0.86376426 | K42: =EXP(K8) -> 1.0420066 | L42: =EXP(L8) -> 0.571841 | ... AF42: =EXP(AF8) -> 1.4353191 | AG42: =SUM(E42:AF42) -> 22.168997
D43: 2 | E43: =EXP(E9) -> 1.3135726 | F43: =EXP(F9) -> 1.0058007 | G43: =EXP(G9) -> 1.0331628 | H43: =EXP(H9) -> 0.85663745 | I43: =EXP(I9) -> 1.0563712 | J43: =EXP(J9) -> 0.91125811 | K43: =EXP(K9) -> 1.0320111 | L43: =EXP(L9) -> 0.64507132 | ... AF43: =EXP(AF9) -> 1.4383117 | AG43: =SUM(E43:AF43) -> 23.297633
D44: 3 | E44: =EXP(E10) -> 1.325675 | F44: =EXP(F10) -> 0.98003676 | G44: =EXP(G10) -> 1.0471798 | H44: =EXP(H10) -> 0.86303667 | I44: =EXP(I10) -> 1.136452 | J44: =EXP(J10) -> 0.96879941 | K44: =EXP(K10) -> 1.1158581 | L44: =EXP(L10) -> 0.63937234 | ... AF44: =EXP(AF10) -> 1.5518528 | AG44: =SUM(E44:AF44) -> 24.221455
D45: 5 | E45: =EXP(E11) -> 1.1217714 | F45: =EXP(F11) -> 0.8865418 | G45: =EXP(G11) -> 0.94158128 | H45: =EXP(H11) -> 0.94238597 | I45: =EXP(I11) -> 0.98278657 | J45: =EXP(J11) -> 0.92686616 | K45: =EXP(K11) -> 1.0197926 | L45: =EXP(L11) -> 0.75827778 | ... AF45: =EXP(AF11) -> 1.4824906 | AG45: =SUM(E45:AF45) -> 25.088894
D46: 6 | E46: =EXP(E12) -> 1.3143681 | F46: =EXP(F12) -> 0.89927185 | G46: =EXP(G12) -> 1.0198868 | H46: =EXP(H12) -> 0.8084097 | I46: =EXP(I12) -> 1.1793491 | J46: =EXP(J12) -> 0.93866268 | K46: =EXP(K12) -> 1.1832652 | L46: =EXP(L12) -> 0.60064608 | ... AF46: =EXP(AF12) -> 1.6297897 | AG46: =SUM(E46:AF46) -> 24.010288
D47: 7 | E47: =EXP(E13) -> 1.2270318 | F47: =EXP(F13) -> 0.91850255 | G47: =EXP(G13) -> 1.0294357 | H47: =EXP(H13) -> 0.90272158 | I47: =EXP(I13) -> 1.1114094 | J47: =EXP(J13) -> 1.0098798 | K47: =EXP(K13) -> 1.152231 | L47: =EXP(L13) -> 0.67272376 | ... AF47: =EXP(AF13) -> 1.6412128 | AG47: =SUM(E47:AF47) -> 25.366874
D48: 8 | E48: =EXP(E14) -> 1.2208146 | F48: =EXP(F14) -> 0.85791041 | G48: =EXP(G14) -> 0.97789664 | H48: =EXP(H14) -> 0.81915726 | I48: =EXP(I14) -> 1.1554873 | J48: =EXP(J14) -> 0.95029445 | K48: =EXP(K14) -> 1.2374778 | L48: =EXP(L14) -> 0.61843691 | ... AF48: =EXP(AF14) -> 1.7558808 | AG48: =SUM(E48:AF48) -> 24.873956
D49: 9 | E49: =EXP(E15) -> 0.81663601 | F49: =EXP(F15) -> 0.65364107 | G49: =EXP(G15) -> 0.68298608 | H49: =EXP(H15) -> 0.74243385 | I49: =EXP(I15) -> 0.71495019 | J49: =EXP(J15) -> 0.67628446 | K49: =EXP(K15) -> 0.75382307 | L49: =EXP(L15) -> 0.9499059 | ... AF49: =EXP(AF15) -> 1.1249065 | AG49: =SUM(E49:AF49) -> 22.572227
D50: 10 | E50: =EXP(E16) -> 1.1861595 | F50: =EXP(F16) -> 0.8519583 | G50: =EXP(G16) -> 0.96807434 | H50: =EXP(H16) -> 0.84106124 | I50: =EXP(I16) -> 1.1172225 | J50: =EXP(J16) -> 0.96419521 | K50: =EXP(K16) -> 1.2235144 | L50: =EXP(L16) -> 0.64118619 | ... AF50: =EXP(AF16) -> 1.788157 | AG50: =SUM(E50:AF50) -> 25.425627
D51: 11 | E51: =EXP(E17) -> 1.1530283 | F51: =EXP(F17) -> 0.87040618 | G51: =EXP(G17) -> 0.96774989 | H51: =EXP(H17) -> 0.91713491 | I51: =EXP(I17) -> 1.0556645 | J51: =EXP(J17) -> 0.98787066 | K51: =EXP(K17) -> 1.1245584 | L51: =EXP(L17) -> 0.70107522 | ... AF51: =EXP(AF17) -> 1.6545135 | AG51: =SUM(E51:AF51) -> 25.891968
D52: 12 | E52: =EXP(E18) -> 1.1529334 | F52: =EXP(F18) -> 0.84481932 | G52: =EXP(G18) -> 0.95364547 | H52: =EXP(H18) -> 0.86350309 | I52: =EXP(I18) -> 1.0783735 | J52: =EXP(J18) -> 0.9663957 | K52: =EXP(K18) -> 1.1740358 | L52: =EXP(L18) -> 0.66638047 | ... AF52: =EXP(AF18) -> 1.7570399 | AG52: =SUM(E52:AF52) -> 25.800953
D53: 13 | E53: =EXP(E19) -> 1.0283336 | F53: =EXP(F19) -> 0.76717166 | G53: =EXP(G19) -> 0.85684289 | H53: =EXP(H19) -> 0.83639123 | I53: =EXP(I19) -> 0.96052958 | J53: =EXP(J19) -> 0.87467936 | K53: =EXP(K19) -> 1.0512955 | L53: =EXP(L19) -> 0.70441775 | ... AF53: =EXP(AF19) -> 1.6236583 | AG53: =SUM(E53:AF53) -> 25.88383
...

Sheet ODmatrix
A1: idzoning | B1: pf1 family
A2: 1 | B2: 1094 | G2: 1 | H2: 2 | I2: 3 | J2: 5 | K2: 6 | L2: 7 | M2: 8 | N2: 9 | O2: 10 | P2: 11 | Q2: 12 | R2: 13 | S2: 14 | T2: 15 | U2: 16 | V2: 17 | W2: 18 | X2: 19 | Y2: 20 | Z2: 21 | AA2: 22 | AB2: 23 | AC2: 24 | AD2: 25 | AE2: 26 | AF2: 27 | AG2: 28 | AH2: 29
A3: 2 | B3: 633 | F3: 1 | G3: =generation!$C2*distribution!$E77 -> 18.768379 | H3: =generation!$C2*distribution!$E77 -> 18.768379 | I3: =generation!$C2*distribution!$E77 -> 18.768379 | J3: =generation!$C2*distribution!$E77 -> 18.768379 | K3: =generation!$C2*distribution!$E77 -> 18.768379 | L3: =generation!$C2*distribution!$E77 -> 18.768379 | M3: =generation!$C2*distribution!$E77 -> 18.768379 | N3: =generation!$C2*distribution!$E77 -> 18.768379 | ... AH3: =generation!$C2*distribution!$E77 -> 18.768379 | AI3: =SUM(G3:AH3) -> 525.51462
A4: 3 | B4: 592 | F4: 2 | G4: =generation!$C3*distribution!$E78 -> 9.7290815 | H4: =generation!$C3*distribution!$E78 -> 9.7290815 | I4: =generation!$C3*distribution!$E78 -> 9.7290815 | J4: =generation!$C3*distribution!$E78 -> 9.7290815 | K4: =generation!$C3*distribution!$E78 -> 9.7290815 | L4: =generation!$C3*distribution!$E78 -> 9.7290815 | M4: =generation!$C3*distribution!$E78 -> 9.7290815 | N4: =generation!$C3*distribution!$E78 -> 9.7290815 | ... AH4: =generation!$C3*distribution!$E78 -> 9.7290815 | AI4: =SUM(G4:AH4) -> 272.41428
A5: 5 | B5: 318 | F5: 3 | G5: =generation!$C4*distribution!$E79 -> 8.8325155 | H5: =generation!$C4*distribution!$E79 -> 8.8325155 | I5: =generation!$C4*distribution!$E79 -> 8.8325155 | J5: =generation!$C4*distribution!$E79 -> 8.8325155 | K5: =generation!$C4*distribution!$E79 -> 8.8325155 | L5: =generation!$C4*distribution!$E79 -> 8.8325155 | M5: =generation!$C4*distribution!$E79 -> 8.8325155 | N5: =generation!$C4*distribution!$E79 -> 8.8325155 | ... AH5: =generation!$C4*distribution!$E79 -> 8.8325155 | AI5: =SUM(G5:AH5) -> 247.31043
A6: 6 | B6: 1108 | F6: 5 | G6: =generation!$C5*distribution!$E80 -> 3.8759288 | H6: =generation!$C5*distribution!$E80 -> 3.8759288 | I6: =generation!$C5*distribution!$E80 -> 3.8759288 | J6: =generation!$C5*distribution!$E80 -> 3.8759288 | K6: =generation!$C5*distribution!$E80 -> 3.8759288 | L6: =generation!$C5*distribution!$E80 -> 3.8759288 | M6: =generation!$C5*distribution!$E80 -> 3.8759288 | N6: =generation!$C5*distribution!$E80 -> 3.8759288 | ... AH6: =generation!$C5*distribution!$E80 -> 3.8759288 | AI6: =SUM(G6:AH6) -> 108.52601
A7: 7 | B7: 1067 | F7: 6 | G7: =generation!$C6*distribution!$E81 -> 16.534278 | H7: =generation!$C6*distribution!$E81 -> 16.534278 | I7: =generation!$C6*distribution!$E81 -> 16.534278 | J7: =generation!$C6*distribution!$E81 -> 16.534278 | K7: =generation!$C6*distribution!$E81 -> 16.534278 | L7: =generation!$C6*distribution!$E81 -> 16.534278 | M7: =generation!$C6*distribution!$E81 -> 16.534278 | N7: =generation!$C6*distribution!$E81 -> 16.534278 | ... AH7: =generation!$C6*distribution!$E81 -> 16.534278 | AI7: =SUM(G7:AH7) -> 462.95979
A8: 8 | B8: 1488 | F8: 7 | G8: =generation!$C7*distribution!$E82 -> 14.069515 | H8: =generation!$C7*distribution!$E82 -> 14.069515 | I8: =generation!$C7*distribution!$E82 -> 14.069515 | J8: =generation!$C7*distribution!$E82 -> 14.069515 | K8: =generation!$C7*distribution!$E82 -> 14.069515 | L8: =generation!$C7*distribution!$E82 -> 14.069515 | M8: =generation!$C7*distribution!$E82 -> 14.069515 | N8: =generation!$C7*distribution!$E82 -> 14.069515 | ... AH8: =generation!$C7*distribution!$E82 -> 14.069515 | AI8: =SUM(G8:AH8) -> 393.94643
A9: 9 | B9: 500 | F9: 8 | G9: =generation!$C8*distribution!$E83 -> 19.908274 | H9: =generation!$C8*distribution!$E83 -> 19.908274 | I9: =generation!$C8*distribution!$E83 -> 19.908274 | J9: =generation!$C8*distribution!$E83 -> 19.908274 | K9: =generation!$C8*distribution!$E83 -> 19.908274 | L9: =generation!$C8*distribution!$E83 -> 19.908274 | M9: =generation!$C8*distribution!$E83 -> 19.908274 | N9: =generation!$C8*distribution!$E83 -> 19.908274 | ... AH9: =generation!$C8*distribution!$E83 -> 19.908274 | AI9: =SUM(G9:AH9) -> 557.43168
A10: 10 | B10: 882 | F10: 9 | G10: =generation!$C9*distribution!$E84 -> 4.9311701 | H10: =generation!$C9*distribution!$E84 -> 4.9311701 | I10: =generation!$C9*distribution!$E84 -> 4.9311701 | J10: =generation!$C9*distribution!$E84 -> 4.9311701 | K10: =generation!$C9*distribution!$E84 -> 4.9311701 | L10: =generation!$C9*distribution!$E84 -> 4.9311701 | M10: =generation!$C9*distribution!$E84 -> 4.9311701 | N10: =generation!$C9*distribution!$E84 -> 4.9311701 | ... AH10: =generation!$C9*distribution!$E84 -> 4.9311701 | AI10: =SUM(G10:AH10) -> 138.07276
A11: 11 | B11: 61 | F11: 10 | G11: =generation!$C10*distribution!$E85 -> 11.21672 | H11: =generation!$C10*distribution!$E85 -> 11.21672 | I11: =generation!$C10*distribution!$E85 -> 11.21672 | J11: =generation!$C10*distribution!$E85 -> 11.21672 | K11: =generation!$C10*distribution!$E85 -> 11.21672 | L11: =generation!$C10*distribution!$E85 -> 11.21672 | M11: =generation!$C10*distribution!$E85 -> 11.21672 | N11: =generation!$C10*distribution!$E85 -> 11.21672 | ... AH11: =generation!$C10*distribution!$E85 -> 11.21672 | AI11: =SUM(G11:AH11) -> 314.06815
A12: 12 | B12: 386 | F12: 11 | G12: =generation!$C11*distribution!$E86 -> 0.74050944 | H12: =generation!$C11*distribution!$E86 -> 0.74050944 | I12: =generation!$C11*distribution!$E86 -> 0.74050944 | J12: =generation!$C11*distribution!$E86 -> 0.74050944 | K12: =generation!$C11*distribution!$E86 -> 0.74050944 | L12: =generation!$C11*distribution!$E86 -> 0.74050944 | M12: =generation!$C11*distribution!$E86 -> 0.74050944 | N12: =generation!$C11*distribution!$E86 -> 0.74050944 | ... AH12: =generation!$C11*distribution!$E86 -> 0.74050944 | AI12: =SUM(G12:AH12) -> 20.734264
A13: 13 | B13: 535 | F13: 12 | G13: =generation!$C12*distribution!$E87 -> 4.7019894 | H13: =generation!$C12*distribution!$E87 -> 4.7019894 | I13: =generation!$C12*distribution!$E87 -> 4.7019894 | J13: =generation!$C12*distribution!$E87 -> 4.7019894 | K13: =generation!$C12*distribution!$E87 -> 4.7019894 | L13: =generation!$C12*distribution!$E87 -> 4.7019894 | M13: =generation!$C12*distribution!$E87 -> 4.7019894 | N13: =generation!$C12*distribution!$E87 -> 4.7019894 | ... AH13: =generation!$C12*distribution!$E87 -> 4.7019894 | AI13: =SUM(G13:AH13) -> 131.6557
A14: 14 | B14: 539 | F14: 13 | G14: =generation!$C13*distribution!$E88 -> 5.7940883 | H14: =generation!$C13*distribution!$E88 -> 5.7940883 | I14: =generation!$C13*distribution!$E88 -> 5.7940883 | J14: =generation!$C13*distribution!$E88 -> 5.7940883 | K14: =generation!$C13*distribution!$E88 -> 5.7940883 | L14: =generation!$C13*distribution!$E88 -> 5.7940883 | M14: =generation!$C13*distribution!$E88 -> 5.7940883 | N14: =generation!$C13*distribution!$E88 -> 5.7940883 | ... AH14: =generation!$C13*distribution!$E88 -> 5.7940883 | AI14: =SUM(G14:AH14) -> 162.23447
... A29: 29 | B29: 833 | F29: 28 | G29: =generation!$C28*distribution!$E103 -> 10.846828 | H29: =generation!$C28*distribution!$E103 -> 10.846828 | I29: =generation!$C28*distribution!$E103 -> 10.846828 | J29: =generation!$C28*distribution!$E103 -> 10.846828 | K29: =generation!$C28*distribution!$E103 -> 10.846828 | L29: =generation!$C28*distribution!$E103 -> 10.846828 | M29: =generation!$C28*distribution!$E103 -> 10.846828 | N29: =generation!$C28*distribution!$E103 -> 10.846828 | ... AH29: =generation!$C28*distribution!$E103 -> 10.846828 | AI29: =SUM(G29:AH29) -> 303.71119
F30: 29 | G30: =generation!$C29*distribution!$E104 -> 10.332379 | H30: =generation!$C29*distribution!$E104 -> 10.332379 | I30: =generation!$C29*distribution!$E104 -> 10.332379 | J30: =generation!$C29*distribution!$E104 -> 10.332379 | K30: =generation!$C29*distribution!$E104 -> 10.332379 | L30: =generation!$C29*distribution!$E104 -> 10.332379 | M30: =generation!$C29*distribution!$E104 -> 10.332379 | N30: =generation!$C29*distribution!$E104 -> 10.332379 | ... AH30: =generation!$C29*distribution!$E104 -> 10.332379 | AI30: =SUM(G30:AH30) -> 289.30662
G37: 1 | H37: 2 | I37: 3 | J37: 5 | K37: 6 | L37: 7 | M37: 8 | N37: 9 | O37: 10 | P37: 11 | Q37: 12 | R37: 13 | S37: 14 | T37: 15 | U37: 16 | V37: 17 | W37: 18 | X37: 19 | Y37: 20 | Z37: 21 | AA37: 22 | AB37: 23 | AC37: 24 | AD37: 25 | AE37: 26 | AF37: 27 | AG37: 28 | AH37: 29
F38: 1 | G38: =ROUND(G3,0) -> 19 | H38: =ROUND(H3,0) -> 19 | I38: =ROUND(I3,0) -> 19 | J38: =ROUND(J3,0) -> 19 | K38: =ROUND(K3,0) -> 19 | L38: =ROUND(L3,0) -> 19 | M38: =ROUND(M3,0) -> 19 | N38: =ROUND(N3,0) -> 19 | ... AH38: =ROUND(AH3,0) -> 19 | AI38: =SUM(G38:AH38) -> 532
F39: 2 | G39: =ROUND(G4,0) -> 10 | H39: =ROUND(H4,0) -> 10 | I39: =ROUND(I4,0) -> 10 | J39: =ROUND(J4,0) -> 10 | K39: =ROUND(K4,0) -> 10 | L39: =ROUND(L4,0) -> 10 | M39: =ROUND(M4,0) -> 10 | N39: =ROUND(N4,0) -> 10 | ... AH39: =ROUND(AH4,0) -> 10 | AI39: =SUM(G39:AH39) -> 280
F40: 3 | G40: =ROUND(G5,0) -> 9 | H40: =ROUND(H5,0) -> 9 | I40: =ROUND(I5,0) -> 9 | J40: =ROUND(J5,0) -> 9 | K40: =ROUND(K5,0) -> 9 | L40: =ROUND(L5,0) -> 9 | M40: =ROUND(M5,0) -> 9 | N40: =ROUND(N5,0) -> 9 | ... AH40: =ROUND(AH5,0) -> 9 | AI40: =SUM(G40:AH40) -> 252
F41: 5 | G41: =ROUND(G6,0) -> 4 | H41: =ROUND(H6,0) -> 4 | I41: =ROUND(I6,0) -> 4 | J41: =ROUND(J6,0) -> 4 | K41: =ROUND(K6,0) -> 4 | L41: =ROUND(L6,0) -> 4 | M41: =ROUND(M6,0) -> 4 | N41: =ROUND(N6,0) -> 4 | ... AH41: =ROUND(AH6,0) -> 4 | AI41: =SUM(G41:AH41) -> 112
F42: 6 | G42: =ROUND(G7,0) -> 17 | H42: =ROUND(H7,0) -> 17 | I42: =ROUND(I7,0) -> 17 | J42: =ROUND(J7,0) -> 17 | K42: =ROUND(K7,0) -> 17 | L42: =ROUND(L7,0) -> 17 | M42: =ROUND(M7,0) -> 17 | N42: =ROUND(N7,0) -> 17 | ... AH42: =ROUND(AH7,0) -> 17 | AI42: =SUM(G42:AH42) -> 476
F43: 7 | G43: =ROUND(G8,0) -> 14 | H43: =ROUND(H8,0) -> 14 | I43: =ROUND(I8,0) -> 14 | J43: =ROUND(J8,0) -> 14 | K43: =ROUND(K8,0) -> 14 | L43: =ROUND(L8,0) -> 14 | M43: =ROUND(M8,0) -> 14 | N43: =ROUND(N8,0) -> 14 | ... AH43: =ROUND(AH8,0) -> 14 | AI43: =SUM(G43:AH43) -> 392
F44: 8 | G44: =ROUND(G9,0) -> 20 | H44: =ROUND(H9,0) -> 20 | I44: =ROUND(I9,0) -> 20 | J44: =ROUND(J9,0) -> 20 | K44: =ROUND(K9,0) -> 20 | L44: =ROUND(L9,0) -> 20 | M44: =ROUND(M9,0) -> 20 | N44: =ROUND(N9,0) -> 20 | ... AH44: =ROUND(AH9,0) -> 20 | AI44: =SUM(G44:AH44) -> 560
F45: 9 | G45: =ROUND(G10,0) -> 5 | H45: =ROUND(H10,0) -> 5 | I45: =ROUND(I10,0) -> 5 | J45: =ROUND(J10,0) -> 5 | K45: =ROUND(K10,0) -> 5 | L45: =ROUND(L10,0) -> 5 | M45: =ROUND(M10,0) -> 5 | N45: =ROUND(N10,0) -> 5 | ... AH45: =ROUND(AH10,0) -> 5 | AI45: =SUM(G45:AH45) -> 140
F46: 10 | G46: =ROUND(G11,0) -> 11 | H46: =ROUND(H11,0) -> 11 | I46: =ROUND(I11,0) -> 11 | J46: =ROUND(J11,0) -> 11 | K46: =ROUND(K11,0) -> 11 | L46: =ROUND(L11,0) -> 11 | M46: =ROUND(M11,0) -> 11 | N46: =ROUND(N11,0) -> 11 | ... AH46: =ROUND(AH11,0) -> 11 | AI46: =SUM(G46:AH46) -> 308
F47: 11 | G47: =ROUND(G12,0) -> 1 | H47: =ROUND(H12,0) -> 1 | I47: =ROUND(I12,0) -> 1 | J47: =ROUND(J12,0) -> 1 | K47: =ROUND(K12,0) -> 1 | L47: =ROUND(L12,0) -> 1 | M47: =ROUND(M12,0) -> 1 | N47: =ROUND(N12,0) -> 1 | ... AH47: =ROUND(AH12,0) -> 1 | AI47: =SUM(G47:AH47) -> 28
F48: 12 | G48: =ROUND(G13,0) -> 5 | H48: =ROUND(H13,0) -> 5 | I48: =ROUND(I13,0) -> 5 | J48: =ROUND(J13,0) -> 5 | K48: =ROUND(K13,0) -> 5 | L48: =ROUND(L13,0) -> 5 | M48: =ROUND(M13,0) -> 5 | N48: =ROUND(N13,0) -> 5 | ... AH48: =ROUND(AH13,0) -> 5 | AI48: =SUM(G48:AH48) -> 140
F49: 13 | G49: =ROUND(G14,0) -> 6 | H49: =ROUND(H14,0) -> 6 | I49: =ROUND(I14,0) -> 6 | J49: =ROUND(J14,0) -> 6 | K49: =ROUND(K14,0) -> 6 | L49: =ROUND(L14,0) -> 6 | M49: =ROUND(M14,0) -> 6 | N49: =ROUND(N14,0) -> 6 | ... AH49: =ROUND(AH14,0) -> 6 | AI49: =SUM(G49:AH49) -> 168
... F65: 29 | G65: =ROUND(G30,0) -> 10 | H65: =ROUND(H30,0) -> 10 | I65: =ROUND(I30,0) -> 10 | J65: =ROUND(J30,0) -> 10 | K65: =ROUND(K30,0) -> 10 | L65: =ROUND(L30,0) -> 10 | M65: =ROUND(M30,0) -> 10 | N65: =ROUND(N30,0) -> 10 | ... AH65: =ROUND(AH30,0) -> 10 | AI65: =SUM(G65:AH65) -> 280
