Workbook

Sheet data
A1: idzoning | B1: p61 employees | C1: p131 students | D1: pf1 family
A2: 1 | B2: 953 | C2: 229 | D2: 1094
A3: 2 | B3: 558 | C3: 149 | D3: 633
A4: 3 | B4: 478 | C4: 144 | D4: 592
A5: 5 | B5: 0 | C5: 0 | D5: 0
A6: 6 | B6: 268 | C6: 71 | D6: 318
A7: 7 | B7: 921 | C7: 233 | D7: 1108
A8: 8 | B8: 947 | C8: 269 | D8: 1067
A9: 9 | B9: 1193 | C9: 299 | D9: 1488
A10: 10 | B10: 468 | C10: 114 | D10: 500
A11: 11 | B11: 787 | C11: 186 | D11: 882
A12: 12 | B12: 47 | C12: 12 | D12: 61
A13: 13 | B13: 341 | C13: 100 | D13: 386
... A45: 0 | B45: 0 | C45: 0 | D45: 0

Sheet distancematrix
B1: 1 | C1: 2 | D1: 3 | E1: 5 | F1: 6 | G1: 7 | H1: 8 | I1: 9 | J1: 10 | K1: 11 | L1: 12 | M1: 13 | N1: 14 | O1: 15 | P1: 16 | Q1: 17 | R1: 18 | S1: 19 | T1: 20 | U1: 21 | V1: 22 | W1: 23 | X1: 24 | Y1: 25 | Z1: 26 | AA1: 27 | AB1: 28 | AC1: 29 | AD1: 101 | AE1: 102 | AF1: 103 | AG1: 104 | AH1: 105 | AI1: 106 | AJ1: 107 | AK1: 108 | AL1: 109 | AM1: 110 | AN1: 111 | AO1: 112 | AP1: 113 | AQ1: 114 | AR1: 115
A2: 1 | B2: 0.68181955 | C2: 1.284534 | D2: 1.192822 | E2: 2.86295 | F2: 1.27848 | G2: 1.966059 | H2: 2.016857 | I2: 6.037658 | J2: 2.304832 | K2: 2.588122 | L2: 2.588945 | M2: 3.732644 | N2: 3.669351 | O2: 4.289047 | P2: 9.207378 | Q2: 5.012865 | R2: 4.858912 | S2: 5.345885 | T2: 6.695306 | U2: 7.363369 | V2: 9.366328 | W2: 8.135048 | X2: 6.118518 | Y2: 5.674337 | Z2: 6.61103 | AA2: 7.650443 | AB2: 3.185189 | AC2: 2.668138 | AD2: 10.802906 | AE2: 6.659687 | AF2: 7.336507 | AG2: 6.360181 | AH2: 7.55162 | AI2: 8.299856 | AJ2: 9.628539 | AK2: 8.150397 | AL2: 7.86928 | AM2: 6.657017 | AN2: 6.282654 | AO2: 4.430696 | AP2: 0.755505 | AQ2: 1.097192 | AR2: 1.219731 | AS2: 2.091159
A3: 2 | B3: 1.284534 | C3: 0.52285065 | D3: 0.782342 | E3: 1.78496 | F3: 1.642389 | G3: 1.430796 | H3: 2.113246 | I3: 4.832659 | J3: 2.182867 | K3: 1.968643 | L3: 2.267015 | M3: 3.231137 | N3: 2.85932 | O3: 3.038381 | P3: 8.427841 | Q3: 4.022587 | R3: 4.218967 | S3: 4.859198 | T3: 5.696777 | U3: 6.578801 | V3: 8.444111 | W3: 7.15381 | X3: 5.729511 | Y3: 4.928213 | Z3: 6.04059 | AA3: 6.518905 | AB3: 2.460191 | AC3: 2.64731 | AD3: 9.801818 | AE3: 6.369103 | AF3: 6.893177 | AG3: 6.086192 | AH3: 6.941477 | AI3: 7.714135 | AJ3: 8.598343 | AK3: 6.973114 | AL3: 6.67606 | AM3: 5.406179 | AN3: 5.010943 | AO3: 3.156372 | AP3: 1.829099 | AQ3: 2.30603 | AR3: 1.58082 | AS3: 1.705355
A4: 3 | B4: 1.192822 | C4: 0.782342 | D4: 0.64758372 | E4: 1.710536 | F4: 0.911674 | G4: 0.818482 | H4: 1.332103 | I4: 4.921398 | J4: 1.433054 | K4: 1.436406 | L4: 1.583223 | M4: 2.653597 | N4: 2.486271 | O4: 3.253456 | P4: 8.048577 | Q4: 3.820956 | R4: 3.732354 | S4: 4.290349 | T4: 5.502802 | U4: 6.200056 | V4: 8.178156 | W4: 6.942302 | X4: 5.119791 | Y4: 4.516805 | Z4: 5.52268 | AA4: 6.482144 | AB4: 2.014924 | AC4: 1.887514 | AD4: 9.610084 | AE4: 5.722149 | AF4: 6.313279 | AG4: 5.431706 | AH4: 6.449403 | AI4: 7.210189 | AJ4: 8.436768 | AK4: 7.004267 | AL4: 6.735146 | AM4: 5.596108 | AN4: 5.275444 | AO4: 3.644563 | AP4: 1.925547 | AQ4: 2.285091 | AR4: 2.032725 | AS4: 2.42808
A5: 5 | B5: 2.86295 | C5: 1.78496 | D5: 1.710536 | E5: 0.83095856 | F5: 2.364418 | G5: 1.260966 | H5: 2.232347 | I5: 3.21577 | J5: 1.968463 | K5: 1.102562 | L5: 1.705133 | M5: 2.024143 | N5: 1.27398 | O5: 1.663624 | P5: 6.702036 | Q5: 2.239988 | R5: 2.699365 | S5: 3.470033 | T5: 3.911817 | U5: 4.863872 | V5: 6.665207 | W5: 5.368951 | X5: 4.400756 | Y5: 3.270001 | Z5: 4.506579 | AA5: 4.787915 | AB5: 1.113273 | AC5: 2.344775 | AD5: 8.017915 | AE5: 5.122256 | AF5: 5.459268 | AG5: 4.87291 | AH5: 5.349436 | AI5: 6.129299 | AJ5: 6.818116 | AK5: 5.295209 | AL5: 5.024614 | AM5: 3.925964 | AN5: 3.664738 | AO5: 2.475217 | AP5: 3.540206 | AQ5: 3.95825 | AR5: 3.360904 | AS5: 3.228292
A6: 6 | B6: 1.27848 | C6: 1.642389 | D6: 0.911674 | E6: 2.364418 | F6: 0.54115811 | G6: 1.134496 | H6: 0.745563 | I6: 5.546209 | J6: 1.082328 | K6: 1.649081 | L6: 1.436246 | M6: 2.59349 | N6: 2.759565 | O6: 4.004565 | P6: 8.129365 | Q6: 4.208612 | R6: 3.757006 | S6: 4.153375 | T6: 5.849243 | U6: 6.30768 | V6: 8.401923 | W6: 7.244566 | X6: 4.882348 | Y6: 4.621184 | Z6: 5.438512 | AA6: 6.972552 | AB6: 2.247205 | AC6: 1.3975 | AD6: 9.907828 | AE6: 5.397471 | AF6: 6.108357 | AG6: 5.096271 | AH6: 6.388663 | AI6: 7.119678 | AJ6: 8.777705 | AK6: 7.55116 | AL6: 7.309592 | AM6: 6.288022 | AN6: 6.022315 | AO6: 4.520573 | AP6: 1.988568 | AQ6: 2.148818 | AR6: 2.452091 | AS6: 3.120863
A7: 7 | B7: 1.966059 | C7: 1.430796 | D7: 0.818482 | E7: 1.260966 | F7: 1.134496 | G7: 0.40319152 | H7: 1.011339 | I7: 4.41292 | J7: 0.86612 | K7: 0.62354 | L7: 0.843324 | M7: 1.840484 | N7: 1.713728 | O7: 2.923 | P7: 7.244206 | Q7: 3.116813 | R7: 2.915117 | S7: 3.478316 | T7: 4.782451 | U7: 5.398419 | V7: 7.411004 | W7: 6.204125 | X7: 4.321997 | Y7: 3.710875 | Z7: 4.704665 | AA7: 5.853554 | AB7: 1.220269 | AC7: 1.327655 | AD7: 8.873441 | AE7: 4.944987 | AF7: 5.50589 | AG7: 4.659596 | AH7: 5.630941 | AI7: 6.391868 | AJ7: 7.719018 | AK7: 6.421262 | AL7: 6.176424 | AM7: 5.166047 | AN7: 4.924274 | AO7: 3.598071 | AP7: 2.716313 | AQ7: 3.030204 | AR7: 2.845224 | AS7: 3.136147
A8: 8 | B8: 2.016857 | C8: 2.113246 | D8: 1.332103 | E8: 2.232347 | F8: 0.745563 | G8: 1.011339 | H8: 0.29758741 | I8: 5.254316 | J8: 0.411066 | K8: 1.254436 | L8: 0.823868 | M8: 1.928108 | N8: 2.275295 | O8: 3.891076 | P8: 7.459444 | Q8: 3.74534 | R8: 3.097954 | S8: 3.435072 | T8: 5.329186 | U8: 5.656666 | V8: 7.79345 | W8: 6.684886 | X8: 4.142567 | Y8: 3.984001 | Z8: 4.726435 | AA8: 6.543487 | AB8: 1.775706 | AC8: 0.652304 | AD8: 9.332756 | AE8: 4.651911 | AF8: 5.370459 | AG8: 4.350723 | AH8: 5.679068 | AI8: 6.400601 | AJ8: 8.232398 | AK8: 7.163736 | AL8: 6.948601 | AM8: 6.057372 | AN8: 5.86258 | AO8: 4.60939 | AP8: 2.734087 | AQ8: 2.87963 | AR8: 3.160245 | AS8: 3.732045
A9: 9 | B9: 6.037658 | C9: 4.832659 | D9: 4.921398 | E9: 3.21577 | F9: 5.546209 | G9: 4.41292 | H9: 5.254316 | I9: 0.96263855 | J9: 4.893069 | K9: 4.000116 | L9: 4.50766 | M9: 3.952552 | N9: 3.10158 | O9: 1.85508 | P9: 5.126288 | Q9: 1.88906 | R9: 3.486655 | S9: 4.235979 | T9: 2.026888 | U9: 3.722821 | V9: 4.503375 | W9: 3.13508 | X9: 4.993001 | Y9: 3.147184 | Z9: 4.409811 | AA9: 1.861494 | AB9: 3.528169 | AC9: 5.105011 | AD9: 5.431627 | AE9: 5.73571 | AF9: 5.462783 | AG9: 5.628239 | AH9: 4.778525 | AI9: 5.430094 | AJ9: 4.190833 | AK9: 2.159824 | AL9: 1.845716 | AM9: 0.924768 | AN9: 1.185671 | AO9: 2.694225 | AP9: 6.65983 | AQ9: 7.117705 | AR9: 6.28898 | AS9: 5.768598
A10: 10 | B10: 2.304832 | C10: 2.182867 | D10: 1.433054 | E10: 1.968463 | F10: 1.082328 | G10: 0.86612 | H10: 0.411066 | I10: 4.893069 | J10: 0.25755239 | K10: 0.913918 | L10: 0.415192 | M10: 1.52801 | N10: 1.877181 | O10: 3.60353 | P10: 7.065145 | Q10: 3.345541 | R10: 2.697721 | S10: 3.071261 | T10: 4.920057 | U10: 5.255719 | V10: 7.385068 | W10: 6.273822 | X10: 3.815278 | Y10: 3.578915 | Z10: 4.356371 | AA10: 6.145925 | AB10: 1.386082 | AC10: 0.470155 | AD10: 8.922027 | AE10: 4.360548 | AF10: 5.03689 | AG10: 4.063052 | AH10: 5.306932 | AI10: 6.037414 | AJ10: 7.821481 | AK10: 6.773922 | AL10: 6.565055 | AM10: 5.713211 | AN10: 5.544128 | AO10: 4.406893 | AP10: 3.044265 | AQ10: 3.230776 | AR10: 3.389113 | AS10: 3.860631
A11: 11 | B11: 2.588122 | C11: 1.968643 | D11: 1.436406 | E11: 1.102562 | F11: 1.649081 | G11: 0.62354 | H11: 1.254436 | I11: 4.000116 | J11: 0.913918 | K11: 0.44499861 | L11: 0.603419 | M11: 1.262756 | N11: 1.115707 | O11: 2.699183 | P11: 6.620775 | Q11: 2.560208 | R11: 2.296884 | S11: 2.892568 | T11: 4.203556 | U11: 4.775437 | V11: 6.800566 | W11: 5.610682 | X11: 3.762366 | Y11: 3.087424 | Z11: 4.097613 | AA11: 5.335735 | AB11: 0.608056 | AC11: 1.24694 | AD11: 8.278334 | AE11: 4.415566 | AF11: 4.925959 | AG11: 4.138843 | AH11: 5.017596 | AI11: 5.781993 | AJ11: 7.136038 | AK11: 5.934267 | AL11: 5.708736 | AM11: 4.806213 | AN11: 4.630216 | AO11: 3.576385 | AP11: 3.339437 | AQ11: 3.644566 | AR11: 3.448733 | AS11: 3.65722
A12: 12 | B12: 2.588945 | C12: 2.267015 | D12: 1.583223 | E12: 1.705133 | F12: 1.436246 | G12: 0.843324 | H12: 0.823868 | I12: 4.50766 | J12: 0.415192 | K12: 0.603419 | L12: 0.2239854 | M12: 1.159711 | N12: 1.466176 | O12: 3.292178 | P12: 6.693131 | Q12: 2.932549 | R12: 2.320759 | S12: 2.756946 | T12: 4.505456 | U12: 4.873074 | V12: 6.985752 | W12: 5.863532 | X12: 3.549616 | Y12: 3.189335 | Z12: 4.026405 | AA12: 5.733584 | AB12: 0.984643 | AC12: 0.645705 | AD12: 8.514966 | AE12: 4.139269 | AF12: 4.756879 | AG12: 3.848484 | AH12: 4.971569 | AI12: 5.713838 | AJ12: 7.409682 | AK12: 6.365895 | AL12: 6.161216 | AM12: 5.341599 | AN12: 5.195983 | AO12: 4.176807 | AP12: 3.340657 | AQ12: 3.566744 | AR12: 3.603049 | AS12: 3.970778
A13: 13 | B13: 3.732644 | C13: 3.231137 | D13: 2.653597 | E13: 2.024143 | F13: 2.59349 | G13: 1.840484 | H13: 1.928108 | I13: 3.952552 | J13: 1.52801 | K13: 1.262756 | L13: 1.159711 | M13: 0.53023737 | N13: 0.965973 | O13: 3.20818 | P13: 5.53827 | Q13: 2.144836 | R13: 1.170044 | S13: 1.637838 | T13: 3.532528 | U13: 3.728665 | V13: 5.87673 | W13: 4.815343 | X13: 2.500071 | Y13: 2.059485 | Z13: 2.879584 | AA13: 4.885098 | AB13: 0.912008 | AC13: 1.435192 | AD13: 7.437993 | AE13: 3.166118 | AF13: 3.667496 | AG13: 2.897133 | AH13: 3.819085 | AI13: 4.568903 | AJ13: 6.371345 | AK13: 5.572672 | AL13: 5.416527 | AM13: 4.854416 | AN13: 4.844616 | AO13: 4.346369 | AP13: 4.487296 | AQ13: 4.725885 | AR13: 4.685002 | AS13: 4.918124
... A44: 115 | B44: 1.219731 | C44: 1.58082 | D44: 2.032725 | E44: 3.360904 | F44: 2.452091 | G44: 2.845224 | H44: 3.160245 | I44: 6.28898 | J44: 3.389113 | K44: 3.448733 | L44: 3.603049 | M44: 4.685002 | N44: 4.42053 | O44: 4.444712 | P44: 9.998808 | Q44: 5.600668 | R44: 5.740852 | S44: 6.322445 | T44: 7.270415 | U44: 8.148406 | V44: 10.024131 | W44: 8.728333 | X44: 7.149587 | Y44: 6.485769 | Z44: 7.546078 | AA44: 8.035522 | AB44: 3.99255 | AC44: 3.797924 | AD44: 11.369506 | AE44: 7.737424 | AF44: 8.345918 | AG44: 7.443322 | AH44: 8.464824 | AI44: 9.230626 | AJ44: 10.15928 | AK44: 8.446829 | AL44: 8.132712 | AM44: 6.769241 | AN44: 6.304644 | AO44: 4.21952 | AP44: 0.897654 | AQ44: 1.376857 | AR44: 0 | AS44: 1.090244
B45: 2.091159 | C45: 1.705355 | D45: 2.42808 | E45: 3.228292 | F45: 3.120863 | G45: 3.136147 | H45: 3.732045 | I45: 5.768598 | J45: 3.860631 | K45: 3.65722 | L45: 3.970778 | M45: 4.918124 | N45: 4.444402 | O45: 3.919923 | P45: 9.921417 | Q45: 5.404171 | R45: 5.849582 | S45: 6.532203 | T45: 7.012445 | U45: 8.089483 | V45: 9.803569 | W45: 8.460893 | X45: 7.418043 | Y45: 6.491826 | Z45: 7.676185 | AA45: 7.588929 | AB45: 4.102432 | AC45: 4.314751 | AD45: 11.045582 | AE45: 8.06918 | AF45: 8.564347 | AG45: 7.788238 | AH45: 8.552252 | AI45: 9.330349 | AJ45: 9.813543 | AK45: 7.918975 | AL45: 7.582956 | AM45: 6.12699 | AN45: 5.60591 | AO45: 3.423156 | AP45: 1.976668 | AQ45: 2.467038 | AR45: 1.090244 | AS45: 0

Sheet generation
A1: idzoning | B1: employeep61 | C1: generation | H1: co-efficient | I1: home-work | J1: home-cshool | K1: home-leisure
A2: 1 | B2: 953 | C2: =$I$2*$I$3*B2 -> 897.80224 | H2: beta1 | I2: 1.024 | J2: 0.84 | K2: 0.47
A3: 2 | B3: 558 | C3: =$I$2*$I$3*B3 -> 525.68064 | H3: beta2 | I3: 0.92 | J3: 0 | K3: 0.58
A4: 3 | B4: 478 | C4: =$I$2*$I$3*B4 -> 450.31424
A5: 5 | B5: 268 | C5: =$I$2*$I$3*B5 -> 252.47744
A6: 6 | B6: 921 | C6: =$I$2*$I$3*B6 -> 867.65568
A7: 7 | B7: 947 | C7: =$I$2*$I$3*B7 -> 892.14976
A8: 8 | B8: 1193 | C8: =$I$2*$I$3*B8 -> 1123.9014
A9: 9 | B9: 468 | C9: =$I$2*$I$3*B9 -> 440.89344
A10: 10 | B10: 787 | C10: =$I$2*$I$3*B10 -> 741.41696
A11: 11 | B11: 47 | C11: =$I$2*$I$3*B11 -> 44.27776
A12: 12 | B12: 341 | C12: =$I$2*$I$3*B12 -> 321.24928
A13: 13 | B13: 480 | C13: =$I$2*$I$3*B13 -> 452.1984
A14: 14 | B14: 453 | C14: =$I$2*$I$3*B14 -> 426.76224
A15: 15 | B15: 538 | C15: =$I$2*$I$3*B15 -> 506.83904
... A29: 29 | B29: 708 | C29: =$I$2*$I$3*B29 -> 666.99264

Sheet distribution
A1: idzoning | B1: totalworker | G1: co-efficient | H1: home-work | I1: home-school | J1: home-leisure
A2: 1 | B2: 1782 | G2: beta1 | H2: 0.0009 | I2: 1.1 | J2: 0.0026395
A3: 2 | B3: 391 | G3: beta2 | H3: -0.7 | I3: 0 | J3: -0.1
A4: 3 | B4: 152
A5: 5 | B5: 1
A6: 6 | B6: 44 | G6: 1782 | H6: 391 | I6: 152 | J6: 1 | K6: 44 | L6: 603 | M6: 382 | N6: 458 | O6: 139 | P6: 667 | Q6: 57 | R6: 361 | S6: 2344 | T6: 588 | U6: 1753 | V6: 130 | W6: 6 | X6: 1093 | Y6: 2242 | Z6: 788 | AA6: 849 | AB6: 270 | AC6: 810 | AD6: 87 | AE6: 1082 | AF6: 116 | AG6: 1198 | AH6: 209
A7: 7 | B7: 603 | G7: 1 | H7: 2 | I7: 3 | J7: 5 | K7: 6 | L7: 7 | M7: 8 | N7: 9 | O7: 10 | P7: 11 | Q7: 12 | R7: 13 | S7: 14 | T7: 15 | U7: 16 | V7: 17 | W7: 18 | X7: 19 | Y7: 20 | Z7: 21 | AA7: 22 | AB7: 23 | AC7: 24 | AD7: 25 | AE7: 26 | AF7: 27 | AG7: 28 | AH7: 29
A8: 8 | B8: 382 | F8: 1 | G8: =($H$2*G$6)+($H$3*distancematrix!B2) -> 1.1265263 | H8: =($H$2*H$6)+($H$3*distancematrix!C2) -> -0.5472738 | I8: =($H$2*I$6)+($H$3*distancematrix!D2) -> -0.6981754 | J8: =($H$2*J$6)+($H$3*distancematrix!E2) -> -2.003165 | K8: =($H$2*K$6)+($H$3*distancematrix!F2) -> -0.855336 | L8: =($H$2*L$6)+($H$3*distancematrix!G2) -> -0.8335413 | M8: =($H$2*M$6)+($H$3*distancematrix!H2) -> -1.0679999 | N8: =($H$2*N$6)+($H$3*distancematrix!I2) -> -3.8141606 | ... AH8: =($H$2*AH$6)+($H$3*distancematrix!AC2) -> -1.6795966
A9: 9 | B9: 458 | F9: 2 | G9: =($H$2*G$6)+($H$3*distancematrix!B3) -> 0.7046262 | H9: =($H$2*H$6)+($H$3*distancematrix!C3) -> -0.014095458 | I9: =($H$2*I$6)+($H$3*distancematrix!D3) -> -0.4108394 | J9: =($H$2*J$6)+($H$3*distancematrix!E3) -> -1.248572 | K9: =($H$2*K$6)+($H$3*distancematrix!F3) -> -1.1100723 | L9: =($H$2*L$6)+($H$3*distancematrix!G3) -> -0.4588572 | M9: =($H$2*M$6)+($H$3*distancematrix!H3) -> -1.1354722 | N9: =($H$2*N$6)+($H$3*distancematrix!I3) -> -2.9706613 | ... AH9: =($H$2*AH$6)+($H$3*distancematrix!AC3) -> -1.665017
A10: 10 | B10: 139 | F10: 3 | G10: =($H$2*G$6)+($H$3*distancematrix!B4) -> 0.7688246 | H10: =($H$2*H$6)+($H$3*distancematrix!C4) -> -0.1957394 | I10: =($H$2*I$6)+($H$3*distancematrix!D4) -> -0.31650861 | J10: =($H$2*J$6)+($H$3*distancematrix!E4) -> -1.1964752 | K10: =($H$2*K$6)+($H$3*distancematrix!F4) -> -0.5985718 | L10: =($H$2*L$6)+($H$3*distancematrix!G4) -> -0.0302374 | M10: =($H$2*M$6)+($H$3*distancematrix!H4) -> -0.5886721 | N10: =($H$2*N$6)+($H$3*distancematrix!I4) -> -3.0327786 | ... AH10: =($H$2*AH$6)+($H$3*distancematrix!AC4) -> -1.1331598
A11: 11 | B11: 667 | F11: 5 | G11: =($H$2*G$6)+($H$3*distancematrix!B5) -> -0.400265 | H11: =($H$2*H$6)+($H$3*distancematrix!C5) -> -0.897572 | I11: =($H$2*I$6)+($H$3*distancematrix!D5) -> -1.0605752 | J11: =($H$2*J$6)+($H$3*distancematrix!E5) -> -0.58077099 | K11: =($H$2*K$6)+($H$3*distancematrix!F5) -> -1.6154926 | L11: =($H$2*L$6)+($H$3*distancematrix!G5) -> -0.3399762 | M11: =($H$2*M$6)+($H$3*distancematrix!H5) -> -1.2188429 | N11: =($H$2*N$6)+($H$3*distancematrix!I5) -> -1.838839 | ... AH11: =($H$2*AH$6)+($H$3*distancematrix!AC5) -> -1.4532425
A12: 12 | B12: 57 | F12: 6 | G12: =($H$2*G$6)+($H$3*distancematrix!B6) -> 0.708864 | H12: =($H$2*H$6)+($H$3*distancematrix!C6) -> -0.7977723 | I12: =($H$2*I$6)+($H$3*distancematrix!D6) -> -0.5013718 | J12: =($H$2*J$6)+($H$3*distancematrix!E6) -> -1.6541926 | K12: =($H$2*K$6)+($H$3*distancematrix!F6) -> -0.33921068 | L12: =($H$2*L$6)+($H$3*distancematrix!G6) -> -0.2514472 | M12: =($H$2*M$6)+($H$3*distancematrix!H6) -> -0.1780941 | N12: =($H$2*N$6)+($H$3*distancematrix!I6) -> -3.4701463 | ... AH12: =($H$2*AH$6)+($H$3*distancematrix!AC6) -> -0.79015
A13: 13 | B13: 361 | F13: 7 | G13: =($H$2*G$6)+($H$3*distancematrix!B7) -> 0.2275587 | H13: =($H$2*H$6)+($H$3*distancematrix!C7) -> -0.6496572 | I13: =($H$2*I$6)+($H$3*distancematrix!D7) -> -0.4361374 | J13: =($H$2*J$6)+($H$3*distancematrix!E7) -> -0.8817762 | K13: =($H$2*K$6)+($H$3*distancematrix!F7) -> -0.7545472 | L13: =($H$2*L$6)+($H$3*distancematrix!G7) -> 0.26046593 | M13: =($H$2*M$6)+($H$3*distancematrix!H7) -> -0.3641373 | N13: =($H$2*N$6)+($H$3*distancematrix!I7) -> -2.676844 | ... AH13: =($H$2*AH$6)+($H$3*distancematrix!AC7) -> -0.7412585
A14: 14 | B14: 2344 | F14: 8 | G14: =($H$2*G$6)+($H$3*distancematrix!B8) -> 0.1920001 | H14: =($H$2*H$6)+($H$3*distancematrix!C8) -> -1.1273722 | I14: =($H$2*I$6)+($H$3*distancematrix!D8) -> -0.7956721 | J14: =($H$2*J$6)+($H$3*distancematrix!E8) -> -1.5617429 | K14: =($H$2*K$6)+($H$3*distancematrix!F8) -> -0.4822941 | L14: =($H$2*L$6)+($H$3*distancematrix!G8) -> -0.1652373 | M14: =($H$2*M$6)+($H$3*distancematrix!H8) -> 0.13548881 | N14: =($H$2*N$6)+($H$3*distancematrix!I8) -> -3.2658212 | ... AH14: =($H$2*AH$6)+($H$3*distancematrix!AC8) -> -0.2685128
A15: 15 | B15: 588 | F15: 9 | G15: =($H$2*G$6)+($H$3*distancematrix!B9) -> -2.6225606 | H15: =($H$2*H$6)+($H$3*distancematrix!C9) -> -3.0309613 | I15: =($H$2*I$6)+($H$3*distancematrix!D9) -> -3.3081786 | J15: =($H$2*J$6)+($H$3*distancematrix!E9) -> -2.250139 | K15: =($H$2*K$6)+($H$3*distancematrix!F9) -> -3.8427463 | L15: =($H$2*L$6)+($H$3*distancematrix!G9) -> -2.546344 | M15: =($H$2*M$6)+($H$3*distancematrix!H9) -> -3.3342212 | N15: =($H$2*N$6)+($H$3*distancematrix!I9) -> -0.26164698 | ... AH15: =($H$2*AH$6)+($H$3*distancematrix!AC9) -> -3.3854077
A16: 16 | B16: 1753 | F16: 10 | G16: =($H$2*G$6)+($H$3*distancematrix!B10) -> -0.0095824 | H16: =($H$2*H$6)+($H$3*distancematrix!C10) -> -1.1761069 | I16: =($H$2*I$6)+($H$3*distancematrix!D10) -> -0.8663378 | J16: =($H$2*J$6)+($H$3*distancematrix!E10) -> -1.3770241 | K16: =($H$2*K$6)+($H$3*distancematrix!F10) -> -0.7180296 | L16: =($H$2*L$6)+($H$3*distancematrix!G10) -> -0.063584 | M16: =($H$2*M$6)+($H$3*distancematrix!H10) -> 0.0560538 | N16: =($H$2*N$6)+($H$3*distancematrix!I10) -> -3.0129483 | ... AH16: =($H$2*AH$6)+($H$3*distancematrix!AC10) -> -0.1410085
A17: 17 | B17: 130 | F17: 11 | G17: =($H$2*G$6)+($H$3*distancematrix!B11) -> -0.2078854 | H17: =($H$2*H$6)+($H$3*distancematrix!C11) -> -1.0261501 | I17: =($H$2*I$6)+($H$3*distancematrix!D11) -> -0.8686842 | J17: =($H$2*J$6)+($H$3*distancematrix!E11) -> -0.7708934 | K17: =($H$2*K$6)+($H$3*distancematrix!F11) -> -1.1147567 | L17: =($H$2*L$6)+($H$3*distancematrix!G11) -> 0.106222 | M17: =($H$2*M$6)+($H$3*distancematrix!H11) -> -0.5343052 | N17: =($H$2*N$6)+($H$3*distancematrix!I11) -> -2.3878812 | ... AH17: =($H$2*AH$6)+($H$3*distancematrix!AC11) -> -0.684758
A18: 18 | B18: 6 | F18: 12 | G18: =($H$2*G$6)+($H$3*distancematrix!B12) -> -0.2084615 | H18: =($H$2*H$6)+($H$3*distancematrix!C12) -> -1.2350105 | I18: =($H$2*I$6)+($H$3*distancematrix!D12) -> -0.9714561 | J18: =($H$2*J$6)+($H$3*distancematrix!E12) -> -1.1926931 | K18: =($H$2*K$6)+($H$3*distancematrix!F12) -> -0.9657722 | L18: =($H$2*L$6)+($H$3*distancematrix!G12) -> -0.0476268 | M18: =($H$2*M$6)+($H$3*distancematrix!H12) -> -0.2329076 | N18: =($H$2*N$6)+($H$3*distancematrix!I12) -> -2.743162 | ... AH18: =($H$2*AH$6)+($H$3*distancematrix!AC12) -> -0.2638935
A19: 19 | B19: 1093 | F19: 13 | G19: =($H$2*G$6)+($H$3*distancematrix!B13) -> -1.0090508 | H19: =($H$2*H$6)+($H$3*distancematrix!C13) -> -1.9098959 | I19: =($H$2*I$6)+($H$3*distancematrix!D13) -> -1.7207179 | J19: =($H$2*J$6)+($H$3*distancematrix!E13) -> -1.4160001 | K19: =($H$2*K$6)+($H$3*distancematrix!F13) -> -1.775843 | L19: =($H$2*L$6)+($H$3*distancematrix!G13) -> -0.7456388 | M19: =($H$2*M$6)+($H$3*distancematrix!H13) -> -1.0058756 | N19: =($H$2*N$6)+($H$3*distancematrix!I13) -> -2.3545864 | ... AH19: =($H$2*AH$6)+($H$3*distancematrix!AC13) -> -0.8165344
... A29: 29 | B29: 209 | F29: 23 | G29: =($H$2*G$6)+($H$3*distancematrix!B23) -> -4.0907336 | H29: =($H$2*H$6)+($H$3*distancematrix!C23) -> -4.655767 | I29: =($H$2*I$6)+($H$3*distancematrix!D23) -> -4.7228114 | J29: =($H$2*J$6)+($H$3*distancematrix!E23) -> -3.7573657 | K29: =($H$2*K$6)+($H$3*distancematrix!F23) -> -5.0315962 | L29: =($H$2*L$6)+($H$3*distancematrix!G23) -> -3.8001875 | M29: =($H$2*M$6)+($H$3*distancematrix!H23) -> -4.3356202 | N29: =($H$2*N$6)+($H$3*distancematrix!I23) -> -1.782356 | ... AH29: =($H$2*AH$6)+($H$3*distancematrix!AC23) -> -4.1868132
F30: 24 | G30: =($H$2*G$6)+($H$3*distancematrix!B24) -> -2.6791626 | H30: =($H$2*H$6)+($H$3*distancematrix!C24) -> -3.6587577 | I30: =($H$2*I$6)+($H$3*distancematrix!D24) -> -3.4470537 | J30: =($H$2*J$6)+($H$3*distancematrix!E24) -> -3.0796292 | K30: =($H$2*K$6)+($H$3*distancematrix!F24) -> -3.3780436 | L30: =($H$2*L$6)+($H$3*distancematrix!G24) -> -2.4826979 | M30: =($H$2*M$6)+($H$3*distancematrix!H24) -> -2.5559969 | N30: =($H$2*N$6)+($H$3*distancematrix!I24) -> -3.0829007 | ... AH30: =($H$2*AH$6)+($H$3*distancematrix!AC24) -> -2.2639552
F31: 25 | G31: =($H$2*G$6)+($H$3*distancematrix!B25) -> -2.3682359 | H31: =($H$2*H$6)+($H$3*distancematrix!C25) -> -3.0978491 | I31: =($H$2*I$6)+($H$3*distancematrix!D25) -> -3.0249635 | J31: =($H$2*J$6)+($H$3*distancematrix!E25) -> -2.2881007 | K31: =($H$2*K$6)+($H$3*distancematrix!F25) -> -3.1952288 | L31: =($H$2*L$6)+($H$3*distancematrix!G25) -> -2.0549125 | M31: =($H$2*M$6)+($H$3*distancematrix!H25) -> -2.4450007 | N31: =($H$2*N$6)+($H$3*distancematrix!I25) -> -1.7908288 | ... AH31: =($H$2*AH$6)+($H$3*distancematrix!AC25) -> -2.2493602
F32: 26 | G32: =($H$2*G$6)+($H$3*distancematrix!B26) -> -3.023921 | H32: =($H$2*H$6)+($H$3*distancematrix!C26) -> -3.876513 | I32: =($H$2*I$6)+($H$3*distancematrix!D26) -> -3.729076 | J32: =($H$2*J$6)+($H$3*distancematrix!E26) -> -3.1537053 | K32: =($H$2*K$6)+($H$3*distancematrix!F26) -> -3.7673584 | L32: =($H$2*L$6)+($H$3*distancematrix!G26) -> -2.7505655 | M32: =($H$2*M$6)+($H$3*distancematrix!H26) -> -2.9647045 | N32: =($H$2*N$6)+($H$3*distancematrix!I26) -> -2.6746677 | ... AH32: =($H$2*AH$6)+($H$3*distancematrix!AC26) -> -2.699302
F33: 27 | G33: =($H$2*G$6)+($H$3*distancematrix!B27) -> -3.7515101 | H33: =($H$2*H$6)+($H$3*distancematrix!C27) -> -4.2113335 | I33: =($H$2*I$6)+($H$3*distancematrix!D27) -> -4.4007008 | J33: =($H$2*J$6)+($H$3*distancematrix!E27) -> -3.3506405 | K33: =($H$2*K$6)+($H$3*distancematrix!F27) -> -4.8411864 | L33: =($H$2*L$6)+($H$3*distancematrix!G27) -> -3.5547878 | M33: =($H$2*M$6)+($H$3*distancematrix!H27) -> -4.2366409 | N33: =($H$2*N$6)+($H$3*distancematrix!I27) -> -0.8908458 | ... AH33: =($H$2*AH$6)+($H$3*distancematrix!AC27) -> -4.1828946
F34: 28 | G34: =($H$2*G$6)+($H$3*distancematrix!B28) -> -0.6258323 | H34: =($H$2*H$6)+($H$3*distancematrix!C28) -> -1.3702337 | I34: =($H$2*I$6)+($H$3*distancematrix!D28) -> -1.2736468 | J34: =($H$2*J$6)+($H$3*distancematrix!E28) -> -0.7783911 | K34: =($H$2*K$6)+($H$3*distancematrix!F28) -> -1.5334435 | L34: =($H$2*L$6)+($H$3*distancematrix!G28) -> -0.3114883 | M34: =($H$2*M$6)+($H$3*distancematrix!H28) -> -0.8991942 | N34: =($H$2*N$6)+($H$3*distancematrix!I28) -> -2.0575183 | ... AH34: =($H$2*AH$6)+($H$3*distancematrix!AC28) -> -0.9183662
F35: 29 | G35: =($H$2*G$6)+($H$3*distancematrix!B29) -> -0.2638966 | H35: =($H$2*H$6)+($H$3*distancematrix!C29) -> -1.501217 | I35: =($H$2*I$6)+($H$3*distancematrix!D29) -> -1.1844598 | J35: =($H$2*J$6)+($H$3*distancematrix!E29) -> -1.6404425 | K35: =($H$2*K$6)+($H$3*distancematrix!F29) -> -0.93865 | L35: =($H$2*L$6)+($H$3*distancematrix!G29) -> -0.3866585 | M35: =($H$2*M$6)+($H$3*distancematrix!H29) -> -0.1128128 | N35: =($H$2*N$6)+($H$3*distancematrix!I29) -> -3.1613077 | ... AH35: =($H$2*AH$6)+($H$3*distancematrix!AC29) -> -0.02955164
O39: exp
G40: 1 | H40: 2 | I40: 3 | J40: 5 | K40: 6 | L40: 7 | M40: 8 | N40: 9 | O40: 10 | P40: 11 | Q40: 12 | R40: 13 | S40: 14 | T40: 15 | U40: 16 | V40: 17 | W40: 18 | X40: 19 | Y40: 20 | Z40: 21 | AA40: 22 | AB40: 23 | AC40: 24 | AD40: 25 | AE40: 26 | AF40: 27 | AG40: 28 | AH40: 29
F41: 1 | G41: =EXP(G8) -> 3.0849218 | H41: =EXP(H8) -> 0.57852484 | I41: =EXP(I8) -> 0.4974922 | J41: =EXP(J8) -> 0.13490762 | K41: =EXP(K8) -> 0.42514032 | L41: =EXP(L8) -> 0.43450784 | M41: =EXP(M8) -> 0.34369526 | N41: =EXP(N8) -> 0.022056221 | ... AH41: =EXP(AH8) -> 0.18644917 | AI41: =SUM(G41:AH41) -> 7.8438009
F42: 2 | G42: =EXP(G9) -> 2.0230903 | H42: =EXP(H9) -> 0.98600342 | I42: =EXP(I9) -> 0.66309342 | J42: =EXP(J9) -> 0.28691422 | K42: =EXP(K9) -> 0.32953513 | L42: =EXP(L9) -> 0.63200549 | M42: =EXP(M9) -> 0.32127038 | N42: =EXP(N9) -> 0.051269395 | ... AH42: =EXP(AH9) -> 0.18918744 | AI42: =SUM(G42:AH42) -> 8.9072319
F43: 3 | G43: =EXP(G10) -> 2.1572292 | H43: =EXP(H10) -> 0.82222648 | I43: =EXP(I10) -> 0.72868874 | J43: =EXP(J10) -> 0.30225773 | K43: =EXP(K10) -> 0.54959601 | L43: =EXP(L10) -> 0.97021518 | M43: =EXP(M10) -> 0.55506386 | N43: =EXP(N10) -> 0.048181575 | ... AH43: =EXP(AH10) -> 0.32201415 | AI43: =SUM(G43:AH43) -> 11.114482
F44: 5 | G44: =EXP(G11) -> 0.67014243 | H44: =EXP(H11) -> 0.40755801 | I44: =EXP(I11) -> 0.34625659 | J44: =EXP(J11) -> 0.55946686 | K44: =EXP(K11) -> 0.19879272 | L44: =EXP(L11) -> 0.71178726 | M44: =EXP(M11) -> 0.29557198 | N44: =EXP(N11) -> 0.15900192 | ... AH44: =EXP(AH11) -> 0.23381093 | AI44: =SUM(G44:AH44) -> 12.250122
F45: 6 | G45: =EXP(G12) -> 2.031682 | H45: =EXP(H12) -> 0.45033105 | I45: =EXP(I12) -> 0.60569919 | J45: =EXP(J12) -> 0.19124641 | K45: =EXP(K12) -> 0.71233236 | L45: =EXP(L12) -> 0.77767452 | M45: =EXP(M12) -> 0.83686367 | N45: =EXP(N12) -> 0.031112479 | ... AH45: =EXP(AH12) -> 0.45377672 | AI45: =SUM(G45:AH45) -> 10.349965
F46: 7 | G46: =EXP(G13) -> 1.2555311 | H46: =EXP(H13) -> 0.52222476 | I46: =EXP(I13) -> 0.64652889 | J46: =EXP(J13) -> 0.41404683 | K46: =EXP(K13) -> 0.47022348 | L46: =EXP(L13) -> 1.2975345 | M46: =EXP(M13) -> 0.69479579 | N46: =EXP(N13) -> 0.068779881 | ... AH46: =EXP(AH13) -> 0.47651385 | AI46: =SUM(G46:AH46) -> 13.721523
F47: 8 | G47: =EXP(G14) -> 1.2116706 | H47: =EXP(H14) -> 0.32388324 | I47: =EXP(I14) -> 0.45127783 | J47: =EXP(J14) -> 0.20977014 | K47: =EXP(K14) -> 0.61736547 | L47: =EXP(L14) -> 0.84769252 | M47: =EXP(M14) -> 1.1450964 | N47: =EXP(N14) -> 0.038165581 | ... AH47: =EXP(AH14) -> 0.76451564 | AI47: =SUM(G47:AH47) -> 11.796535
F48: 9 | G48: =EXP(G15) -> 0.072616682 | H48: =EXP(H15) -> 0.048269215 | I48: =EXP(I15) -> 0.036582745 | J48: =EXP(J15) -> 0.10538458 | K48: =EXP(K15) -> 0.021434654 | L48: =EXP(L15) -> 0.078367655 | M48: =EXP(M15) -> 0.035642334 | N48: =EXP(N15) -> 0.76978272 | ... AH48: =EXP(AH15) -> 0.033863833 | AI48: =SUM(G48:AH48) -> 6.6017892
F49: 10 | G49: =EXP(G16) -> 0.99046336 | H49: =EXP(H16) -> 0.30847734 | I49: =EXP(I16) -> 0.42048865 | J49: =EXP(J16) -> 0.25232834 | K49: =EXP(K16) -> 0.4877123 | L49: =EXP(L16) -> 0.93839529 | M49: =EXP(M16) -> 1.0576546 | N49: =EXP(N16) -> 0.049146566 | ... AH49: =EXP(AH16) -> 0.86848193 | AI49: =SUM(G49:AH49) -> 13.306769
F50: 11 | G50: =EXP(G17) -> 0.81230012 | H50: =EXP(H17) -> 0.35838405 | I50: =EXP(I17) -> 0.41950317 | J50: =EXP(J17) -> 0.4625996 | K50: =EXP(K17) -> 0.32799507 | L50: =EXP(L17) -> 1.1120687 | M50: =EXP(M17) -> 0.58607635 | N50: =EXP(N17) -> 0.091824035 | ... AH50: =EXP(AH17) -> 0.50421223 | AI50: =SUM(G50:AH50) -> 15.573166
F51: 12 | G51: =EXP(G18) -> 0.81183229 | H51: =EXP(H18) -> 0.29083171 | I51: =EXP(I18) -> 0.37853146 | J51: =EXP(J18) -> 0.30340307 | K51: =EXP(K18) -> 0.38068912 | L51: =EXP(L18) -> 0.95348956 | M51: =EXP(M18) -> 0.79222677 | N51: =EXP(N18) -> 0.064366498 | ... AH51: =EXP(AH18) -> 0.76805533 | AI51: =SUM(G51:AH51) -> 14.566782
F52: 13 | G52: =EXP(G19) -> 0.36456486 | H52: =EXP(H19) -> 0.1480958 | I52: =EXP(I19) -> 0.17893764 | J52: =EXP(J19) -> 0.24268278 | K52: =EXP(K19) -> 0.16934064 | L52: =EXP(L19) -> 0.47443114 | M52: =EXP(M19) -> 0.36572427 | N52: =EXP(N19) -> 0.094932763 | ... AH52: =EXP(AH19) -> 0.44196066 | AI52: =SUM(G52:AH52) -> 14.481694
...

Sheet ODmatrix
A1: idzoning | B1: totalworker
A2: 1 | B2: 1782
A3: 2 | B3: 391 | G3: 1 | H3: 2 | I3: 3 | J3: 5 | K3: 6 | L3: 7 | M3: 8 | N3: 9 | O3: 10 | P3: 11 | Q3: 12 | R3: 13 | S3: 14 | T3: 15 | U3: 16 | V3: 17 | W3: 18 | X3: 19 | Y3: 20 | Z3: 21 | AA3: 22 | AB3: 23 | AC3: 24 | AD3: 25 | AE3: 26 | AF3: 27 | AG3: 28 | AH3: 29
A4: 3 | B4: 152 | F4: 1 | G4: =generation!$C2*distribution!G73 -> 353.10046 | H4: =generation!$C2*distribution!H73 -> 66.218011 | I4: =generation!$C2*distribution!I73 -> 56.943008 | J4: =generation!$C2*distribution!J73 -> 15.44154 | K4: =generation!$C2*distribution!K73 -> 48.661604 | L4: =generation!$C2*distribution!L73 -> 49.733811 | M4: =generation!$C2*distribution!M73 -> 39.339394 | N4: =generation!$C2*distribution!N73 -> 2.5245573 | ... AH4: =generation!$C2*distribution!AH73 -> 21.340991 | AI4: =SUM(G4:AH4) -> 897.80224
A5: 5 | B5: 1 | F5: 2 | G5: =generation!$C3*distribution!G74 -> 119.3973 | H5: =generation!$C3*distribution!H74 -> 58.191244 | I5: =generation!$C3*distribution!I74 -> 39.133973 | J5: =generation!$C3*distribution!J74 -> 16.932898 | K5: =generation!$C3*distribution!K74 -> 19.448269 | L5: =generation!$C3*distribution!L74 -> 37.299248 | M5: =generation!$C3*distribution!M74 -> 18.960506 | N5: =generation!$C3*distribution!N74 -> 3.0257805 | ... AH5: =generation!$C3*distribution!AH74 -> 11.165329 | AI5: =SUM(G5:AH5) -> 525.68064
A6: 6 | B6: 44 | F6: 3 | G6: =generation!$C4*distribution!G75 -> 87.402272 | H6: =generation!$C4*distribution!H75 -> 33.313319 | I6: =generation!$C4*distribution!I75 -> 29.523545 | J6: =generation!$C4*distribution!J75 -> 12.246271 | K6: =generation!$C4*distribution!K75 -> 22.267426 | L6: =generation!$C4*distribution!L75 -> 39.309227 | M6: =generation!$C4*distribution!M75 -> 22.488961 | N6: =generation!$C4*distribution!N75 -> 1.9521241 | ... AH6: =generation!$C4*distribution!AH75 -> 13.046722 | AI6: =SUM(G6:AH6) -> 450.31424
A7: 7 | B7: 603 | F7: 5 | G7: =generation!$C5*distribution!G76 -> 13.811768 | H7: =generation!$C5*distribution!H76 -> 8.3998513 | I7: =generation!$C5*distribution!I76 -> 7.1364168 | J7: =generation!$C5*distribution!J76 -> 11.530723 | K7: =generation!$C5*distribution!K76 -> 4.0971573 | L7: =generation!$C5*distribution!L76 -> 14.670076 | M7: =generation!$C5*distribution!M76 -> 6.0917969 | N7: =generation!$C5*distribution!N76 -> 3.277061 | ... AH7: =generation!$C5*distribution!AH76 -> 4.8188895 | AI7: =SUM(G7:AH7) -> 252.47744
A8: 8 | B8: 382 | F8: 6 | G8: =generation!$C6*distribution!G77 -> 170.31945 | H8: =generation!$C6*distribution!H77 -> 37.75204 | I8: =generation!$C6*distribution!I77 -> 50.776823 | J8: =generation!$C6*distribution!J77 -> 16.032521 | K8: =generation!$C6*distribution!K77 -> 59.716068 | L8: =generation!$C6*distribution!L77 -> 65.193815 | M8: =generation!$C6*distribution!M77 -> 70.155746 | N8: =generation!$C6*distribution!N77 -> 2.6082135 | ... AH8: =generation!$C6*distribution!AH77 -> 38.040897 | AI8: =SUM(G8:AH8) -> 867.65568
A9: 9 | B9: 458 | F9: 7 | G9: =generation!$C7*distribution!G78 -> 81.632469 | H9: =generation!$C7*distribution!H78 -> 33.954154 | I9: =generation!$C7*distribution!I78 -> 42.036193 | J9: =generation!$C7*distribution!J78 -> 26.920611 | K9: =generation!$C7*distribution!K78 -> 30.57312 | L9: =generation!$C7*distribution!L78 -> 84.363456 | M9: =generation!$C7*distribution!M78 -> 45.174424 | N9: =generation!$C7*distribution!N78 -> 4.4719493 | ... AH9: =generation!$C7*distribution!AH78 -> 30.982108 | AI9: =SUM(G9:AH9) -> 892.14976
A10: 10 | B10: 139 | F10: 8 | G10: =generation!$C8*distribution!G79 -> 115.44054 | H10: =generation!$C8*distribution!H79 -> 30.857607 | I10: =generation!$C8*distribution!I79 -> 42.994981 | J10: =generation!$C8*distribution!J79 -> 19.985611 | K10: =generation!$C8*distribution!K79 -> 58.818791 | L10: =generation!$C8*distribution!L79 -> 80.762939 | M10: =generation!$C8*distribution!M79 -> 109.09775 | N10: =generation!$C8*distribution!N79 -> 3.6361822 | ... AH10: =generation!$C8*distribution!AH79 -> 72.838356 | AI10: =SUM(G10:AH10) -> 1123.9014
A11: 11 | B11: 667 | F11: 9 | G11: =generation!$C9*distribution!G80 -> 4.8496275 | H11: =generation!$C9*distribution!H80 -> 3.2236079 | I11: =generation!$C9*distribution!I80 -> 2.4431395 | J11: =generation!$C9*distribution!J80 -> 7.0379963 | K11: =generation!$C9*distribution!K80 -> 1.4314905 | L11: =generation!$C9*distribution!L80 -> 5.2337001 | M11: =generation!$C9*distribution!M80 -> 2.3803352 | N11: =generation!$C9*distribution!N80 -> 51.409117 | ... AH11: =generation!$C9*distribution!AH80 -> 2.2615599 | AI11: =SUM(G11:AH11) -> 440.89344
A12: 12 | B12: 57 | F12: 10 | G12: =generation!$C10*distribution!G81 -> 55.185922 | H12: =generation!$C10*distribution!H81 -> 17.187517 | I12: =generation!$C10*distribution!I81 -> 23.428482 | J12: =generation!$C10*distribution!J81 -> 14.059048 | K12: =generation!$C10*distribution!K81 -> 27.174001 | L12: =generation!$C10*distribution!L81 -> 52.28483 | M12: =generation!$C10*distribution!M81 -> 58.929633 | N12: =generation!$C10*distribution!N81 -> 2.7383128 | ... AH12: =generation!$C10*distribution!AH81 -> 48.389448 | AI12: =SUM(G12:AH12) -> 741.41696
A13: 13 | B13: 361 | F13: 11 | G13: =generation!$C11*distribution!G82 -> 2.3095387 | H13: =generation!$C11*distribution!H82 -> 1.0189606 | I13: =generation!$C11*distribution!I82 -> 1.192735 | J13: =generation!$C11*distribution!J82 -> 1.3152671 | K13: =generation!$C11*distribution!K82 -> 0.93255839 | L13: =generation!$C11*distribution!L82 -> 3.1618433 | M13: =generation!$C11*distribution!M82 -> 1.6663373 | N13: =generation!$C11*distribution!N82 -> 0.26107488 | ... AH13: =generation!$C11*distribution!AH82 -> 1.4335805 | AI13: =SUM(G13:AH13) -> 44.27776
A14: 14 | B14: 2344 | F14: 12 | G14: =generation!$C12*distribution!G83 -> 17.903786 | H14: =generation!$C12*distribution!H83 -> 6.4138723 | I14: =generation!$C12*distribution!I83 -> 8.3479633 | J14: =generation!$C12*distribution!J83 -> 6.6911155 | K14: =generation!$C12*distribution!K83 -> 8.3955474 | L14: =generation!$C12*distribution!L83 -> 21.027832 | M14: =generation!$C12*distribution!M83 -> 17.471415 | N14: =generation!$C12*distribution!N83 -> 1.4195099 | ... AH14: =generation!$C12*distribution!AH83 -> 16.938349 | AI14: =SUM(G14:AH14) -> 321.24928
A15: 15 | B15: 588 | F15: 13 | G15: =generation!$C13*distribution!G84 -> 11.383726 | H15: =generation!$C13*distribution!H84 -> 4.624368 | I15: =generation!$C13*distribution!I84 -> 5.5874205 | J15: =generation!$C13*distribution!J84 -> 7.5778955 | K15: =generation!$C13*distribution!K84 -> 5.2877489 | L15: =generation!$C13*distribution!L84 -> 14.814358 | M15: =generation!$C13*distribution!M84 -> 11.419929 | N15: =generation!$C13*distribution!N84 -> 2.9643246 | ... AH15: =generation!$C13*distribution!AH84 -> 13.80045 | AI15: =SUM(G15:AH15) -> 452.1984
... A29: 29 | B29: 209 | F29: 27 | G29: =generation!$C27*distribution!G98 -> 8.2599936 | H29: =generation!$C27*distribution!H98 -> 5.2153198 | I29: =generation!$C27*distribution!I98 -> 4.315586 | J29: =generation!$C27*distribution!J98 -> 12.333183 | K29: =generation!$C27*distribution!K98 -> 2.7780452 | L29: =generation!$C27*distribution!L98 -> 10.055765 | M29: =generation!$C27*distribution!M98 -> 5.0849898 | N29: =generation!$C27*distribution!N98 -> 144.32795 | ... AH29: =generation!$C27*distribution!AH98 -> 5.3657669 | AI29: =SUM(G29:AH29) -> 2296.791
F30: 28 | G30: =generation!$C28*distribution!G99 -> 23.232717 | H30: =generation!$C28*distribution!H99 -> 11.035972 | I30: =generation!$C28*distribution!I99 -> 12.155077 | J30: =generation!$C28*distribution!J99 -> 19.945483 | K30: =generation!$C28*distribution!K99 -> 9.3740973 | L30: =generation!$C28*distribution!L99 -> 31.813969 | M30: =generation!$C28*distribution!M99 -> 17.675855 | N30: =generation!$C28*distribution!N99 -> 5.5504304 | ... AH30: =generation!$C28*distribution!AH99 -> 17.340201 | AI30: =SUM(G30:AH30) -> 725.4016
F31: 29 | G31: =generation!$C29*distribution!G100 -> 43.642378 | H31: =generation!$C29*distribution!H100 -> 12.663303 | I31: =generation!$C29*distribution!I100 -> 17.382526 | J31: =generation!$C29*distribution!J100 -> 11.017476 | K31: =generation!$C29*distribution!K100 -> 22.226277 | L31: =generation!$C29*distribution!L100 -> 38.600559 | M31: =generation!$C29*distribution!M100 -> 50.760193 | N31: =generation!$C29*distribution!N100 -> 2.4075691 | ... AH31: =generation!$C29*distribution!AH100 -> 55.167478 | AI31: =SUM(G31:AH31) -> 666.99264
G34: 1 | H34: 2 | I34: 3 | J34: 5 | K34: 6 | L34: 7 | M34: 8 | N34: 9 | O34: 10 | P34: 11 | Q34: 12 | R34: 13 | S34: 14 | T34: 15 | U34: 16 | V34: 17 | W34: 18 | X34: 19 | Y34: 20 | Z34: 21 | AA34: 22 | AB34: 23 | AC34: 24 | AD34: 25 | AE34: 26 | AF34: 27 | AG34: 28 | AH34: 29
F35: 1 | G35: =ROUND(G4,0) -> 353 | H35: =ROUND(H4,0) -> 66 | I35: =ROUND(I4,0) -> 57 | J35: =ROUND(J4,0) -> 15 | K35: =ROUND(K4,0) -> 49 | L35: =ROUND(L4,0) -> 50 | M35: =ROUND(M4,0) -> 39 | N35: =ROUND(N4,0) -> 3 | ... AH35: =ROUND(AH4,0) -> 21 | AI35: =SUM(G35:AH35) -> 897
F36: 2 | G36: =ROUND(G5,0) -> 119 | H36: =ROUND(H5,0) -> 58 | I36: =ROUND(I5,0) -> 39 | J36: =ROUND(J5,0) -> 17 | K36: =ROUND(K5,0) -> 19 | L36: =ROUND(L5,0) -> 37 | M36: =ROUND(M5,0) -> 19 | N36: =ROUND(N5,0) -> 3 | ... AH36: =ROUND(AH5,0) -> 11 | AI36: =SUM(G36:AH36) -> 525
F37: 3 | G37: =ROUND(G6,0) -> 87 | H37: =ROUND(H6,0) -> 33 | I37: =ROUND(I6,0) -> 30 | J37: =ROUND(J6,0) -> 12 | K37: =ROUND(K6,0) -> 22 | L37: =ROUND(L6,0) -> 39 | M37: =ROUND(M6,0) -> 22 | N37: =ROUND(N6,0) -> 2 | ... AH37: =ROUND(AH6,0) -> 13 | AI37: =SUM(G37:AH37) -> 447
F38: 5 | G38: =ROUND(G7,0) -> 14 | H38: =ROUND(H7,0) -> 8 | I38: =ROUND(I7,0) -> 7 | J38: =ROUND(J7,0) -> 12 | K38: =ROUND(K7,0) -> 4 | L38: =ROUND(L7,0) -> 15 | M38: =ROUND(M7,0) -> 6 | N38: =ROUND(N7,0) -> 3 | ... AH38: =ROUND(AH7,0) -> 5 | AI38: =SUM(G38:AH38) -> 253
F39: 6 | G39: =ROUND(G8,0) -> 170 | H39: =ROUND(H8,0) -> 38 | I39: =ROUND(I8,0) -> 51 | J39: =ROUND(J8,0) -> 16 | K39: =ROUND(K8,0) -> 60 | L39: =ROUND(L8,0) -> 65 | M39: =ROUND(M8,0) -> 70 | N39: =ROUND(N8,0) -> 3 | ... AH39: =ROUND(AH8,0) -> 38 | AI39: =SUM(G39:AH39) -> 870
F40: 7 | G40: =ROUND(G9,0) -> 82 | H40: =ROUND(H9,0) -> 34 | I40: =ROUND(I9,0) -> 42 | J40: =ROUND(J9,0) -> 27 | K40: =ROUND(K9,0) -> 31 | L40: =ROUND(L9,0) -> 84 | M40: =ROUND(M9,0) -> 45 | N40: =ROUND(N9,0) -> 4 | ... AH40: =ROUND(AH9,0) -> 31 | AI40: =SUM(G40:AH40) -> 891
F41: 8 | G41: =ROUND(G10,0) -> 115 | H41: =ROUND(H10,0) -> 31 | I41: =ROUND(I10,0) -> 43 | J41: =ROUND(J10,0) -> 20 | K41: =ROUND(K10,0) -> 59 | L41: =ROUND(L10,0) -> 81 | M41: =ROUND(M10,0) -> 109 | N41: =ROUND(N10,0) -> 4 | ... AH41: =ROUND(AH10,0) -> 73 | AI41: =SUM(G41:AH41) -> 1124
F42: 9 | G42: =ROUND(G11,0) -> 5 | H42: =ROUND(H11,0) -> 3 | I42: =ROUND(I11,0) -> 2 | J42: =ROUND(J11,0) -> 7 | K42: =ROUND(K11,0) -> 1 | L42: =ROUND(L11,0) -> 5 | M42: =ROUND(M11,0) -> 2 | N42: =ROUND(N11,0) -> 51 | ... AH42: =ROUND(AH11,0) -> 2 | AI42: =SUM(G42:AH42) -> 438
F43: 10 | G43: =ROUND(G12,0) -> 55 | H43: =ROUND(H12,0) -> 17 | I43: =ROUND(I12,0) -> 23 | J43: =ROUND(J12,0) -> 14 | K43: =ROUND(K12,0) -> 27 | L43: =ROUND(L12,0) -> 52 | M43: =ROUND(M12,0) -> 59 | N43: =ROUND(N12,0) -> 3 | ... AH43: =ROUND(AH12,0) -> 48 | AI43: =SUM(G43:AH43) -> 740
F44: 11 | G44: =ROUND(G13,0) -> 2 | H44: =ROUND(H13,0) -> 1 | I44: =ROUND(I13,0) -> 1 | J44: =ROUND(J13,0) -> 1 | K44: =ROUND(K13,0) -> 1 | L44: =ROUND(L13,0) -> 3 | M44: =ROUND(M13,0) -> 2 | N44: =ROUND(N13,0) -> 0 | ... AH44: =ROUND(AH13,0) -> 1 | AI44: =SUM(G44:AH44) -> 43
F45: 12 | G45: =ROUND(G14,0) -> 18 | H45: =ROUND(H14,0) -> 6 | I45: =ROUND(I14,0) -> 8 | J45: =ROUND(J14,0) -> 7 | K45: =ROUND(K14,0) -> 8 | L45: =ROUND(L14,0) -> 21 | M45: =ROUND(M14,0) -> 17 | N45: =ROUND(N14,0) -> 1 | ... AH45: =ROUND(AH14,0) -> 17 | AI45: =SUM(G45:AH45) -> 319
F46: 13 | G46: =ROUND(G15,0) -> 11 | H46: =ROUND(H15,0) -> 5 | I46: =ROUND(I15,0) -> 6 | J46: =ROUND(J15,0) -> 8 | K46: =ROUND(K15,0) -> 5 | L46: =ROUND(L15,0) -> 15 | M46: =ROUND(M15,0) -> 11 | N46: =ROUND(N15,0) -> 3 | ... AH46: =ROUND(AH15,0) -> 14 | AI46: =SUM(G46:AH46) -> 454
... F62: 29 | G62: =ROUND(G31,0) -> 44 | H62: =ROUND(H31,0) -> 13 | I62: =ROUND(I31,0) -> 17 | J62: =ROUND(J31,0) -> 11 | K62: =ROUND(K31,0) -> 22 | L62: =ROUND(L31,0) -> 39 | M62: =ROUND(M31,0) -> 51 | N62: =ROUND(N31,0) -> 2 | ... AH62: =ROUND(AH31,0) -> 55 | AI62: =SUM(G62:AH62) -> 665
